Workbook

Sheet KPIs
B2: Quona KPIs - Enza Group | C2: [unit] | E2: 45658 | F2: =EOMONTH(E2,1) -> 45716 | G2: =EOMONTH(F2,1) -> 45747 | H2: =EOMONTH(G2,1) -> 45777 | I2: =EOMONTH(H2,1) -> 45808 | J2: =EOMONTH(I2,1) -> 45838 | K2: =EOMONTH(J2,1) -> 45869 | L2: =EOMONTH(K2,1) -> 45900 | M2: =EOMONTH(L2,1) -> 45930 | ... P2: =EOMONTH(O2,1) -> 46022 | R2: 46023 | S2: =EOMONTH(R2,1) -> 46081 | T2: =EOMONTH(S2,1) -> 46112 | U2: =EOMONTH(T2,1) -> 46142 | V2: =EOMONTH(U2,1) -> 46173 | W2: =EOMONTH(V2,1) -> 46203 | X2: =EOMONTH(W2,1) -> 46234 | Y2: =EOMONTH(X2,1) -> 46265 | Z2: =EOMONTH(Y2,1) -> 46295 | ... AC2: =EOMONTH(AB2,1) -> 46387
B4: Operational Metrics
B5: Total Processed Volumes | C5: USD
B6: Transaction Count | C6: # | E6: =SUM([1]Sheet1!B14:B16,[1]Sheet1!B9) -> 105 | F6: =SUM([1]Sheet1!C14:C16,[1]Sheet1!C9) -> 20 | G6: =SUM([1]Sheet1!D14:D16,[1]Sheet1!D9) -> 8 | H6: =SUM([1]Sheet1!E14:E16,[1]Sheet1!E9) -> 167 | I6: =SUM([1]Sheet1!F14:F16,[1]Sheet1!F9) -> 71 | J6: =SUM([1]Sheet1!G14:G16,[1]Sheet1!G9) -> 80 | K6: =SUM([1]Sheet1!H14:H16,[1]Sheet1!H9) -> 0 | L6: =SUM([1]Sheet1!I14:I16,[1]Sheet1!I9) -> 64 | ... P6: =SUM([1]Sheet1!M14:M16,[1]Sheet1!M9) -> 276 | R6: =SUM([1]Sheet1!O14:O16,[1]Sheet1!O9) -> 530 | S6: =SUM([1]Sheet1!P14:P16,[1]Sheet1!P9) -> 12526 | T6: =SUM([1]Sheet1!Q14:Q16,[1]Sheet1!Q9) -> 6911
B7: Total Revenues | C7: USD | E7: =SUM(E8:E11) -> 15853.23 | F7: =SUM(F8:F11) -> 5050.7412 | G7: =SUM(G8:G11) -> 25050.25 | H7: =SUM(H8:H11) -> 5075.6412 | I7: =SUM(I8:I11) -> 5083.0621 | J7: =SUM(J8:J11) -> 5101.8235 | K7: =SUM(K8:K11) -> 5100 | L7: =SUM(L8:L11) -> 10000.003 | ... P7: =SUM(P8:P11) -> 290500 | R7: =SUM(R8:R11) -> 11600.003 | S7: =SUM(S8:S11) -> 11600.003 | T7: =SUM(T8:T11) -> 397350
B8: Issuer Processing Revenues | C8: USD | E8: ='P&L'!E14 -> 10800 | F8: ='P&L'!F14 -> 0 | G8: ='P&L'!G14 -> 0 | H8: ='P&L'!H14 -> 0 | I8: ='P&L'!I14 -> 0 | J8: ='P&L'!J14 -> 0 | K8: ='P&L'!K14 -> 0 | L8: ='P&L'!L14 -> 0 | ... P8: ='P&L'!P14 -> 300500 | R8: ='P&L'!S14 -> 1600.0027 | S8: ='P&L'!T14 -> 1600.0027 | T8: ='P&L'!U14 -> 387350
B9: Acceptance Revenues | C9: USD | E9: ='P&L'!E24 -> 0 | F9: ='P&L'!F24 -> 0 | G9: ='P&L'!G24 -> 0 | H9: ='P&L'!H24 -> 0 | I9: ='P&L'!I24 -> 0 | J9: ='P&L'!J24 -> 0 | K9: ='P&L'!K24 -> 0 | L9: ='P&L'!L24 -> 0 | ... P9: ='P&L'!P24 -> 0 | R9: ='P&L'!S24 -> 0 | S9: ='P&L'!T24 -> 0 | T9: ='P&L'!U24 -> 0
B10: enza conductor | C10: USD | E10: ='P&L'!E19 -> 5053.2297 | F10: ='P&L'!F19 -> 5050.7412 | G10: ='P&L'!G19 -> 25050.25 | H10: ='P&L'!H19 -> 5075.6412 | I10: ='P&L'!I19 -> 5083.0621 | J10: ='P&L'!J19 -> 5101.8235 | K10: ='P&L'!K19 -> 5100 | L10: ='P&L'!L19 -> 10000.003 | ... P10: ='P&L'!P19 -> -10000.001 | R10: ='P&L'!S19 -> 10000 | S10: ='P&L'!T19 -> 10000 | T10: ='P&L'!U19 -> 9999.9973
B11: Value Add Services Revenues | C11: USD | E11: ='[2]Detailed FS_$ Cons. (formating)'!BR$10 -> 0 | F11: ='[2]Detailed FS_$ Cons. (formating)'!BS$10 -> 0 | G11: ='[2]Detailed FS_$ Cons. (formating)'!BT$10 -> 0 | H11: ='[2]Detailed FS_$ Cons. (formating)'!BU$10 -> 0 | I11: ='[2]Detailed FS_$ Cons. (formating)'!BV$10 -> 0 | J11: ='[2]Detailed FS_$ Cons. (formating)'!BW$10 -> 0 | K11: ='[2]Detailed FS_$ Cons. (formating)'!BX$10 -> 0 | L11: ='[2]Detailed FS_$ Cons. (formating)'!BY$10 -> 0 | ... P11: ='[2]Detailed FS_$ Cons. (formating)'!CC$10 -> 0 | R11: ='[2]Detailed FS_$ Cons. (formating)'!CF$10 -> 0 | S11: ='[2]Detailed FS_$ Cons. (formating)'!CG$10 -> 0 | T11: ='[2]Detailed FS_$ Cons. (formating)'!CH$10 -> 0
B12: COGS | C12: USD | E12: ='P&L'!E51 -> -9999.8639 | F12: ='P&L'!F51 -> -9999.8639 | G12: ='P&L'!G51 -> -10000 | H12: ='P&L'!H51 -> -10000 | I12: ='P&L'!I51 -> 40000 | J12: ='P&L'!J51 -> 0 | K12: ='P&L'!K51 -> 0 | L12: ='P&L'!L51 -> 0 | ... P12: ='P&L'!P51 -> -3580.5118 | R12: ='P&L'!S51 -> -2187.2012 | S12: ='P&L'!T51 -> -2187.2012 | T12: ='P&L'!U51 -> -2187.2012
B13: Contribution Margin | C13: USD | E13: =E7+E12 -> 5853.3658 | F13: =F7+F12 -> -4949.1226 | G13: =G7+G12 -> 15050.25 | H13: =H7+H12 -> -4924.3588 | I13: =I7+I12 -> 45083.062 | J13: =J7+J12 -> 5101.8235 | K13: =K7+K12 -> 5100 | L13: =L7+L12 -> 10000.003 | ... P13: =P7+P12 -> 286919.49 | R13: =R7+R12 -> 9412.8015 | S13: =S7+S12 -> 9412.8015 | T13: =T7+T12 -> 395162.8
B14: Contibution Margin | C14: % | E14: =E13/E7 -> 0.36922229 | F14: =F13/F7 -> -0.97988046 | G14: =G13/G7 -> 0.60080239 | H14: =H13/H7 -> -0.97019444 | I14: =I13/I7 -> 8.8692723 | J14: =J13/J7 -> 1 | K14: =IFERROR(K13/K7,0) -> 1 | L14: =IFERROR(L13/L7,0) -> 1 | M14: =IFERROR(M13/M7,0) -> 1 | N14: =IFERROR(N13/N7,0) -> -15.560166 | O14: =IFERROR(O13/O7,0) -> 0.72417548 | P14: =IFERROR(P13/P7,0) -> 0.98767466 | R14: =IFERROR(R13/R7,0) -> 0.81144822 | S14: =IFERROR(S13/S7,0) -> 0.81144822 | T14: =IFERROR(T13/T7,0) -> 0.99449553
B15: EBITDA | C15: USD | E15: ='P&L'!E120 -> -200195.8 | F15: ='P&L'!F120 -> -254096.13 | G15: ='P&L'!G120 -> -236704.41 | H15: ='P&L'!H120 -> -252988.65 | I15: ='P&L'!I120 -> -292041.93 | J15: ='P&L'!J120 -> -224377.04 | K15: ='P&L'!K120 -> -377020.29 | L15: ='P&L'!L120 -> -248243.75 | ... P15: ='P&L'!P120 -> -32075.749 | R15: ='P&L'!S120 -> -366484.09 | S15: ='P&L'!T120 -> -346373.03 | T15: ='P&L'!U120 -> 64903.82
B17: Employees
B18: Total Employees | C18: # | I18: 54 | J18: 53 | K18: 53 | L18: 54 | M18: 54 | N18: 57 | O18: 60 | P18: 64 | R18: 65 | S18: 63 | T18: 64
B19: Total Female Employees | C19: # | I19: 14 | J19: 14 | K19: 14 | L19: 14 | M19: 19 | N19: 20 | O19: 20 | P19: 20 | R19: =17+1+1 -> 19 | S19: =16+1+1 -> 18 | T19: =15+1+1 -> 17
R20: =32+8+2+4 -> 46 | S20: =31+8+2+4 -> 45 | T20: =32+8+3+4 -> 47
B21: Senior Management
B22: Total Senior Managers | C22: # | I22: 10 | J22: 11 | K22: 11 | L22: 11 | M22: 11 | N22: 11 | O22: 11 | P22: 12 | R22: 12 | S22: 12 | T22: 13
B23: Total Female Senior Managers | C23: # | I23: 2 | J23: 2 | K23: 2 | L23: 2 | M23: 2 | N23: 2 | O23: 2 | P23: 2 | R23: 2 | S23: 2 | T23: 2
B25: Customers
B26: Number of Clients (Banks/Institutions) | C26: # | E26: 2 | F26: 2 | G26: 3 | H26: 3 | I26: 5 | J26: 10 | K26: 10 | L26: 10 | M26: 11 | N26: 11 | O26: 11 | P26: =[1]Sheet1!$O$13+[1]Sheet1!$O$4 -> 11 | R26: =[1]Sheet1!O13+[1]Sheet1!O4 -> 11 | S26: =[1]Sheet1!P13+[1]Sheet1!P4 -> 11 | T26: =[1]Sheet1!Q13+[1]Sheet1!Q4 -> 13
B27: Number of Clients (MFIs and Small FIs) | C27: #
B28: Number of Issuer Credentials
B29: Number of Merchants | C29: # | E29: ='[3]KPIs '!B18 -> 5 | F29: ='[3]KPIs '!C18 -> 5 | G29: ='[3]KPIs '!D18 -> 5 | H29: ='[3]KPIs '!E18 -> 7 | I29: ='[3]KPIs '!F18 -> 8 | J29: ='[3]KPIs '!G18 -> 10 | K29: ='[3]KPIs '!H18 -> 10 | L29: ='[3]KPIs '!I18 -> 11 | ... O29: ='[3]KPIs '!L18 -> 11 | P29: 11 | R29: =[1]Sheet1!O17 -> 12 | S29: =[1]Sheet1!P17 -> 17 | T29: =[1]Sheet1!Q17 -> 18
B31: Cash Reserves
B32: Cash Reserves | C32: USD
B33: Monthly Cash Burn | C33: USD
B34: Runway | C34: USD

Sheet P&L
B1: First Year | C1: 2026
B2: Selected Plan | C2: AV
B3: Last Month | C3: 46053
B5: past months | E5: =IF(AND(E7<=$C$3,YEAR(E7)=YEAR($C$3)),1,0) -> 0 | F5: =IF(AND(F7<=$C$3,YEAR(F7)=YEAR($C$3)),1,0) -> 0 | G5: =IF(AND(G7<=$C$3,YEAR(G7)=YEAR($C$3)),1,0) -> 0 | H5: =IF(AND(H7<=$C$3,YEAR(H7)=YEAR($C$3)),1,0) -> 0 | I5: =IF(AND(I7<=$C$3,YEAR(I7)=YEAR($C$3)),1,0) -> 0 | J5: =IF(AND(J7<=$C$3,YEAR(J7)=YEAR($C$3)),1,0) -> 0 | K5: =IF(AND(K7<=$C$3,YEAR(K7)=YEAR($C$3)),1,0) -> 0 | L5: =IF(AND(L7<=$C$3,YEAR(L7)=YEAR($C$3)),1,0) -> 0 | ... P5: =IF(AND(P7<=$C$3,YEAR(P7)=YEAR($C$3)),1,0) -> 0 | S5: =IF(AND(S7<=$C$3,YEAR(S7)=YEAR($C$3)),1,0) -> 1 | T5: =IF(AND(T7<=$C$3,YEAR(T7)=YEAR($C$3)),1,0) -> 0 | U5: =IF(AND(U7<=$C$3,YEAR(U7)=YEAR($C$3)),1,0) -> 0 | V5: =IF(AND(V7<=$C$3,YEAR(V7)=YEAR($C$3)),1,0) -> 0 | W5: =IF(AND(W7<=$C$3,YEAR(W7)=YEAR($C$3)),1,0) -> 0 | X5: =IF(AND(X7<=$C$3,YEAR(X7)=YEAR($C$3)),1,0) -> 0 | Y5: =IF(AND(Y7<=$C$3,YEAR(Y7)=YEAR($C$3)),1,0) -> 0 | Z5: =IF(AND(Z7<=$C$3,YEAR(Z7)=YEAR($C$3)),1,0) -> 0 | ... AD5: =IF(AND(AD7<=$C$3,YEAR(AD7)=YEAR($C$3)),1,0) -> 0
B6: last month | E6: =IF(E7=$C$3,1,0) -> 0 | F6: =IF(F7=$C$3,1,0) -> 0 | G6: =IF(G7=$C$3,1,0) -> 0 | H6: =IF(H7=$C$3,1,0) -> 0 | I6: =IF(I7=$C$3,1,0) -> 0 | J6: =IF(J7=$C$3,1,0) -> 0 | K6: =IF(K7=$C$3,1,0) -> 0 | L6: =IF(L7=$C$3,1,0) -> 0 | ... P6: =IF(P7=$C$3,1,0) -> 0 | S6: =IF(S7=$C$3,1,0) -> 1 | T6: =IF(T7=$C$3,1,0) -> 0 | U6: =IF(U7=$C$3,1,0) -> 0 | V6: =IF(V7=$C$3,1,0) -> 0 | W6: =IF(W7=$C$3,1,0) -> 0 | X6: =IF(X7=$C$3,1,0) -> 0 | Y6: =IF(Y7=$C$3,1,0) -> 0 | Z6: =IF(Z7=$C$3,1,0) -> 0 | ... AD6: =IF(AD7=$C$3,1,0) -> 0
B7: P&L | C7: USD | E7: 45688 | F7: =EOMONTH(E7,1) -> 45716 | G7: =EOMONTH(F7,1) -> 45747 | H7: =EOMONTH(G7,1) -> 45777 | I7: =EOMONTH(H7,1) -> 45808 | J7: =EOMONTH(I7,1) -> 45838 | K7: =EOMONTH(J7,1) -> 45869 | L7: =EOMONTH(K7,1) -> 45900 | M7: =EOMONTH(L7,1) -> 45930 | ... P7: =EOMONTH(O7,1) -> 46022 | Q7: =YEAR(P7) -> 2025 | S7: =EOMONTH(P7,1) -> 46053 | T7: =EOMONTH(S7,1) -> 46081 | U7: =EOMONTH(T7,1) -> 46112 | V7: =EOMONTH(U7,1) -> 46142 | W7: =EOMONTH(V7,1) -> 46173 | X7: =EOMONTH(W7,1) -> 46203 | Y7: =EOMONTH(X7,1) -> 46234 | Z7: =EOMONTH(Y7,1) -> 46265 | AA7: =EOMONTH(Z7,1) -> 46295 | ... AD7: =EOMONTH(AC7,1) -> 46387 | AE7: =YEAR(AD7) -> 2026 | AH7: =C3 -> 46053 | AI7: YTD
E8: =E9-'[2]Detailed FS_$ Cons. (formating)'!BR13 -> 0 | F8: =F9-'[2]Detailed FS_$ Cons. (formating)'!BS13 -> 0 | G8: =G9-'[2]Detailed FS_$ Cons. (formating)'!BT13 -> 0 | H8: =H9-'[2]Detailed FS_$ Cons. (formating)'!BU13 -> 0 | I8: =I9-'[2]Detailed FS_$ Cons. (formating)'!BV13 -> 0 | J8: =J9-'[2]Detailed FS_$ Cons. (formating)'!BW13 -> 0 | K8: =K9-'[2]Detailed FS_$ Cons. (formating)'!BX13 -> 0 | L8: =L9-'[2]Detailed FS_$ Cons. (formating)'!BY13 -> 0 | ... P8: =P9-'[2]Detailed FS_$ Cons. (formating)'!CC13 -> 0 | Q8: 12 months | S8: =S9-'[2]Detailed FS_$ Cons. (formating)'!CF13 -> 0 | T8: =T9-'[2]Detailed FS_$ Cons. (formating)'!CG13 -> 0 | U8: =U9-'[2]Detailed FS_$ Cons. (formating)'!CH13 -> 0 | AE8: 12 months | AH8: last month | BH8: AV
B9: GMV | C9: Actual | E9: =SUM(E14,E19,E24) -> 15853.23 | F9: =SUM(F14,F19,F24) -> 5050.7412 | G9: =SUM(G14,G19,G24) -> 25050.25 | H9: =SUM(H14,H19,H24) -> 5075.6412 | I9: =SUM(I14,I19,I24) -> 5083.0621 | J9: =SUM(J14,J19,J24) -> 5101.8235 | K9: =SUM(K14,K19,K24) -> 5100 | L9: =SUM(L14,L19,L24) -> 10000.003 | ... P9: =SUM(P14,P19,P24) -> 290500 | Q9: =SUM(E9:P9) -> 416214.75 | S9: =SUM(S14,S19,S24) -> 11600.003 | T9: =SUM(T14,T19,T24) -> 11600.003 | U9: =SUM(U14,U19,U24) -> 397350 | V9: =SUM(V14,V19,V24) -> 0 | W9: =SUM(W14,W19,W24) -> 0 | X9: =SUM(X14,X19,X24) -> 0 | Y9: =SUM(Y14,Y19,Y24) -> 0 | Z9: =SUM(Z14,Z19,Z24) -> 0 | ... AD9: =SUM(AD14,AD19,AD24) -> 0 | AE9: =SUM(S9:AD9) -> 420550 | AH9: =SUMPRODUCT($S$7:$AD$7,S9:AD9) -> 1.9391358e+10 | AI9: =SUMPRODUCT($S$6:$AD$7,S9:AD9) -> #VALUE! | BH9: Mgmt (Adj)
C10: =IF($C$2="AV",C13,IF($C$2="Mgmt",C11,IF($C$2="Mgmt (Adj)",C12))) -> plan (AV) | Q10: =SUM(E10:P10) -> 0 | V10: =IF($C$2="AV",V13,IF($C$2="Mgmt",V11,IF($C$2="Mgmt (Adj)",V12))) -> 0 | W10: =IF($C$2="AV",W13,IF($C$2="Mgmt",W11,IF($C$2="Mgmt (Adj)",W12))) -> 0 | X10: =IF($C$2="AV",X13,IF($C$2="Mgmt",X11,IF($C$2="Mgmt (Adj)",X12))) -> 0 | Y10: =IF($C$2="AV",Y13,IF($C$2="Mgmt",Y11,IF($C$2="Mgmt (Adj)",Y12))) -> 0 | Z10: =IF($C$2="AV",Z13,IF($C$2="Mgmt",Z11,IF($C$2="Mgmt (Adj)",Z12))) -> 0 | AA10: =IF($C$2="AV",AA13,IF($C$2="Mgmt",AA11,IF($C$2="Mgmt (Adj)",AA12))) -> 0 | AB10: =IF($C$2="AV",AB13,IF($C$2="Mgmt",AB11,IF($C$2="Mgmt (Adj)",AB12))) -> 0 | AC10: =IF($C$2="AV",AC13,IF($C$2="Mgmt",AC11,IF($C$2="Mgmt (Adj)",AC12))) -> 0 | AD10: =IF($C$2="AV",AD13,IF($C$2="Mgmt",AD11,IF($C$2="Mgmt (Adj)",AD12))) -> 0 | AE10: =SUM(S10:AD10) -> 0 | AH10: =SUMPRODUCT($E$6:$AD$6,E10:AD10) -> 0 | AI10: =SUMPRODUCT($E$5:$AD$5,E10:AD10) -> 0 | BH10: Mgmt
C11: plan (Mgmt) | E11: =SUM(E16,E21,E26) -> 0 | F11: =SUM(F16,F21,F26) -> 0 | G11: =SUM(G16,G21,G26) -> 0 | H11: =SUM(H16,H21,H26) -> 0 | I11: =SUM(I16,I21,I26) -> 0 | J11: =SUM(J16,J21,J26) -> 0 | K11: =SUM(K16,K21,K26) -> 0 | L11: =SUM(L16,L21,L26) -> 0 | ... P11: =SUM(P16,P21,P26) -> 0 | Q11: =SUM(E11:P11) -> 0 | S11: =SUM(S16,S21,S26) -> 0 | T11: =SUM(T16,T21,T26) -> 0 | U11: =SUM(U16,U21,U26) -> 0 | V11: =SUM(V16,V21,V26) -> 0 | W11: =SUM(W16,W21,W26) -> 0 | X11: =SUM(X16,X21,X26) -> 0 | Y11: =SUM(Y16,Y21,Y26) -> 0 | Z11: =SUM(Z16,Z21,Z26) -> 0 | ... AD11: =SUM(AD16,AD21,AD26) -> 0 | AE11: =SUM(S11:AD11) -> 0 | AH11: =SUMPRODUCT($E$6:$AD$6,E11:AD11) -> 0 | AI11: =SUMPRODUCT($E$5:$AD$5,E11:AD11) -> 0
C12: plan (Mgmt Adj) | E12: =SUM(E17,E22,E27) -> 0 | F12: =SUM(F17,F22,F27) -> 0 | G12: =SUM(G17,G22,G27) -> 0 | H12: =SUM(H17,H22,H27) -> 0 | I12: =SUM(I17,I22,I27) -> 0 | J12: =SUM(J17,J22,J27) -> 0 | K12: =SUM(K17,K22,K27) -> 0 | L12: =SUM(L17,L22,L27) -> 0 | ... P12: =SUM(P17,P22,P27) -> 0 | Q12: =SUM(E12:P12) -> 0 | S12: =SUM(S17,S22,S27) -> 0 | T12: =SUM(T17,T22,T27) -> 0 | U12: =SUM(U17,U22,U27) -> 0 | V12: =SUM(V17,V22,V27) -> 0 | W12: =SUM(W17,W22,W27) -> 0 | X12: =SUM(X17,X22,X27) -> 0 | Y12: =SUM(Y17,Y22,Y27) -> 0 | Z12: =SUM(Z17,Z22,Z27) -> 0 | ... AD12: =SUM(AD17,AD22,AD27) -> 0 | AE12: =SUM(S12:AD12) -> 0 | AH12: =SUMPRODUCT($E$6:$AD$6,E12:AD12) -> 0 | AI12: =SUMPRODUCT($E$5:$AD$5,E12:AD12) -> 0
C13: plan (AV) | E13: =SUM(E18,E23,E28) -> 0 | F13: =SUM(F18,F23,F28) -> 0 | G13: =SUM(G18,G23,G28) -> 0 | H13: =SUM(H18,H23,H28) -> 0 | I13: =SUM(I18,I23,I28) -> 0 | J13: =SUM(J18,J23,J28) -> 0 | K13: =SUM(K18,K23,K28) -> 0 | L13: =SUM(L18,L23,L28) -> 0 | ... P13: =SUM(P18,P23,P28) -> 0 | Q13: =SUM(E13:P13) -> 0 | S13: =SUM(S18,S23,S28) -> 0 | T13: =SUM(T18,T23,T28) -> 0 | U13: =SUM(U18,U23,U28) -> 0 | V13: =SUM(V18,V23,V28) -> 0 | W13: =SUM(W18,W23,W28) -> 0 | X13: =SUM(X18,X23,X28) -> 0 | Y13: =SUM(Y18,Y23,Y28) -> 0 | Z13: =SUM(Z18,Z23,Z28) -> 0 | ... AD13: =SUM(AD18,AD23,AD28) -> 0 | AE13: =SUM(S13:AD13) -> 0 | AH13: =SUMPRODUCT($E$6:$AD$6,E13:AD13) -> 0 | AI13: =SUMPRODUCT($E$5:$AD$5,E13:AD13) -> 0
B14: PaaS | C14: Actual | E14: ='[2]Detailed FS_$ Cons. (formating)'!BR$7 -> 10800 | F14: ='[2]Detailed FS_$ Cons. (formating)'!BS$7 -> 0 | G14: ='[2]Detailed FS_$ Cons. (formating)'!BT$7 -> 0 | H14: ='[2]Detailed FS_$ Cons. (formating)'!BU7 -> 0 | I14: ='[2]Detailed FS_$ Cons. (formating)'!BV7 -> 0 | J14: ='[2]Detailed FS_$ Cons. (formating)'!BW7 -> 0 | K14: ='[2]Detailed FS_$ Cons. (formating)'!BX7 -> 0 | L14: ='[2]Detailed FS_$ Cons. (formating)'!BY7 -> 0 | M14: ='[2]Detailed FS_$ Cons. (formating)'!BZ7 -> 0 | N14: ='[2]Detailed FS_$ Cons. (formating)'!CA7 -> 17800.003 | O14: ='[2]Detailed FS_$ Cons. (formating)'!CB7 -> 1600 | P14: ='[2]Detailed FS_$ Cons. (formating)'!CC7 -> 300500 | Q14: =SUM(E14:P14) -> 330700 | S14: ='[2]Detailed FS_$ Cons. (formating)'!CF7 -> 1600.0027 | T14: ='[2]Detailed FS_$ Cons. (formating)'!CG7 -> 1600.0027 | U14: ='[2]Detailed FS_$ Cons. (formating)'!CH7 -> 387350 | AE14: =SUM(S14:AD14) -> 390550.01 | AH14: =SUMPRODUCT($E$6:$AD$6,E14:AD14) -> 1600.0027 | AI14: =SUMPRODUCT($E$5:$AD$5,E14:AD14) -> 1600.0027
C15: =IF($C$2="AV",C18,IF($C$2="Mgmt",C16,IF($C$2="Mgmt (Adj)",C17))) -> plan (AV) | E15: =IF($C$2="AV",E18,IF($C$2="Mgmt",E16,IF($C$2="Mgmt (Adj)",E17))) -> 0 | F15: =IF($C$2="AV",F18,IF($C$2="Mgmt",F16,IF($C$2="Mgmt (Adj)",F17))) -> 0 | G15: =IF($C$2="AV",G18,IF($C$2="Mgmt",G16,IF($C$2="Mgmt (Adj)",G17))) -> 0 | H15: =IF($C$2="AV",H18,IF($C$2="Mgmt",H16,IF($C$2="Mgmt (Adj)",H17))) -> 0 | I15: =IF($C$2="AV",I18,IF($C$2="Mgmt",I16,IF($C$2="Mgmt (Adj)",I17))) -> 0 | J15: =IF($C$2="AV",J18,IF($C$2="Mgmt",J16,IF($C$2="Mgmt (Adj)",J17))) -> 0 | K15: =IF($C$2="AV",K18,IF($C$2="Mgmt",K16,IF($C$2="Mgmt (Adj)",K17))) -> 0 | L15: =IF($C$2="AV",L18,IF($C$2="Mgmt",L16,IF($C$2="Mgmt (Adj)",L17))) -> 0 | ... P15: =IF($C$2="AV",P18,IF($C$2="Mgmt",P16,IF($C$2="Mgmt (Adj)",P17))) -> 0 | Q15: =SUM(E15:P15) -> 0 | S15: =IF($C$2="AV",S18,IF($C$2="Mgmt",S16,IF($C$2="Mgmt (Adj)",S17))) -> 0 | T15: =IF($C$2="AV",T18,IF($C$2="Mgmt",T16,IF($C$2="Mgmt (Adj)",T17))) -> 0 | U15: =IF($C$2="AV",U18,IF($C$2="Mgmt",U16,IF($C$2="Mgmt (Adj)",U17))) -> 0 | V15: =IF($C$2="AV",V18,IF($C$2="Mgmt",V16,IF($C$2="Mgmt (Adj)",V17))) -> 0 | W15: =IF($C$2="AV",W18,IF($C$2="Mgmt",W16,IF($C$2="Mgmt (Adj)",W17))) -> 0 | X15: =IF($C$2="AV",X18,IF($C$2="Mgmt",X16,IF($C$2="Mgmt (Adj)",X17))) -> 0 | Y15: =IF($C$2="AV",Y18,IF($C$2="Mgmt",Y16,IF($C$2="Mgmt (Adj)",Y17))) -> 0 | Z15: . | AA15: =IF($C$2="AV",AA18,IF($C$2="Mgmt",AA16,IF($C$2="Mgmt (Adj)",AA17))) -> 0 | AB15: =IF($C$2="AV",AB18,IF($C$2="Mgmt",AB16,IF($C$2="Mgmt (Adj)",AB17))) -> 0 | AC15: =IF($C$2="AV",AC18,IF($C$2="Mgmt",AC16,IF($C$2="Mgmt (Adj)",AC17))) -> 0 | AD15: =IF($C$2="AV",AD18,IF($C$2="Mgmt",AD16,IF($C$2="Mgmt (Adj)",AD17))) -> 0 | AE15: =SUM(S15:AD15) -> 0 | AH15: =SUMPRODUCT($E$6:$AD$6,E15:AD15) -> 0 | AI15: =SUMPRODUCT($E$5:$AD$5,E15:AD15) -> 0
C16: plan (Mgmt) | Q16: =SUM(E16:P16) -> 0 | AE16: =SUM(S16:AD16) -> 0 | AH16: =SUMPRODUCT($E$6:$AD$6,E16:AD16) -> 0 | AI16: =SUMPRODUCT($E$5:$AD$5,E16:AD16) -> 0
C17: plan (Mgmt Adj) | Q17: =SUM(E17:P17) -> 0 | AE17: =SUM(S17:AD17) -> 0 | AH17: =SUMPRODUCT($E$6:$AD$6,E17:AD17) -> 0 | AI17: =SUMPRODUCT($E$5:$AD$5,E17:AD17) -> 0
C18: plan (AV) | Q18: =SUM(E18:P18) -> 0 | AE18: =SUM(S18:AD18) -> 0 | AH18: =SUMPRODUCT($E$6:$AD$6,E18:AD18) -> 0 | AI18: =SUMPRODUCT($E$5:$AD$5,E18:AD18) -> 0
B19: enza conductor | C19: Actual | E19: ='[2]Detailed FS_$ Cons. (formating)'!BR$9 -> 5053.2297 | F19: ='[2]Detailed FS_$ Cons. (formating)'!BS$9 -> 5050.7412 | G19: ='[2]Detailed FS_$ Cons. (formating)'!BT$9 -> 25050.25 | H19: ='[2]Detailed FS_$ Cons. (formating)'!BU$9 -> 5075.6412 | I19: ='[2]Detailed FS_$ Cons. (formating)'!BV$9 -> 5083.0621 | J19: ='[2]Detailed FS_$ Cons. (formating)'!BW$9 -> 5101.8235 | K19: ='[2]Detailed FS_$ Cons. (formating)'!BX$9 -> 5100 | L19: ='[2]Detailed FS_$ Cons. (formating)'!BY$9 -> 10000.003 | ... P19: ='[2]Detailed FS_$ Cons. (formating)'!CC$9 -> -10000.001 | Q19: =SUM(E19:P19) -> 85514.75 | S19: ='[2]Detailed FS_$ Cons. (formating)'!CF$9 -> 10000 | T19: ='[2]Detailed FS_$ Cons. (formating)'!CG$9 -> 10000 | U19: ='[2]Detailed FS_$ Cons. (formating)'!CH$9 -> 9999.9973 | AE19: =SUM(S19:AD19) -> 29999.997 | AH19: =SUMPRODUCT($E$6:$AD$6,E19:AD19) -> 10000 | AI19: =SUMPRODUCT($E$5:$AD$5,E19:AD19) -> 10000
C20: =IF($C$2="AV",C23,IF($C$2="Mgmt",C21,IF($C$2="Mgmt (Adj)",C22))) -> plan (AV) | E20: =IF($C$2="AV",E23,IF($C$2="Mgmt",E21,IF($C$2="Mgmt (Adj)",E22))) -> 0 | F20: =IF($C$2="AV",F23,IF($C$2="Mgmt",F21,IF($C$2="Mgmt (Adj)",F22))) -> 0 | G20: =IF($C$2="AV",G23,IF($C$2="Mgmt",G21,IF($C$2="Mgmt (Adj)",G22))) -> 0 | H20: =IF($C$2="AV",H23,IF($C$2="Mgmt",H21,IF($C$2="Mgmt (Adj)",H22))) -> 0 | I20: =IF($C$2="AV",I23,IF($C$2="Mgmt",I21,IF($C$2="Mgmt (Adj)",I22))) -> 0 | J20: =IF($C$2="AV",J23,IF($C$2="Mgmt",J21,IF($C$2="Mgmt (Adj)",J22))) -> 0 | K20: =IF($C$2="AV",K23,IF($C$2="Mgmt",K21,IF($C$2="Mgmt (Adj)",K22))) -> 0 | L20: =IF($C$2="AV",L23,IF($C$2="Mgmt",L21,IF($C$2="Mgmt (Adj)",L22))) -> 0 | ... P20: =IF($C$2="AV",P23,IF($C$2="Mgmt",P21,IF($C$2="Mgmt (Adj)",P22))) -> 0 | Q20: =SUM(E20:P20) -> 0 | S20: =IF($C$2="AV",S23,IF($C$2="Mgmt",S21,IF($C$2="Mgmt (Adj)",S22))) -> 0 | T20: =IF($C$2="AV",T23,IF($C$2="Mgmt",T21,IF($C$2="Mgmt (Adj)",T22))) -> 0 | U20: =IF($C$2="AV",U23,IF($C$2="Mgmt",U21,IF($C$2="Mgmt (Adj)",U22))) -> 0 | V20: =IF($C$2="AV",V23,IF($C$2="Mgmt",V21,IF($C$2="Mgmt (Adj)",V22))) -> 0 | W20: =IF($C$2="AV",W23,IF($C$2="Mgmt",W21,IF($C$2="Mgmt (Adj)",W22))) -> 0 | X20: =IF($C$2="AV",X23,IF($C$2="Mgmt",X21,IF($C$2="Mgmt (Adj)",X22))) -> 0 | Y20: =IF($C$2="AV",Y23,IF($C$2="Mgmt",Y21,IF($C$2="Mgmt (Adj)",Y22))) -> 0 | Z20: =IF($C$2="AV",Z23,IF($C$2="Mgmt",Z21,IF($C$2="Mgmt (Adj)",Z22))) -> 0 | ... AD20: =IF($C$2="AV",AD23,IF($C$2="Mgmt",AD21,IF($C$2="Mgmt (Adj)",AD22))) -> 0 | AE20: =SUM(S20:AD20) -> 0 | AH20: =SUMPRODUCT($E$6:$AD$6,E20:AD20) -> 0 | AI20: =SUMPRODUCT($E$5:$AD$5,E20:AD20) -> 0
C21: plan (Mgmt) | Q21: =SUM(E21:P21) -> 0 | AE21: =SUM(S21:AD21) -> 0 | AH21: =SUMPRODUCT($E$6:$AD$6,E21:AD21) -> 0 | AI21: =SUMPRODUCT($E$5:$AD$5,E21:AD21) -> 0
C22: plan (Mgmt Adj) | Q22: =SUM(E22:P22) -> 0 | AE22: =SUM(S22:AD22) -> 0 | AH22: =SUMPRODUCT($E$6:$AD$6,E22:AD22) -> 0 | AI22: =SUMPRODUCT($E$5:$AD$5,E22:AD22) -> 0
C23: plan (AV) | Q23: =SUM(E23:P23) -> 0 | AE23: =SUM(S23:AD23) -> 0 | AH23: =SUMPRODUCT($E$6:$AD$6,E23:AD23) -> 0 | AI23: =SUMPRODUCT($E$5:$AD$5,E23:AD23) -> 0
B24: Inperson (acceptance) | C24: Actual | Q24: =SUM(E24:P24) -> 0 | X24: 0 | Y24: 0 | Z24: 0 | AA24: 0 | AB24: 0 | AD24: 0 | AE24: =SUM(S24:AD24) -> 0 | AH24: =SUMPRODUCT($E$6:$AD$6,E24:AD24) -> 0 | AI24: =SUMPRODUCT($E$5:$AD$5,E24:AD24) -> 0
C25: =IF($C$2="AV",C28,IF($C$2="Mgmt",C26,IF($C$2="Mgmt (Adj)",C27))) -> plan (AV) | E25: =IF($C$2="AV",E28,IF($C$2="Mgmt",E26,IF($C$2="Mgmt (Adj)",E27))) -> 0 | F25: =IF($C$2="AV",F28,IF($C$2="Mgmt",F26,IF($C$2="Mgmt (Adj)",F27))) -> 0 | G25: =IF($C$2="AV",G28,IF($C$2="Mgmt",G26,IF($C$2="Mgmt (Adj)",G27))) -> 0 | H25: =IF($C$2="AV",H28,IF($C$2="Mgmt",H26,IF($C$2="Mgmt (Adj)",H27))) -> 0 | I25: =IF($C$2="AV",I28,IF($C$2="Mgmt",I26,IF($C$2="Mgmt (Adj)",I27))) -> 0 | J25: =IF($C$2="AV",J28,IF($C$2="Mgmt",J26,IF($C$2="Mgmt (Adj)",J27))) -> 0 | K25: =IF($C$2="AV",K28,IF($C$2="Mgmt",K26,IF($C$2="Mgmt (Adj)",K27))) -> 0 | L25: =IF($C$2="AV",L28,IF($C$2="Mgmt",L26,IF($C$2="Mgmt (Adj)",L27))) -> 0 | ... P25: =IF($C$2="AV",P28,IF($C$2="Mgmt",P26,IF($C$2="Mgmt (Adj)",P27))) -> 0 | Q25: =SUM(E25:P25) -> 0 | S25: =IF($C$2="AV",S28,IF($C$2="Mgmt",S26,IF($C$2="Mgmt (Adj)",S27))) -> 0 | T25: =IF($C$2="AV",T28,IF($C$2="Mgmt",T26,IF($C$2="Mgmt (Adj)",T27))) -> 0 | U25: =IF($C$2="AV",U28,IF($C$2="Mgmt",U26,IF($C$2="Mgmt (Adj)",U27))) -> 0 | V25: =IF($C$2="AV",V28,IF($C$2="Mgmt",V26,IF($C$2="Mgmt (Adj)",V27))) -> 0 | W25: =IF($C$2="AV",W28,IF($C$2="Mgmt",W26,IF($C$2="Mgmt (Adj)",W27))) -> 0 | X25: =IF($C$2="AV",X28,IF($C$2="Mgmt",X26,IF($C$2="Mgmt (Adj)",X27))) -> 0 | Y25: =IF($C$2="AV",Y28,IF($C$2="Mgmt",Y26,IF($C$2="Mgmt (Adj)",Y27))) -> 0 | Z25: =IF($C$2="AV",Z28,IF($C$2="Mgmt",Z26,IF($C$2="Mgmt (Adj)",Z27))) -> 0 | ... AD25: =IF($C$2="AV",AD28,IF($C$2="Mgmt",AD26,IF($C$2="Mgmt (Adj)",AD27))) -> 0 | AE25: =SUM(S25:AD25) -> 0 | AH25: =SUMPRODUCT($E$6:$AD$6,E25:AD25) -> 0 | AI25: =SUMPRODUCT($E$5:$AD$5,E25:AD25) -> 0
C26: plan (Mgmt) | Q26: =SUM(E26:P26) -> 0 | AE26: =SUM(S26:AD26) -> 0 | AH26: =SUMPRODUCT($E$6:$AD$6,E26:AD26) -> 0 | AI26: =SUMPRODUCT($E$5:$AD$5,E26:AD26) -> 0
C27: plan (Mgmt Adj) | Q27: =SUM(E27:P27) -> 0 | AE27: =SUM(S27:AD27) -> 0 | AH27: =SUMPRODUCT($E$6:$AD$6,E27:AD27) -> 0 | AI27: =SUMPRODUCT($E$5:$AD$5,E27:AD27) -> 0
C28: plan (AV) | Q28: =SUM(E28:P28) -> 0 | AE28: =SUM(S28:AD28) -> 0 | AH28: =SUMPRODUCT($E$6:$AD$6,E28:AD28) -> 0 | AI28: =SUMPRODUCT($E$5:$AD$5,E28:AD28) -> 0
AH29: =SUMPRODUCT($E$6:$AD$6,E29:AD29) -> 0 | AI29: =SUMPRODUCT($E$5:$AD$5,E29:AD29) -> 0
B30: Revenue | C30: Actual | E30: =E35+E40+E45 -> 15853.23 | F30: =F35+F40+F45 -> 5050.7412 | G30: =G35+G40+G45 -> 25050.25 | H30: =H35+H40+H45 -> 5075.6412 | I30: =I35+I40+I45 -> 5083.0621 | J30: =J35+J40+J45 -> 5101.8235 | K30: =K35+K40+K45 -> 5100 | L30: =L35+L40+L45 -> 10000.003 | ... P30: =P35+P40+P45 -> 290500 | Q30: =SUM(E30:P30) -> 416214.75 | S30: =S35+S40+S45 -> 11600.003 | T30: =T35+T40+T45 -> 11600.003 | U30: =U35+U40+U45 -> 397350 | V30: =V35+V40+V45 -> 0 | W30: =W35+W40+W45 -> 0 | X30: =X35+X40+X45 -> 0 | Y30: =Y35+Y40+Y45 -> 0 | Z30: =Z35+Z40+Z45 -> 0 | ... AD30: =AD35+AD40+AD45 -> 0 | AE30: =SUM(S30:AD30) -> 420550 | AH30: =SUMPRODUCT($E$6:$AD$6,E30:AD30) -> 11600.003 | AI30: =SUMPRODUCT($E$5:$AD$5,E30:AD30) -> 11600.003
C31: =IF($C$2="AV",C34,IF($C$2="Mgmt",C32,IF($C$2="Mgmt (Adj)",C33))) -> plan (AV) | E31: =IF($C$2="AV",E34,IF($C$2="Mgmt",E32,IF($C$2="Mgmt (Adj)",E33))) -> 0 | F31: =IF($C$2="AV",F34,IF($C$2="Mgmt",F32,IF($C$2="Mgmt (Adj)",F33))) -> 0 | G31: =IF($C$2="AV",G34,IF($C$2="Mgmt",G32,IF($C$2="Mgmt (Adj)",G33))) -> 0 | H31: =IF($C$2="AV",H34,IF($C$2="Mgmt",H32,IF($C$2="Mgmt (Adj)",H33))) -> 0 | I31: =IF($C$2="AV",I34,IF($C$2="Mgmt",I32,IF($C$2="Mgmt (Adj)",I33))) -> 0 | J31: =IF($C$2="AV",J34,IF($C$2="Mgmt",J32,IF($C$2="Mgmt (Adj)",J33))) -> 0 | K31: =IF($C$2="AV",K34,IF($C$2="Mgmt",K32,IF($C$2="Mgmt (Adj)",K33))) -> 0 | L31: =IF($C$2="AV",L34,IF($C$2="Mgmt",L32,IF($C$2="Mgmt (Adj)",L33))) -> 0 | ... P31: =IF($C$2="AV",P34,IF($C$2="Mgmt",P32,IF($C$2="Mgmt (Adj)",P33))) -> 0 | Q31: =SUM(E31:P31) -> 0 | S31: =IF($C$2="AV",S34,IF($C$2="Mgmt",S32,IF($C$2="Mgmt (Adj)",S33))) -> 0 | T31: =IF($C$2="AV",T34,IF($C$2="Mgmt",T32,IF($C$2="Mgmt (Adj)",T33))) -> 0 | U31: =IF($C$2="AV",U34,IF($C$2="Mgmt",U32,IF($C$2="Mgmt (Adj)",U33))) -> 0 | V31: =IF($C$2="AV",V34,IF($C$2="Mgmt",V32,IF($C$2="Mgmt (Adj)",V33))) -> 0 | W31: =IF($C$2="AV",W34,IF($C$2="Mgmt",W32,IF($C$2="Mgmt (Adj)",W33))) -> 0 | X31: =IF($C$2="AV",X34,IF($C$2="Mgmt",X32,IF($C$2="Mgmt (Adj)",X33))) -> 0 | Y31: =IF($C$2="AV",Y34,IF($C$2="Mgmt",Y32,IF($C$2="Mgmt (Adj)",Y33))) -> 0 | Z31: =IF($C$2="AV",Z34,IF($C$2="Mgmt",Z32,IF($C$2="Mgmt (Adj)",Z33))) -> 0 | ... AD31: =IF($C$2="AV",AD34,IF($C$2="Mgmt",AD32,IF($C$2="Mgmt (Adj)",AD33))) -> 0 | AE31: =SUM(S31:AD31) -> 0 | AH31: =SUMPRODUCT($E$6:$AD$6,E31:AD31) -> 0 | AI31: =SUMPRODUCT($E$5:$AD$5,E31:AD31) -> 0
C32: plan (Mgmt) | E32: =E37+E42+E47 -> 0 | F32: =F37+F42+F47 -> 0 | G32: =G37+G42+G47 -> 0 | H32: =H37+H42+H47 -> 0 | I32: =I37+I42+I47 -> 0 | J32: =J37+J42+J47 -> 0 | K32: =K37+K42+K47 -> 0 | L32: =L37+L42+L47 -> 0 | ... P32: =P37+P42+P47 -> 0 | Q32: =SUM(E32:P32) -> 0 | S32: =S37+S42+S47 -> 0 | T32: =T37+T42+T47 -> 0 | U32: =U37+U42+U47 -> 0 | V32: =V37+V42+V47 -> 0 | W32: =W37+W42+W47 -> 0 | X32: =X37+X42+X47 -> 0 | Y32: =Y37+Y42+Y47 -> 0 | Z32: =Z37+Z42+Z47 -> 0 | ... AD32: =AD37+AD42+AD47 -> 0 | AE32: =SUM(S32:AD32) -> 0 | AH32: =SUMPRODUCT($E$6:$AD$6,E32:AD32) -> 0 | AI32: =SUMPRODUCT($E$5:$AD$5,E32:AD32) -> 0
C33: plan (Mgmt Adj) | E33: =E38+E43+E48 -> 0 | F33: =F38+F43+F48 -> 0 | G33: =G38+G43+G48 -> 0 | H33: =H38+H43+H48 -> 0 | I33: =I38+I43+I48 -> 0 | J33: =J38+J43+J48 -> 0 | K33: =K38+K43+K48 -> 0 | L33: =L38+L43+L48 -> 0 | ... P33: =P38+P43+P48 -> 0 | Q33: =SUM(E33:P33) -> 0 | S33: =S38+S43+S48 -> 0 | T33: =T38+T43+T48 -> 0 | U33: =U38+U43+U48 -> 0 | V33: =V38+V43+V48 -> 0 | W33: =W38+W43+W48 -> 0 | X33: =X38+X43+X48 -> 0 | Y33: =Y38+Y43+Y48 -> 0 | Z33: =Z38+Z43+Z48 -> 0 | ... AD33: =AD38+AD43+AD48 -> 0 | AE33: =SUM(S33:AD33) -> 0 | AH33: =SUMPRODUCT($E$6:$AD$6,E33:AD33) -> 0 | AI33: =SUMPRODUCT($E$5:$AD$5,E33:AD33) -> 0
C34: plan (AV) | E34: =E39+E44+E49 -> 0 | F34: =F39+F44+F49 -> 0 | G34: =G39+G44+G49 -> 0 | H34: =H39+H44+H49 -> 0 | I34: =I39+I44+I49 -> 0 | J34: =J39+J44+J49 -> 0 | K34: =K39+K44+K49 -> 0 | L34: =L39+L44+L49 -> 0 | ... P34: =P39+P44+P49 -> 0 | Q34: =SUM(E34:P34) -> 0 | S34: =S39+S44+S49 -> 0 | T34: =T39+T44+T49 -> 0 | U34: =U39+U44+U49 -> 0 | V34: =V39+V44+V49 -> 0 | W34: =W39+W44+W49 -> 0 | X34: =X39+X44+X49 -> 0 | Y34: =Y39+Y44+Y49 -> 0 | Z34: =Z39+Z44+Z49 -> 0 | ... AD34: =AD39+AD44+AD49 -> 0 | AE34: =SUM(S34:AD34) -> 0 | AH34: =SUMPRODUCT($E$6:$AD$6,E34:AD34) -> 0 | AI34: =SUMPRODUCT($E$5:$AD$5,E34:AD34) -> 0
B35: Revenue Stream 1 | C35: Actual | E35: =E14 -> 10800 | F35: =F14 -> 0 | G35: =G14 -> 0 | H35: =H14 -> 0 | I35: =I14 -> 0 | J35: =J14 -> 0 | K35: =K14 -> 0 | L35: =L14 -> 0 | ... P35: =P14 -> 300500 | Q35: =SUM(E35:P35) -> 330700 | S35: =S14 -> 1600.0027 | T35: =T14 -> 1600.0027 | U35: =U14 -> 387350 | AE35: =SUM(S35:AD35) -> 390550.01 | AH35: =SUMPRODUCT($E$6:$AD$6,E35:AD35) -> 1600.0027 | AI35: =SUMPRODUCT($E$5:$AD$5,E35:AD35) -> 1600.0027
C36: =IF($C$2="AV",C39,IF($C$2="Mgmt",C37,IF($C$2="Mgmt (Adj)",C38))) -> plan (AV) | E36: =IF($C$2="AV",E39,IF($C$2="Mgmt",E37,IF($C$2="Mgmt (Adj)",E38))) -> 0 | F36: =IF($C$2="AV",F39,IF($C$2="Mgmt",F37,IF($C$2="Mgmt (Adj)",F38))) -> 0 | G36: =IF($C$2="AV",G39,IF($C$2="Mgmt",G37,IF($C$2="Mgmt (Adj)",G38))) -> 0 | H36: =IF($C$2="AV",H39,IF($C$2="Mgmt",H37,IF($C$2="Mgmt (Adj)",H38))) -> 0 | I36: =IF($C$2="AV",I39,IF($C$2="Mgmt",I37,IF($C$2="Mgmt (Adj)",I38))) -> 0 | J36: =IF($C$2="AV",J39,IF($C$2="Mgmt",J37,IF($C$2="Mgmt (Adj)",J38))) -> 0 | K36: =IF($C$2="AV",K39,IF($C$2="Mgmt",K37,IF($C$2="Mgmt (Adj)",K38))) -> 0 | L36: =IF($C$2="AV",L39,IF($C$2="Mgmt",L37,IF($C$2="Mgmt (Adj)",L38))) -> 0 | ... P36: =IF($C$2="AV",P39,IF($C$2="Mgmt",P37,IF($C$2="Mgmt (Adj)",P38))) -> 0 | Q36: =SUM(E36:P36) -> 0 | S36: =IF($C$2="AV",S39,IF($C$2="Mgmt",S37,IF($C$2="Mgmt (Adj)",S38))) -> 0 | T36: =IF($C$2="AV",T39,IF($C$2="Mgmt",T37,IF($C$2="Mgmt (Adj)",T38))) -> 0 | U36: =IF($C$2="AV",U39,IF($C$2="Mgmt",U37,IF($C$2="Mgmt (Adj)",U38))) -> 0 | V36: =IF($C$2="AV",V39,IF($C$2="Mgmt",V37,IF($C$2="Mgmt (Adj)",V38))) -> 0 | W36: =IF($C$2="AV",W39,IF($C$2="Mgmt",W37,IF($C$2="Mgmt (Adj)",W38))) -> 0 | X36: =IF($C$2="AV",X39,IF($C$2="Mgmt",X37,IF($C$2="Mgmt (Adj)",X38))) -> 0 | Y36: =IF($C$2="AV",Y39,IF($C$2="Mgmt",Y37,IF($C$2="Mgmt (Adj)",Y38))) -> 0 | Z36: . | AA36: =IF($C$2="AV",AA39,IF($C$2="Mgmt",AA37,IF($C$2="Mgmt (Adj)",AA38))) -> 0 | AB36: =IF($C$2="AV",AB39,IF($C$2="Mgmt",AB37,IF($C$2="Mgmt (Adj)",AB38))) -> 0 | AC36: =IF($C$2="AV",AC39,IF($C$2="Mgmt",AC37,IF($C$2="Mgmt (Adj)",AC38))) -> 0 | AD36: =IF($C$2="AV",AD39,IF($C$2="Mgmt",AD37,IF($C$2="Mgmt (Adj)",AD38))) -> 0 | AE36: =SUM(S36:AD36) -> 0 | AH36: =SUMPRODUCT($E$6:$AD$6,E36:AD36) -> 0 | AI36: =SUMPRODUCT($E$5:$AD$5,E36:AD36) -> 0
C37: plan (Mgmt) | Q37: =SUM(E37:P37) -> 0 | AE37: =SUM(S37:AD37) -> 0 | AH37: =SUMPRODUCT($E$6:$AD$6,E37:AD37) -> 0 | AI37: =SUMPRODUCT($E$5:$AD$5,E37:AD37) -> 0
C38: plan (Mgmt Adj) | Q38: =SUM(E38:P38) -> 0 | AE38: =SUM(S38:AD38) -> 0 | AH38: =SUMPRODUCT($E$6:$AD$6,E38:AD38) -> 0 | AI38: =SUMPRODUCT($E$5:$AD$5,E38:AD38) -> 0
C39: plan (AV) | Q39: =SUM(E39:P39) -> 0 | AE39: =SUM(S39:AD39) -> 0 | AH39: =SUMPRODUCT($E$6:$AD$6,E39:AD39) -> 0 | AI39: =SUMPRODUCT($E$5:$AD$5,E39:AD39) -> 0
B40: Revenue Stream 2 | C40: Actual | E40: =E19 -> 5053.2297 | F40: =F19 -> 5050.7412 | G40: =G19 -> 25050.25 | H40: =H19 -> 5075.6412 | I40: =I19 -> 5083.0621 | J40: =J19 -> 5101.8235 | K40: =K19 -> 5100 | L40: =L19 -> 10000.003 | ... P40: =P19 -> -10000.001 | Q40: =SUM(E40:P40) -> 85514.75 | S40: =S19 -> 10000 | T40: =T19 -> 10000 | U40: =U19 -> 9999.9973 | AE40: =SUM(S40:AD40) -> 29999.997 | AH40: =SUMPRODUCT($E$6:$AD$6,E40:AD40) -> 10000 | AI40: =SUMPRODUCT($E$5:$AD$5,E40:AD40) -> 10000
C41: =IF($C$2="AV",C44,IF($C$2="Mgmt",C42,IF($C$2="Mgmt (Adj)",C43))) -> plan (AV) | E41: =IF($C$2="AV",E44,IF($C$2="Mgmt",E42,IF($C$2="Mgmt (Adj)",E43))) -> 0 | F41: =IF($C$2="AV",F44,IF($C$2="Mgmt",F42,IF($C$2="Mgmt (Adj)",F43))) -> 0 | G41: =IF($C$2="AV",G44,IF($C$2="Mgmt",G42,IF($C$2="Mgmt (Adj)",G43))) -> 0 | H41: =IF($C$2="AV",H44,IF($C$2="Mgmt",H42,IF($C$2="Mgmt (Adj)",H43))) -> 0 | I41: =IF($C$2="AV",I44,IF($C$2="Mgmt",I42,IF($C$2="Mgmt (Adj)",I43))) -> 0 | J41: =IF($C$2="AV",J44,IF($C$2="Mgmt",J42,IF($C$2="Mgmt (Adj)",J43))) -> 0 | K41: =IF($C$2="AV",K44,IF($C$2="Mgmt",K42,IF($C$2="Mgmt (Adj)",K43))) -> 0 | L41: =IF($C$2="AV",L44,IF($C$2="Mgmt",L42,IF($C$2="Mgmt (Adj)",L43))) -> 0 | ... P41: =IF($C$2="AV",P44,IF($C$2="Mgmt",P42,IF($C$2="Mgmt (Adj)",P43))) -> 0 | Q41: =SUM(E41:P41) -> 0 | S41: =IF($C$2="AV",S44,IF($C$2="Mgmt",S42,IF($C$2="Mgmt (Adj)",S43))) -> 0 | T41: =IF($C$2="AV",T44,IF($C$2="Mgmt",T42,IF($C$2="Mgmt (Adj)",T43))) -> 0 | U41: =IF($C$2="AV",U44,IF($C$2="Mgmt",U42,IF($C$2="Mgmt (Adj)",U43))) -> 0 | V41: =IF($C$2="AV",V44,IF($C$2="Mgmt",V42,IF($C$2="Mgmt (Adj)",V43))) -> 0 | W41: =IF($C$2="AV",W44,IF($C$2="Mgmt",W42,IF($C$2="Mgmt (Adj)",W43))) -> 0 | X41: =IF($C$2="AV",X44,IF($C$2="Mgmt",X42,IF($C$2="Mgmt (Adj)",X43))) -> 0 | Y41: =IF($C$2="AV",Y44,IF($C$2="Mgmt",Y42,IF($C$2="Mgmt (Adj)",Y43))) -> 0 | Z41: =IF($C$2="AV",Z44,IF($C$2="Mgmt",Z42,IF($C$2="Mgmt (Adj)",Z43))) -> 0 | ... AD41: =IF($C$2="AV",AD44,IF($C$2="Mgmt",AD42,IF($C$2="Mgmt (Adj)",AD43))) -> 0 | AE41: =SUM(S41:AD41) -> 0 | AH41: =SUMPRODUCT($E$6:$AD$6,E41:AD41) -> 0 | AI41: =SUMPRODUCT($E$5:$AD$5,E41:AD41) -> 0
...

Sheet Balance Sheet
E1: USD
B2: Balance Sheet | C2: USD | E2: 45627 | G2: ='[3]P&L'!E7 -> 45688 | H2: ='[3]P&L'!F7 -> 45716 | I2: ='[3]P&L'!G7 -> 45747 | J2: ='[3]P&L'!H7 -> 45777 | K2: ='[3]P&L'!I7 -> 45808 | L2: ='[3]P&L'!J7 -> 45838 | M2: ='[3]P&L'!K7 -> 45869 | N2: ='[3]P&L'!L7 -> 45900 | ... R2: ='[3]P&L'!P7 -> 46022 | T2: ='[3]P&L'!S7 -> 46053 | U2: ='[3]P&L'!T7 -> 46081 | V2: ='[3]P&L'!U7 -> 46112 | W2: ='[3]P&L'!V7 -> 46142 | X2: ='[3]P&L'!W7 -> 46173 | Y2: ='[3]P&L'!X7 -> 46203 | Z2: ='[3]P&L'!Y7 -> 46234 | AA2: ='[3]P&L'!Z7 -> 46265 | ... AE2: ='[3]P&L'!AD7 -> 46387
A3: Checker | E3: ='[2]Detailed FS_$ Cons. (formating)'!$BP$188-E4 -> 0 | G3: ='[2]Detailed FS_$ Cons. (formating)'!BR$188-G4 -> 0 | H3: ='[2]Detailed FS_$ Cons. (formating)'!BS$188-H4 -> 0 | I3: ='[2]Detailed FS_$ Cons. (formating)'!BT$188-I4 -> 0 | J3: ='[2]Detailed FS_$ Cons. (formating)'!BU$188-J4 -> 0 | K3: ='[2]Detailed FS_$ Cons. (formating)'!BV$188-K4 -> 0 | L3: ='[2]Detailed FS_$ Cons. (formating)'!BW$188-L4 -> 0 | M3: ='[2]Detailed FS_$ Cons. (formating)'!BX$188-M4 -> 0 | N3: ='[2]Detailed FS_$ Cons. (formating)'!BY$188-N4 -> 0 | ... R3: ='[2]Detailed FS_$ Cons. (formating)'!CC$188-R4 -> 0 | T3: ='[2]Detailed FS_$ Cons. (formating)'!CF$188-T4 -> 0 | U3: ='[2]Detailed FS_$ Cons. (formating)'!CG$188-U4 -> 0 | V3: ='[2]Detailed FS_$ Cons. (formating)'!CH$188-V4 -> 0 | AE3: 12 Months
B4: Assets | C4: Actual | E4: =SUM(E5:E13) -> 887568.4 | G4: =SUM(G5:G13) -> 741101.72 | H4: =SUM(H5:H13) -> 4038449.8 | I4: =SUM(I5:I13) -> 6847077 | J4: =SUM(J5:J13) -> 6592995.8 | K4: =SUM(K5:K13) -> 6266914.8 | L4: =SUM(L5:L13) -> 6049231.6 | M4: =SUM(M5:M13) -> 6739571.5 | N4: =SUM(N5:N13) -> 6333649.8 | ... R4: =SUM(R5:R13) -> 5686209.7 | T4: =SUM(T5:T13) -> 5184093.8 | U4: =SUM(U5:U13) -> 4798490.2 | V4: =SUM(V5:V13) -> 4743704.5 | W4: =W6+SUM(W10:W13) -> 0 | X4: =X6+SUM(X10:X13) -> 0 | Y4: =Y6+SUM(Y10:Y13) -> 0 | Z4: =Z6+SUM(Z10:Z13) -> 0 | AA4: =AA6+SUM(AA10:AA13) -> 0 | AB4: =AB6+SUM(AB10:AB13) -> 0 | AC4: =AC6+SUM(AC10:AC13) -> 0 | AD4: =AD6+SUM(AD10:AD13) -> 0 | AE4: =AE6+SUM(AE10:AE13) -> 0
B5: Fixed Assets | C5: Actual | E5: ='[2]Detailed FS_$ Cons. (formating)'!$BP$172 -> 292255.82 | G5: ='[3]BS breakdown'!D14 -> 303526.35 | H5: ='[3]BS breakdown'!E14 -> 380654.78 | I5: ='[3]BS breakdown'!F14 -> 385328.45 | J5: ='[3]BS breakdown'!G14 -> 379589.75 | K5: ='[3]BS breakdown'!H14 -> 499059.9 | L5: ='[3]BS breakdown'!I14 -> 518647.1 | M5: ='[3]BS breakdown'!J14 -> 1783518.3 | N5: ='[3]BS breakdown'!K14 -> 1760098.4 | ... R5: ='[3]BS breakdown'!O14 -> 2070950.3 | T5: ='[3]BS breakdown'!Q14 -> 2099951 | U5: ='[3]BS breakdown'!R14 -> 2058243.3 | V5: ='[3]BS breakdown'!S14 -> 1868794.7
B6: Cash | C6: Actual | E6: ='[2]Detailed FS_$ Cons. (formating)'!$BP$174+'[2]Detailed FS_$ Cons. (formating)'!$BP$177+'[2]Detailed FS_$ Cons. (formating)'!$BP$175 -> 506664.22 | G6: ='[2]Detailed FS_$ Cons. (formating)'!BR$174+'[2]Detailed FS_$ Cons. (formating)'!BR$176+'[2]Detailed FS_$ Cons. (formating)'!BR$177+'[2]Detailed FS_$ Cons. (formating)'!BR$175 -> 297295.28 | H6: ='[2]Detailed FS_$ Cons. (formating)'!BS$174+'[2]Detailed FS_$ Cons. (formating)'!BS$176+'[2]Detailed FS_$ Cons. (formating)'!BS$177+'[2]Detailed FS_$ Cons. (formating)'!BS$175 -> 3496368.1 | I6: ='[2]Detailed FS_$ Cons. (formating)'!BT$174+'[2]Detailed FS_$ Cons. (formating)'!BT$176+'[2]Detailed FS_$ Cons. (formating)'!BT$177+'[2]Detailed FS_$ Cons. (formating)'!BT$175 -> 6273141.9 | J6: ='[2]Detailed FS_$ Cons. (formating)'!BU$174+'[2]Detailed FS_$ Cons. (formating)'!BU$176+'[2]Detailed FS_$ Cons. (formating)'!BU$177+'[2]Detailed FS_$ Cons. (formating)'!BU$175 -> 5795831.3 | K6: ='[2]Detailed FS_$ Cons. (formating)'!BV$174+'[2]Detailed FS_$ Cons. (formating)'!BV$176+'[2]Detailed FS_$ Cons. (formating)'!BV$177+'[2]Detailed FS_$ Cons. (formating)'!BV$175 -> 5294020.1 | L6: ='[2]Detailed FS_$ Cons. (formating)'!BW$174+'[2]Detailed FS_$ Cons. (formating)'!BW$176+'[2]Detailed FS_$ Cons. (formating)'!BW$177+'[2]Detailed FS_$ Cons. (formating)'!BW$175 -> 5033527.6 | M6: ='[2]Detailed FS_$ Cons. (formating)'!BX$174+'[2]Detailed FS_$ Cons. (formating)'!BX$176+'[2]Detailed FS_$ Cons. (formating)'!BX$177+'[2]Detailed FS_$ Cons. (formating)'!BX$175 -> 4447724.2 | N6: ='[2]Detailed FS_$ Cons. (formating)'!BY$174+'[2]Detailed FS_$ Cons. (formating)'!BY$176+'[2]Detailed FS_$ Cons. (formating)'!BY$177+'[2]Detailed FS_$ Cons. (formating)'!BY$175 -> 4147955.3 | ... R6: ='[2]Detailed FS_$ Cons. (formating)'!CC$174+'[2]Detailed FS_$ Cons. (formating)'!CC$176+'[2]Detailed FS_$ Cons. (formating)'!CC$177+'[2]Detailed FS_$ Cons. (formating)'!CC$175 -> 3123512 | T6: ='[2]Detailed FS_$ Cons. (formating)'!CF$174+'[2]Detailed FS_$ Cons. (formating)'!CF$176+'[2]Detailed FS_$ Cons. (formating)'!CF$177+'[2]Detailed FS_$ Cons. (formating)'!CF$175 -> 2596045.7 | U6: ='[2]Detailed FS_$ Cons. (formating)'!CG$174+'[2]Detailed FS_$ Cons. (formating)'!CG$176+'[2]Detailed FS_$ Cons. (formating)'!CG$177+'[2]Detailed FS_$ Cons. (formating)'!CG$175 -> 2210632.7 | V6: ='[2]Detailed FS_$ Cons. (formating)'!CH$174+'[2]Detailed FS_$ Cons. (formating)'!CH$176+'[2]Detailed FS_$ Cons. (formating)'!CH$177+'[2]Detailed FS_$ Cons. (formating)'!CH$175 -> 1929247.4
C7: plan (Mgmt)
C8: plan (Mgmt Adj)
C9: plan (AV)
B10: Receivables | C10: Actual | E10: ='[2]Detailed FS_$ Cons. (formating)'!$BP$178 -> 42763.016 | G10: ='[2]Detailed FS_$ Cons. (formating)'!BR$178 -> 58637.47 | H10: ='[2]Detailed FS_$ Cons. (formating)'!BS$178 -> 91091.643 | I10: ='[2]Detailed FS_$ Cons. (formating)'!BT$178 -> 78002.464 | J10: ='[2]Detailed FS_$ Cons. (formating)'!BU$178 -> 83079.769 | K10: ='[2]Detailed FS_$ Cons. (formating)'!BV$178 -> 88115.821 | L10: ='[2]Detailed FS_$ Cons. (formating)'!BW$178 -> 93226.055 | M10: ='[2]Detailed FS_$ Cons. (formating)'!BX$178 -> 25667.125 | N10: ='[2]Detailed FS_$ Cons. (formating)'!BY$178 -> 35674.716 | ... R10: ='[2]Detailed FS_$ Cons. (formating)'!CC$178 -> 214271.28 | T10: ='[2]Detailed FS_$ Cons. (formating)'!CF$178 -> 152470.53 | U10: ='[2]Detailed FS_$ Cons. (formating)'!CG$178 -> 123308.15 | V10: ='[2]Detailed FS_$ Cons. (formating)'!CH$178 -> 565606.03
B11: Inventory | C11: Actual | E11: ='[2]Detailed FS_$ Cons. (formating)'!$BP$179 -> 0 | G11: ='[2]Detailed FS_$ Cons. (formating)'!BR$179 -> 0 | H11: ='[2]Detailed FS_$ Cons. (formating)'!BS$179 -> 0 | I11: ='[2]Detailed FS_$ Cons. (formating)'!BT$179 -> 0 | J11: ='[2]Detailed FS_$ Cons. (formating)'!BU$179 -> 0 | K11: ='[2]Detailed FS_$ Cons. (formating)'!BV$179 -> 0 | L11: ='[2]Detailed FS_$ Cons. (formating)'!BW$179 -> 0 | M11: ='[2]Detailed FS_$ Cons. (formating)'!BX$179 -> 0 | N11: ='[2]Detailed FS_$ Cons. (formating)'!BY$179 -> 0 | ... R11: ='[2]Detailed FS_$ Cons. (formating)'!CC$179 -> 0 | T11: ='[2]Detailed FS_$ Cons. (formating)'!CF$179 -> 0 | U11: ='[2]Detailed FS_$ Cons. (formating)'!CG$179 -> 0 | V11: ='[2]Detailed FS_$ Cons. (formating)'!CH$179 -> 0
B12: Prepaid Expenses | C12: Actual | E12: ='[2]Detailed FS_$ Cons. (formating)'!$BP$181 -> 27863.813 | G12: ='[3]BS breakdown'!D24 -> 60758.357 | H12: ='[3]BS breakdown'!E24 -> 47826.265 | I12: ='[3]BS breakdown'!F24 -> 33752.716 | J12: ='[3]BS breakdown'!G24 -> 55587.752 | K12: ='[3]BS breakdown'!H24 -> 101282.58 | L12: ='[3]BS breakdown'!I24 -> 116927.06 | M12: ='[3]BS breakdown'!J24 -> 189011.03 | N12: ='[3]BS breakdown'!K24 -> 92484.866 | ... R12: ='[3]BS breakdown'!O24 -> 85929.038 | T12: ='[3]BS breakdown'!Q24 -> 145299.66 | U12: ='[3]BS breakdown'!R24 -> 131963.73 | V12: ='[3]BS breakdown'!S24 -> 144526.8
B13: Other Assets | C13: Actual | E13: ='[2]Detailed FS_$ Cons. (formating)'!$BP$180+'[2]Detailed FS_$ Cons. (formating)'!$BP$182+'[2]Detailed FS_$ Cons. (formating)'!$BP$184+'[2]Detailed FS_$ Cons. (formating)'!$BP$183 -> 18021.527 | G13: ='[3]BS breakdown'!D32 -> 20884.26 | H13: ='[3]BS breakdown'!E32 -> 22509.012 | I13: ='[3]BS breakdown'!F32 -> 76851.518 | J13: ='[3]BS breakdown'!G32 -> 278907.25 | K13: ='[3]BS breakdown'!H32 -> 284436.43 | L13: ='[3]BS breakdown'!I32 -> 286903.83 | M13: ='[3]BS breakdown'!J32 -> 293650.88 | N13: ='[3]BS breakdown'!K32 -> 297436.52 | ... R13: ='[3]BS breakdown'!O32 -> 191547.03 | T13: ='[3]BS breakdown'!Q32 -> 190326.92 | U13: ='[3]BS breakdown'!R32 -> 274342.32 | V13: ='[3]BS breakdown'!S32 -> 235529.63
A14: Checker | E14: ='[2]Detailed FS_$ Cons. (formating)'!$BP$194+'[2]Detailed FS_$ Cons. (formating)'!$BP$201-E15 -> 0 | G14: =('[2]Detailed FS_$ Cons. (formating)'!BR$194+'[2]Detailed FS_$ Cons. (formating)'!BR$201)-G15 -> 0 | H14: =('[2]Detailed FS_$ Cons. (formating)'!BS$194+'[2]Detailed FS_$ Cons. (formating)'!BS$201)-H15 -> 0 | I14: =('[2]Detailed FS_$ Cons. (formating)'!BT$194+'[2]Detailed FS_$ Cons. (formating)'!BT$201)-I15 -> 0 | J14: =('[2]Detailed FS_$ Cons. (formating)'!BU$194+'[2]Detailed FS_$ Cons. (formating)'!BU$201)-J15 -> 0 | K14: =('[2]Detailed FS_$ Cons. (formating)'!BV$194+'[2]Detailed FS_$ Cons. (formating)'!BV$201)-K15 -> 0 | L14: =('[2]Detailed FS_$ Cons. (formating)'!BW$194+'[2]Detailed FS_$ Cons. (formating)'!BW$201)-L15 -> 0 | M14: =('[2]Detailed FS_$ Cons. (formating)'!BX$194+'[2]Detailed FS_$ Cons. (formating)'!BX$201)-M15 -> 0 | N14: =('[2]Detailed FS_$ Cons. (formating)'!BY$194+'[2]Detailed FS_$ Cons. (formating)'!BY$201)-N15 -> 0 | ... R14: =('[2]Detailed FS_$ Cons. (formating)'!CC$194+'[2]Detailed FS_$ Cons. (formating)'!CC$201)-R15 -> 0 | T14: =('[2]Detailed FS_$ Cons. (formating)'!CF$194+'[2]Detailed FS_$ Cons. (formating)'!CF$201)-T15 -> 0 | U14: =('[2]Detailed FS_$ Cons. (formating)'!CG$194+'[2]Detailed FS_$ Cons. (formating)'!CG$201)-U15 -> 0 | V14: =('[2]Detailed FS_$ Cons. (formating)'!CH$194+'[2]Detailed FS_$ Cons. (formating)'!CH$201)-V15 -> 0
B15: Liabilities | C15: Actual | E15: =E16+SUM(E22:E23) -> 227734.05 | G15: =G16+SUM(G22:G23) -> 285834.87 | H15: =H16+SUM(H22:H23) -> 470790.17 | I15: =I16+SUM(I22:I23) -> 147176.02 | J15: =J16+SUM(J22:J23) -> 154781.86 | K15: =K16+SUM(K22:K23) -> 121216.15 | L15: =L16+SUM(L22:L23) -> 133381.11 | M15: =M16+SUM(M22:M23) -> 1216847.2 | N15: =N16+SUM(N22:N23) -> 1092191 | ... R15: =R16+SUM(R22:R23) -> 1247263.5 | T15: =T16+SUM(T22:T23) -> 1149132 | U15: =U16+SUM(U22:U23) -> 1163902.8 | V15: =V16+SUM(V22:V23) -> 1188475.2 | W15: =W16+SUM(W22:W23) -> 0 | X15: =X16+SUM(X22:X23) -> 0 | Y15: =Y16+SUM(Y22:Y23) -> 0 | Z15: =Z16+SUM(Z22:Z23) -> 0 | AA15: =AA16+SUM(AA22:AA23) -> 0 | ... AE15: =AE16+SUM(AE22:AE23) -> 0
B16: Payables & Accruals | C16: Actual | E16: =SUM(E17:E21) -> 179687.05 | G16: =SUM(G17:G21) -> 236758.46 | H16: =SUM(H17:H21) -> 440345.5 | I16: =SUM(I17:I21) -> 122800.42 | J16: =SUM(J17:J21) -> 130117.42 | K16: =SUM(K17:K21) -> 88912.979 | L16: =SUM(L17:L21) -> 100550.81 | M16: =SUM(M17:M21) -> 92500.462 | N16: =SUM(N17:N21) -> 5127.4464 | ... R16: =SUM(R17:R21) -> 209234.47 | T16: =SUM(T17:T21) -> 162239.43 | U16: =SUM(U17:U21) -> 173995.13 | V16: =SUM(V17:V21) -> 303666.7 | W16: =SUM(W17:W21) -> 0 | X16: =SUM(X17:X21) -> 0 | Y16: =SUM(Y17:Y21) -> 0 | Z16: =SUM(Z17:Z21) -> 0 | AA16: =SUM(AA17:AA21) -> 0 | ... AE16: =SUM(AE17:AE21) -> 0
B17: Employees Payable | C17: Actual
B18: Government Payable | C18: Actual | E18: ='[2]Detailed FS_$ Cons. (formating)'!$BO$197 -> 2244.9835 | G18: ='[3]BS breakdown'!D46 -> 519.31848 | H18: ='[3]BS breakdown'!E46 -> 531.98532 | I18: ='[3]BS breakdown'!F46 -> 1146.548 | J18: ='[3]BS breakdown'!G46 -> 637.93315 | K18: ='[3]BS breakdown'!H46 -> 759.25743 | L18: ='[3]BS breakdown'!I46 -> 999.33513 | M18: ='[3]BS breakdown'!J46 -> 153.04997 | N18: ='[3]BS breakdown'!K46 -> 414.21757 | ... R18: ='[3]BS breakdown'!O46 -> 8828.6184 | T18: ='[3]BS breakdown'!Q46 -> 3709.5141 | U18: ='[3]BS breakdown'!R46 -> 3904.6711 | V18: ='[3]BS breakdown'!S46 -> 5799.3091
B19: Suppliers Payable | C19: Actual | E19: ='[2]Detailed FS_$ Cons. (formating)'!$BO$196 -> 177442.07 | G19: ='[2]Detailed FS_$ Cons. (formating)'!BR$196 -> 236239.14 | H19: ='[2]Detailed FS_$ Cons. (formating)'!BS$196 -> 439813.52 | I19: ='[2]Detailed FS_$ Cons. (formating)'!BT$196 -> 121653.87 | J19: ='[2]Detailed FS_$ Cons. (formating)'!BU$196 -> 129479.48 | K19: ='[2]Detailed FS_$ Cons. (formating)'!BV$196 -> 88153.721 | L19: ='[2]Detailed FS_$ Cons. (formating)'!BW$196 -> 99551.477 | M19: ='[2]Detailed FS_$ Cons. (formating)'!BX$196 -> 92347.412 | N19: ='[2]Detailed FS_$ Cons. (formating)'!BY$196 -> 4713.2288 | ... R19: ='[2]Detailed FS_$ Cons. (formating)'!CC$196 -> 200405.85 | T19: ='[2]Detailed FS_$ Cons. (formating)'!CF$196 -> 158529.92 | U19: ='[2]Detailed FS_$ Cons. (formating)'!CG$196 -> 170090.46 | V19: ='[2]Detailed FS_$ Cons. (formating)'!CH$196 -> 243867.39
B20: Customer Payable | C20: Actual
B21: Other Payable | C21: Actual | V21: ='[2]Detailed FS_$ Cons. (formating)'!$CH$200 -> 54000
B22: Lease Liability / Non current lia. | C22: Actual | E22: ='[2]Detailed FS_$ Cons. (formating)'!$BP$191+'[2]Detailed FS_$ Cons. (formating)'!$BO$192 -> 46864.955 | G22: ='[2]Detailed FS_$ Cons. (formating)'!BR$191 -> 41346.414 | H22: ='[2]Detailed FS_$ Cons. (formating)'!BS$191 -> 41566.108 | I22: ='[2]Detailed FS_$ Cons. (formating)'!BT$191 -> 35739.445 | J22: ='[2]Detailed FS_$ Cons. (formating)'!BU$191 -> 36079.359 | K22: ='[2]Detailed FS_$ Cons. (formating)'!BV$191 -> 37359.409 | L22: ='[2]Detailed FS_$ Cons. (formating)'!BW$191 -> 37978.668 | M22: ='[2]Detailed FS_$ Cons. (formating)'!BX$191 -> 1129370.3 | N22: ='[2]Detailed FS_$ Cons. (formating)'!BY$191 -> 1092186.5 | ... R22: ='[2]Detailed FS_$ Cons. (formating)'!CC$191 -> 1020736.2 | T22: ='[2]Detailed FS_$ Cons. (formating)'!CF$191 -> 969956.06 | U22: ='[2]Detailed FS_$ Cons. (formating)'!CG$191 -> 973022.11 | V22: ='[2]Detailed FS_$ Cons. (formating)'!CH$191 -> 869721.86
B23: Other Current Liabilities | C23: Actual | E23: ='[2]Detailed FS_$ Cons. (formating)'!$BP$199+'[2]Detailed FS_$ Cons. (formating)'!$BP$198+'[2]Detailed FS_$ Cons. (formating)'!$BP$193 -> 1182.0435 | G23: ='[3]BS breakdown'!D55 -> 7729.9921 | H23: ='[3]BS breakdown'!E55 -> -11121.437 | I23: ='[3]BS breakdown'!F55 -> -11363.839 | J23: ='[3]BS breakdown'!G55 -> -11414.91 | K23: ='[3]BS breakdown'!H55 -> -5056.2354 | L23: ='[3]BS breakdown'!I55 -> -5148.3701 | M23: ='[3]BS breakdown'!J55 -> -5023.5946 | N23: ='[3]BS breakdown'!K55 -> -5122.9869 | ... R23: ='[3]BS breakdown'!O55 -> 17292.839 | T23: ='[3]BS breakdown'!Q55 -> 16936.519 | U23: ='[3]BS breakdown'!R55 -> 16885.54 | V23: ='[3]BS breakdown'!S55 -> 15086.629
A24: Checker | E24: ='[2]Detailed FS_$ Cons. (formating)'!$BP$210-E25 -> 0 | G24: ='[2]Detailed FS_$ Cons. (formating)'!BR$210-G25 -> 0 | H24: ='[2]Detailed FS_$ Cons. (formating)'!BS$210-H25 -> 0 | I24: ='[2]Detailed FS_$ Cons. (formating)'!BT$210-I25 -> 0 | J24: ='[2]Detailed FS_$ Cons. (formating)'!BU$210-J25 -> 0 | K24: ='[2]Detailed FS_$ Cons. (formating)'!BV$210-K25 -> 0 | L24: ='[2]Detailed FS_$ Cons. (formating)'!BW$210-L25 -> 0 | M24: ='[2]Detailed FS_$ Cons. (formating)'!BX$210-M25 -> 0 | N24: ='[2]Detailed FS_$ Cons. (formating)'!BY$210-N25 -> 0 | ... R24: ='[2]Detailed FS_$ Cons. (formating)'!CC$210-R25 -> 0 | T24: ='[2]Detailed FS_$ Cons. (formating)'!CF$210-T25 -> 0 | U24: ='[2]Detailed FS_$ Cons. (formating)'!CG$210-U25 -> 0 | V24: ='[2]Detailed FS_$ Cons. (formating)'!CH$210-V25 -> 0
B25: Owners Equity | C25: Actual | E25: =E27+E28+E26 -> 659834.34 | G25: =G27+G28+G26 -> 455266.85 | H25: =H27+H28+H26 -> 3567659.6 | I25: =I27+I28+I26 -> 6699901 | J25: =J27+J28+J26 -> 6438213.9 | K25: =K27+K28+K26 -> 6145698.7 | L25: =L27+L28+L26 -> 5915850.5 | M25: =M27+M28+M26 -> 5522724.3 | N25: =N27+N28+N26 -> 5241458.8 | ... R25: =R27+R28+R26 -> 4438946.2 | T25: =T27+T28+T26 -> 4034961.8 | U25: =U27+U28+U26 -> 3634587.4 | V25: =V27+V28+V26 -> 3555229.3
B26: Translation Adj. | E26: ='[2]Detailed FS_$ Cons. (formating)'!$BP$209 -> 68240.513 | G26: ='[2]Detailed FS_$ Cons. (formating)'!BR$209 -> 71595.066 | H26: ='[2]Detailed FS_$ Cons. (formating)'!BS$209 -> 67938.805 | I26: ='[2]Detailed FS_$ Cons. (formating)'!BT$209 -> 68138.573 | J26: ='[2]Detailed FS_$ Cons. (formating)'!BU$209 -> 66639.431 | K26: ='[2]Detailed FS_$ Cons. (formating)'!BV$209 -> 73252.096 | L26: ='[2]Detailed FS_$ Cons. (formating)'!BW$209 -> 75978.478 | M26: ='[2]Detailed FS_$ Cons. (formating)'!BX$209 -> 83149.946 | N26: ='[2]Detailed FS_$ Cons. (formating)'!BY$209 -> 59068.703 | ... R26: ='[2]Detailed FS_$ Cons. (formating)'!CC$209 -> 68098.651 | T26: ='[2]Detailed FS_$ Cons. (formating)'!CF$209 -> 67605.507 | U26: ='[2]Detailed FS_$ Cons. (formating)'!CG$209 -> 54569.865 | V26: ='[2]Detailed FS_$ Cons. (formating)'!CH$209 -> -43305.909
B27: Earnings | C27: Actual | E27: ='[2]Detailed FS_$ Cons. (formating)'!$BP$206 -> -1823199.6 | G27: ='[2]Detailed FS_$ Cons. (formating)'!BR$206 -> -2031121.7 | H27: ='[2]Detailed FS_$ Cons. (formating)'!BS$206 -> -2290072.6 | I27: ='[2]Detailed FS_$ Cons. (formating)'!BT$206 -> -2533031 | J27: ='[2]Detailed FS_$ Cons. (formating)'!BU$206 -> -2793219 | K27: ='[2]Detailed FS_$ Cons. (formating)'!BV$206 -> -3092147.5 | L27: ='[2]Detailed FS_$ Cons. (formating)'!BW$206 -> -3324722.1 | M27: ='[2]Detailed FS_$ Cons. (formating)'!BX$206 -> -3725019.7 | N27: ='[2]Detailed FS_$ Cons. (formating)'!BY$206 -> -3982204 | ... R27: ='[2]Detailed FS_$ Cons. (formating)'!CC$206 -> -4910173.2 | T27: ='[2]Detailed FS_$ Cons. (formating)'!CF$206 -> -5313664.5 | U27: ='[2]Detailed FS_$ Cons. (formating)'!CG$206 -> -5701003.2 | V27: ='[2]Detailed FS_$ Cons. (formating)'!CH$206 -> -5682485.5
B28: Capital | C28: Actual | E28: ='[2]Detailed FS_$ Cons. (formating)'!$BP$203 -> 2414793.5 | G28: ='[2]Detailed FS_$ Cons. (formating)'!BR$203 -> 2414793.5 | H28: ='[2]Detailed FS_$ Cons. (formating)'!BS$203 -> 5789793.5 | I28: ='[2]Detailed FS_$ Cons. (formating)'!BT$203 -> 9164793.5 | J28: ='[2]Detailed FS_$ Cons. (formating)'!BU$203 -> 9164793.5 | K28: ='[2]Detailed FS_$ Cons. (formating)'!BV$203 -> 9164594.1 | L28: ='[2]Detailed FS_$ Cons. (formating)'!BW$203+'[2]Detailed FS_$ Cons. (formating)'!BW$204+'[2]Detailed FS_$ Cons. (formating)'!BW$205 -> 9164594.1 | M28: ='[2]Detailed FS_$ Cons. (formating)'!BX$203+'[2]Detailed FS_$ Cons. (formating)'!BX$204+'[2]Detailed FS_$ Cons. (formating)'!BX$205 -> 9164594.1 | N28: ='[2]Detailed FS_$ Cons. (formating)'!BY$203+'[2]Detailed FS_$ Cons. (formating)'!BY$204+'[2]Detailed FS_$ Cons. (formating)'!BY$205 -> 9164594.1 | O28: ='[2]Detailed FS_$ Cons. (formating)'!BZ$203+'[2]Detailed FS_$ Cons. (formating)'!BZ$204+'[2]Detailed FS_$ Cons. (formating)'!BZ$205 -> 9281020.7 | P28: ='[2]Detailed FS_$ Cons. (formating)'!CA$203+'[2]Detailed FS_$ Cons. (formating)'!CA$204+'[2]Detailed FS_$ Cons. (formating)'!CA$205 -> 9281519.8 | Q28: ='[2]Detailed FS_$ Cons. (formating)'!CB$203+'[2]Detailed FS_$ Cons. (formating)'!CB$204+'[2]Detailed FS_$ Cons. (formating)'!CB$205 -> 9281020.7 | R28: ='[2]Detailed FS_$ Cons. (formating)'!CC$203+'[2]Detailed FS_$ Cons. (formating)'!CC$204+'[2]Detailed FS_$ Cons. (formating)'!CC$205 -> 9281020.7 | T28: ='[2]Detailed FS_$ Cons. (formating)'!CF$203+'[2]Detailed FS_$ Cons. (formating)'!CF$204+'[2]Detailed FS_$ Cons. (formating)'!CF$205 -> 9281020.7 | U28: ='[2]Detailed FS_$ Cons. (formating)'!CG$203+'[2]Detailed FS_$ Cons. (formating)'!CG$204+'[2]Detailed FS_$ Cons. (formating)'!CG$205 -> 9281020.7 | V28: ='[2]Detailed FS_$ Cons. (formating)'!CH$203+'[2]Detailed FS_$ Cons. (formating)'!CH$204+'[2]Detailed FS_$ Cons. (formating)'!CH$205 -> 9281020.7
B30: Reconciliation | E30: =E4-E15-E25 -> 0 | G30: =G4-G15-G25 -> 0 | H30: =H4-H15-H25 -> 0 | I30: =I4-I15-I25 -> 0 | J30: =J4-J15-J25 -> 0 | K30: =K4-K15-K25 -> 0 | L30: =L4-L15-L25 -> 0 | M30: =M4-M15-M25 -> 0 | N30: =N4-N15-N25 -> 0 | ... R30: =R4-R15-R25 -> 0 | T30: =T4-T15-T25 -> 0 | U30: =U4-U15-U25 -> 0 | V30: =V4-V15-V25 -> 0

Sheet CFS
A2: Cash flow | C2: 45688 | D2: 45716 | E2: 45747 | F2: 45777 | G2: 45808 | H2: 45838 | I2: 45869 | J2: 45900 | K2: 45930 | L2: 45961 | M2: 45991 | N2: 46022 | P2: 46053 | Q2: =EOMONTH(P2,1) -> 46081 | R2: =EOMONTH(Q2,1) -> 46112 | S2: =EOMONTH(R2,1) -> 46142 | T2: =EOMONTH(S2,1) -> 46173 | U2: =EOMONTH(T2,1) -> 46203 | V2: =EOMONTH(U2,1) -> 46234 | W2: =EOMONTH(V2,1) -> 46265 | X2: =EOMONTH(W2,1) -> 46295 | ... AA2: =EOMONTH(Z2,1) -> 46387
A3: EBITDA | C3: ='P&L'!E120 -> -200195.8 | D3: ='P&L'!F120 -> -254096.13 | E3: ='P&L'!G120 -> -236704.41 | F3: ='P&L'!H120 -> -252988.65 | G3: ='P&L'!I120 -> -292041.93 | H3: ='P&L'!J120 -> -224377.04 | I3: ='P&L'!K120 -> -377020.29 | J3: ='P&L'!L120 -> -248243.75 | ... N3: ='P&L'!P120 -> -32075.749 | P3: ='P&L'!S120 -> -366484.09 | Q3: ='P&L'!T120 -> -346373.03 | R3: ='P&L'!U120 -> 64903.82
A4: IFRS 16 impact | C4: =-'P&L'!E128 -> -569.27048 | D4: =-'P&L'!F128 -> -564.52276 | E4: =-'P&L'!G128 -> -565.38536 | F4: =-'P&L'!H128 -> -496.84339 | G4: =-'P&L'!I128 -> -507.48231 | H4: =-'P&L'!J128 -> -508.98031 | I4: =-'P&L'!K128 -> -446.77482 | J4: =-'P&L'!L128 -> 9531.1106 | ... N4: =-'P&L'!P128 -> -22389.327 | P4: =-'P&L'!S128 -> -15450.71 | Q4: =-'P&L'!T128 -> -15256.524 | R4: =-'P&L'!U128 -> -19358.999
A5: Tax paid | N5: =-'P&L'!P134 -> -12309.288 | P5: =-'P&L'!S134 -> 0
A6: Non Cash | C6: =-'P&L'!E129 -> -3115.8304 | D6: =-'P&L'!F129 -> 175.41584 | E6: =-'P&L'!G129 -> -75.994986 | F6: =-'P&L'!H129 -> -939.50123 | G6: =-'P&L'!I129 -> -899.89842 | H6: =-'P&L'!J129 -> -1946.4667 | I6: =-'P&L'!K129 -> 1045.9487 | J6: =-'P&L'!L129 -> 33.202888 | ... N6: =-'P&L'!P129 -> -33434.331 | P6: =-'P&L'!S129 -> 2658.0957 | Q6: =-'P&L'!T129 -> 3128.455 | R6: =-'P&L'!U129 -> -5.4962889
A7: Other income & Gain on sale | C7: =-'P&L'!E127 -> 211.75355 | D7: =-'P&L'!F127 -> 64.226178 | E7: =-'P&L'!G127 -> -80.191851 | F7: =-'P&L'!H127 -> -232.86536 | G7: =-'P&L'!I127 -> 152.4943 | H7: =-'P&L'!J127 -> -24.462678 | I7: =-'P&L'!K127 -> 194.27339 | J7: =-'P&L'!L127 -> 20424.817 | ... N7: =-'P&L'!P127 -> 11414.269 | P7: =-'P&L'!S127 -> 4729.0445 | Q7: =-'P&L'!T127 -> 919.77754 | R7: =-'P&L'!U127 -> 653.18417
A8: WC Movements | C8: =-('Balance Sheet'!G10-'Balance Sheet'!E10)-('Balance Sheet'!G11-'Balance Sheet'!E11)-('Balance Sheet'!G12-'Balance Sheet'!E12)-('Balance Sheet'!G13-'Balance Sheet'!E13)+('Balance Sheet'!G16-'Balance Sheet'!E16) -> 5439.6793 | D8: =-('Balance Sheet'!H10-'Balance Sheet'!G10)-('Balance Sheet'!H11-'Balance Sheet'!G11)-('Balance Sheet'!H12-'Balance Sheet'!G12)-('Balance Sheet'!H13-'Balance Sheet'!G13)+('Balance Sheet'!H16-'Balance Sheet'!G16) -> 182440.21 | E8: =-('Balance Sheet'!I10-'Balance Sheet'!H10)-('Balance Sheet'!I11-'Balance Sheet'!H11)-('Balance Sheet'!I12-'Balance Sheet'!H12)-('Balance Sheet'!I13-'Balance Sheet'!H13)+('Balance Sheet'!I16-'Balance Sheet'!H16) -> -344724.86 | F8: =-('Balance Sheet'!J10-'Balance Sheet'!I10)-('Balance Sheet'!J11-'Balance Sheet'!I11)-('Balance Sheet'!J12-'Balance Sheet'!I12)-('Balance Sheet'!J13-'Balance Sheet'!I13)+('Balance Sheet'!J16-'Balance Sheet'!I16) -> -221651.08 | G8: =-('Balance Sheet'!K10-'Balance Sheet'!J10)-('Balance Sheet'!K11-'Balance Sheet'!J11)-('Balance Sheet'!K12-'Balance Sheet'!J12)-('Balance Sheet'!K13-'Balance Sheet'!J13)+('Balance Sheet'!K16-'Balance Sheet'!J16) -> -97464.497 | H8: =-('Balance Sheet'!L10-'Balance Sheet'!K10)-('Balance Sheet'!L11-'Balance Sheet'!K11)-('Balance Sheet'!L12-'Balance Sheet'!K12)-('Balance Sheet'!L13-'Balance Sheet'!K13)+('Balance Sheet'!L16-'Balance Sheet'!K16) -> -11584.268 | I8: =-('Balance Sheet'!M10-'Balance Sheet'!L10)-('Balance Sheet'!M11-'Balance Sheet'!L11)-('Balance Sheet'!M12-'Balance Sheet'!L12)-('Balance Sheet'!M13-'Balance Sheet'!L13)+('Balance Sheet'!M16-'Balance Sheet'!L16) -> -19322.445 | J8: =-('Balance Sheet'!N10-'Balance Sheet'!M10)-('Balance Sheet'!N11-'Balance Sheet'!M11)-('Balance Sheet'!N12-'Balance Sheet'!M12)-('Balance Sheet'!N13-'Balance Sheet'!M13)+('Balance Sheet'!N16-'Balance Sheet'!M16) -> -4640.0833 | K8: =-('Balance Sheet'!O10-'Balance Sheet'!N10)-('Balance Sheet'!O11-'Balance Sheet'!N11)-('Balance Sheet'!O12-'Balance Sheet'!N12)-('Balance Sheet'!O13-'Balance Sheet'!N13)+('Balance Sheet'!O16-'Balance Sheet'!N16) -> 93766.461 | ... N8: =-('Balance Sheet'!R10-'Balance Sheet'!Q10)-('Balance Sheet'!R11-'Balance Sheet'!Q11)-('Balance Sheet'!R12-'Balance Sheet'!Q12)-('Balance Sheet'!R13-'Balance Sheet'!Q13)+('Balance Sheet'!R16-'Balance Sheet'!Q16) -> -68914.207 | P8: =-('Balance Sheet'!T10-'Balance Sheet'!R10)-('Balance Sheet'!T11-'Balance Sheet'!R11)-('Balance Sheet'!T12-'Balance Sheet'!R12)-('Balance Sheet'!T13-'Balance Sheet'!R13)+('Balance Sheet'!T16-'Balance Sheet'!R16) -> -43344.795 | Q8: =-('Balance Sheet'!U10-'Balance Sheet'!T10)-('Balance Sheet'!U11-'Balance Sheet'!T11)-('Balance Sheet'!U12-'Balance Sheet'!T12)-('Balance Sheet'!U13-'Balance Sheet'!T13)+('Balance Sheet'!U16-'Balance Sheet'!T16) -> -29761.4 | R8: =-('Balance Sheet'!V10-'Balance Sheet'!U10)-('Balance Sheet'!V11-'Balance Sheet'!U11)-('Balance Sheet'!V12-'Balance Sheet'!U12)-('Balance Sheet'!V13-'Balance Sheet'!U13)+('Balance Sheet'!V16-'Balance Sheet'!U16) -> -286376.68
A9: Interest paid
A10: Cash Generated from (Used in) Operation Activity | C10: =SUM(C3:C9) -> -198229.46 | D10: =SUM(D3:D9) -> -71980.803 | E10: =SUM(E3:E9) -> -582150.85 | F10: =SUM(F3:F9) -> -476308.94 | G10: =SUM(G3:G9) -> -390761.31 | H10: =SUM(H3:H9) -> -238441.22 | I10: =SUM(I3:I9) -> -395549.29 | J10: =SUM(J3:J9) -> -222894.71 | ... N10: =SUM(N3:N9) -> -157708.63 | P10: =SUM(P3:P9) -> -417892.46 | Q10: =SUM(Q3:Q9) -> -387342.72 | R10: =SUM(R3:R9) -> -240184.17
A12: Capex - Excl. ROU/POS Lease | C12: =-('Balance Sheet'!G5-'Balance Sheet'!E5)-'P&L'!E130 -> -15523.438 | D12: =-('Balance Sheet'!H5-'Balance Sheet'!G5)-'P&L'!F130 -> -81658.377 | E12: =-('Balance Sheet'!I5-'Balance Sheet'!H5)-'P&L'!G130 -> -10206.075 | F12: =-('Balance Sheet'!J5-'Balance Sheet'!I5)-'P&L'!H130 -> 208.62396 | G12: =-('Balance Sheet'!K5-'Balance Sheet'!J5)-'P&L'!I130 -> -125101.84 | H12: =-('Balance Sheet'!L5-'Balance Sheet'!K5)-'P&L'!J130 -> -25304.832 | I12: =-('Balance Sheet'!M5-'Balance Sheet'!L5)-'P&L'!K130 -> -1288942 | J12: =-('Balance Sheet'!N5-'Balance Sheet'!M5)-'P&L'!L130 -> -15509.795 | K12: =-('Balance Sheet'!O5-'Balance Sheet'!N5)-'P&L'!M130 -> -140037.47 | ... N12: =-('Balance Sheet'!R5-'Balance Sheet'!Q5)-'P&L'!P130 -> -129570.88 | P12: =-('Balance Sheet'!T5-'Balance Sheet'!R5)-'P&L'!S130 -> -57944.291 | Q12: =-('Balance Sheet'!U5-'Balance Sheet'!T5)-'P&L'!T130 -> 11950.266 | R12: =-('Balance Sheet'!V5-'Balance Sheet'!U5)-'P&L'!U130 -> 161773.84
A13: CAPEX - ROU
A14: CAPEX - Leased POSs
A15: Cash Generated from (Used in) Investing Activity | C15: =SUM(C12:C14) -> -15523.438 | D15: =SUM(D12:D14) -> -81658.377 | E15: =SUM(E12:E14) -> -10206.075 | F15: =SUM(F12:F14) -> 208.62396 | G15: =SUM(G12:G14) -> -125101.84 | H15: =SUM(H12:H14) -> -25304.832 | I15: =SUM(I12:I14) -> -1288942 | J15: =SUM(J12:J14) -> -15509.795 | ... N15: =SUM(N12:N14) -> -129570.88 | P15: =SUM(P12:P14) -> -57944.291 | Q15: =SUM(Q12:Q14) -> 11950.266 | R15: =SUM(R12:R14) -> 161773.84
A17: Lease Liability | C17: ='Balance Sheet'!G22-'Balance Sheet'!E22 -> -5518.5403 | D17: ='Balance Sheet'!H22-'Balance Sheet'!G22 -> 219.69357 | E17: ='Balance Sheet'!I22-'Balance Sheet'!H22 -> -5826.6623 | F17: ='Balance Sheet'!J22-'Balance Sheet'!I22 -> 339.91336 | G17: ='Balance Sheet'!K22-'Balance Sheet'!J22 -> 1280.0506 | H17: ='Balance Sheet'!L22-'Balance Sheet'!K22 -> 619.25873 | I17: ='Balance Sheet'!M22-'Balance Sheet'!L22 -> 1091391.7 | J17: ='Balance Sheet'!N22-'Balance Sheet'!M22 -> -37183.796 | K17: ='Balance Sheet'!O22-'Balance Sheet'!N22 -> 16238.897 | ... N17: ='Balance Sheet'!R22-'Balance Sheet'!Q22 -> 18018.277 | P17: ='Balance Sheet'!T22-'Balance Sheet'!R22 -> -50780.128 | Q17: ='Balance Sheet'!U22-'Balance Sheet'!T22 -> 3066.0415 | R17: ='Balance Sheet'!V22-'Balance Sheet'!U22 -> -103300.24
A18: Loans
A19: Long-Term Loans
