Workbook
Name __xlnm.Print_Area: 'Aged debtors'!#REF!
Name __xlnm.Print_Area: #REF!
Name __xlnm.Print_Area: 'Customer data'!#REF!
Name __xlnm.Print_Area: #REF!
Name __xlnm.Print_Area: 'Largest debtors'!#REF!
Name __xlnm.Print_Area: #REF!
Name __xlnm.Print_Area: Stock!#REF!
Name __xlnm.Print_Area: #REF!
Name __xlnm.Print_Area_4: 'Aged debtors'!#REF!
Name __xlnm.Print_Area_4: #REF!
Name __xlnm.Print_Area_4: 'Customer data'!#REF!
Name __xlnm.Print_Area_4: 'Largest debtors'!#REF!
Name __xlnm.Print_Area_4: #REF!
Name __xlnm.Print_Area_4: Stock!#REF!
Name __xlnm.Print_Area_4: #REF!
Name a: 'Aged debtors'!#REF!
Name a: 'Customer data'!#REF!
Name a: 'Largest debtors'!#REF!
Name a: #REF!
Name a: Stock!#REF!
Name a: #REF!
Name Acc_Rev_Chart: OFFSET('Aged debtors'!#REF!,0,0,1,COUNTIF('Aged debtors'!#REF!,">0"))
Name Acc_Rev_Chart: OFFSET('Customer data'!#REF!,0,0,1,COUNTIF('Customer data'!#REF!,">0"))
Name Acc_Rev_Chart: OFFSET('Largest debtors'!#REF!,0,0,1,COUNTIF('Largest debtors'!#REF!,">0"))
Name Acc_Rev_Chart: OFFSET(#REF!,0,0,1,COUNTIF(#REF!,">0"))
Name Acc_Rev_Chart: OFFSET(Stock!#REF!,0,0,1,COUNTIF(Stock!#REF!,">0"))
Name Acc_Rev_Chart: OFFSET(#REF!,0,0,1,COUNTIF(#REF!,">0"))
Name Acc_Rev_Plan_Chart: OFFSET('Aged debtors'!#REF!,0,0,1,COUNTIF('Aged debtors'!#REF!,">0"))
Name Acc_Rev_Plan_Chart: OFFSET('Customer data'!#REF!,0,0,1,COUNTIF('Customer data'!#REF!,">0"))
Name Acc_Rev_Plan_Chart: OFFSET('Largest debtors'!#REF!,0,0,1,COUNTIF('Largest debtors'!#REF!,">0"))
Name Acc_Rev_Plan_Chart: OFFSET(#REF!,0,0,1,COUNTIF(#REF!,">0"))
Name Acc_Rev_Plan_Chart: OFFSET(Stock!#REF!,0,0,1,COUNTIF(Stock!#REF!,">0"))
Name Acc_Rev_Plan_Chart: OFFSET(#REF!,0,0,1,COUNTIF(#REF!,">0"))
Name Actual_Staff_YTD: 'Aged debtors'!#REF!
Name Actual_Staff_YTD: 'Customer data'!#REF!
Name Actual_Staff_YTD: 'Largest debtors'!#REF!
Name Actual_Staff_YTD: #REF!
Name Actual_Staff_YTD: Stock!#REF!
Name Actual_Staff_YTD: #REF!
Name Adj_EBITA_P2: 'Aged debtors'!#REF!
Name Adj_EBITA_P2: #REF!
Name Adj_EBITA_P2: 'Customer data'!#REF!
Name Adj_EBITA_P2: 'Largest debtors'!#REF!
Name Adj_EBITA_P2: #REF!
Name Adj_EBITA_P2: Stock!#REF!
Name Adj_EBITA_P2: #REF!
Name annual_mem: 'Aged debtors'!#REF!
Name annual_mem: 'Customer data'!#REF!
Name annual_mem: 'Largest debtors'!#REF!
Name annual_mem: #REF!
Name annual_mem: Stock!#REF!
Name annual_mem: #REF!
Name bob: 'Aged debtors'!#REF!
Name bob: #REF!
Name bob: 'Customer data'!#REF!
Name bob: 'Largest debtors'!#REF!
Name bob: #REF!
Name bob: Stock!#REF!
Name bob: #REF!
Name Bonus_Amount: 'Aged debtors'!#REF!

Sheet Cover
A1: Auto+Hide+Values
B17: Management Accounts
B19: 46054
E21: Company Confidential
AC68: =AC47+AC46-V46-V47 -> 0

Sheet KPIs
A1: Auto+Hide+Values
B2: Key Performance Indicators | C2: 43101 | D2: 43132 | E2: 43160 | F2: 43191 | G2: 43221 | H2: 43252 | I2: 43282 | J2: 43313 | K2: 43344 | L2: 43374 | M2: 43405 | N2: 43435 | O2: 43466 | P2: 43497 | Q2: 43525 | R2: 43556 | S2: 43586 | T2: 43617 | U2: 43647 | V2: 43678 | W2: 43709 | X2: 43739 | Y2: 43770 | Z2: 43800 | AA2: 43831 | AB2: 43862 | AC2: 43891 | AD2: 43922 | AE2: 43952 | AF2: 43983 | AG2: 44013 | AH2: 44044 | AI2: 44075 | AJ2: 44105 | AK2: 44136 | AL2: 44166 | AM2: 44197 | AN2: 44228 | AO2: 44256 | AP2: 44287 | AQ2: 44317 | AR2: 44348 | AS2: 44378 | AT2: 44409 | AU2: 44440 | AV2: 44470 | AW2: 44501 | AX2: 44531 | AY2: 44562 | AZ2: 44593 | BA2: 44621 | BB2: 44652 | BC2: 44682 | BD2: 44713 | BE2: 44743 | BF2: 44774 | BG2: 44805 | BH2: 44835 | BI2: 44866 | BJ2: 44896 | BK2: 44927 | BL2: 44958 | BM2: 44986 | BN2: 45017 | BO2: 45047 | BP2: 45078 | BQ2: 45108 | BR2: 45139 | BS2: 45170 | BT2: 45200 | BU2: 45231 | BV2: 45261 | BW2: 45292 | BX2: 45323 | BY2: 45352 | BZ2: 45383 | CA2: 45413 | CB2: 45444 | CC2: 45474 | CD2: 45505 | CE2: 45536 | CF2: 45566 | CG2: 45597 | CH2: 45627 | CI2: 45658 | CJ2: 45689 | CK2: 45717 | CL2: 45748 | CM2: 45778 | CN2: 45809 | CO2: 45839 | CP2: 45870 | CQ2: 45901 | CR2: 45931 | CS2: 45962 | CT2: 45992 | CU2: 46023 | CV2: 46054 | CX2: 46054 | CY2: 45689 | CZ2: YTD 2026 | DA2: YTD 2026 | DB2: YTD 2025
C3: Actual | D3: Actual | E3: Actual | F3: Actual | G3: Actual | H3: Actual | I3: Actual | J3: Actual | K3: Actual | L3: Actual | M3: Actual | N3: Actual | O3: Actual | P3: Actual | Q3: Actual | R3: Actual | S3: Actual | T3: Actual | U3: Actual | V3: Actual | W3: Actual | X3: Actual | Y3: Actual | Z3: Actual | AA3: Actual | AB3: Actual | AC3: Actual | AD3: Actual | AE3: Actual | AF3: Actual | AG3: Actual | AH3: Actual | AI3: Actual | AJ3: Actual | AK3: Actual | AL3: Actual | AM3: Actual | AN3: Actual | AO3: Actual | AP3: Actual | AQ3: Actual | AR3: Actual | AS3: Actual | AT3: Actual | AU3: Actual | AV3: Actual | AW3: Actual | AX3: Actual | AY3: Actual | AZ3: Actual | BA3: Actual | BB3: Actual | BC3: Actual | BD3: Actual | BE3: Actual | BF3: Actual | BG3: Actual | BH3: Actual | BI3: Actual | BJ3: Actual | BK3: Actual | BL3: Actual | BM3: Actual | BN3: Actual | BO3: Actual | BP3: Actual | BQ3: Actual | BR3: Actual | BS3: Actual | BT3: Actual | BU3: Actual | BV3: Actual | BW3: Actual | BX3: Actual | BY3: Actual | BZ3: Actual | CA3: Actual | CB3: Actual | CC3: Actual | CD3: Actual | CE3: Actual | CF3: Actual | CG3: Actual | CH3: Actual | CI3: Actual | CJ3: Actual | CK3: Actual | CL3: Actual | CM3: Actual | CN3: Actual | CO3: Actual | CP3: Actual | CQ3: Actual | CR3: Actual | CS3: Actual | CT3: Actual | CU3: Actual | CV3: Actual | CX3: Plan | CY3: Actual | CZ3: Actual | DA3: Plan | DB3: Actual
B5: Managed services | C5: ='Financial statements'!BR7 -> 651796 | D5: ='Financial statements'!BS7 -> 641723 | E5: ='Financial statements'!BT7 -> 631570 | F5: ='Financial statements'!BU7 -> 642402 | G5: ='Financial statements'!BV7 -> 652594 | H5: ='Financial statements'!BW7 -> 678176 | I5: ='Financial statements'!BX7 -> 749078 | J5: ='Financial statements'!BY7 -> 761402 | ... CV5: ='Financial statements'!FK7 -> 2031706.2 | CX5: ='Financial plan'!EZ8 -> 2134808.7 | CY5: =CJ5 -> 1913349.3 | CZ5: ='Financial statements'!$P7 -> 4098084.7 | DA5: =SUM('Financial plan'!$EY8:EZ8) -> 4269617.4 | DB5: =SUM($CI5:CJ5) -> 3794897.1
B6: Hardware | C6: ='Financial statements'!BR13 -> 9430 | D6: ='Financial statements'!BS13 -> 48105 | E6: ='Financial statements'!BT13 -> 71213 | F6: ='Financial statements'!BU13 -> 157072 | G6: ='Financial statements'!BV13 -> 48958 | H6: ='Financial statements'!BW13 -> 34054 | I6: ='Financial statements'!BX13 -> 140299 | J6: ='Financial statements'!BY13 -> 20342 | ... CV6: ='Financial statements'!FK13 -> 5967.9228 | CX6: ='Financial plan'!EZ18 -> 94532.828 | CY6: =CJ6 -> 171809.88 | CZ6: ='Financial statements'!$P13 -> 35492.031 | DA6: =SUM('Financial plan'!$EY18:EZ18) -> 189065.66 | DB6: =SUM($CI6:CJ6) -> 177509.73
B7: Consultancy | C7: ='Financial statements'!BR14 -> 17364 | D7: ='Financial statements'!BS14 -> 0 | E7: ='Financial statements'!BT14 -> 8526 | F7: ='Financial statements'!BU14 -> 0 | G7: ='Financial statements'!BV14 -> 3100 | H7: ='Financial statements'!BW14 -> 0 | I7: ='Financial statements'!BX14 -> 43231 | J7: ='Financial statements'!BY14 -> 8500 | ... CV7: ='Financial statements'!FK14 -> 10068.302 | CX7: ='Financial plan'!EZ19 -> 45000 | CY7: =CJ7 -> 92252.94 | CZ7: ='Financial statements'!$P14 -> 17700.495 | DA7: =SUM('Financial plan'!$EY19:EZ19) -> 90000 | DB7: =SUM($CI7:CJ7) -> 157821.08
B8: Total revenue | C8: ='Financial statements'!BR25 -> 678590 | D8: ='Financial statements'!BS25 -> 689828 | E8: ='Financial statements'!BT25 -> 711309 | F8: ='Financial statements'!BU25 -> 799474 | G8: ='Financial statements'!BV25 -> 704652 | H8: ='Financial statements'!BW25 -> 712230 | I8: ='Financial statements'!BX25 -> 932608 | J8: ='Financial statements'!BY25 -> 790244 | ... CV8: ='Financial statements'!FK25 -> 2047742.4 | CX8: =SUM(CX5:CX7) -> 2274341.5 | CY8: =CJ8 -> 2177412.1 | CZ8: =SUM(CZ5:CZ7) -> 4151277.2 | DA8: =SUM('Financial plan'!$EY21:EZ21) -> 4548683.1 | DB8: =SUM($CI8:CJ8) -> 4130228
DB9: =SUM($CI9:CJ9) -> 0
B10: Gross profit | C10: ='Financial statements'!BR44 -> 373435 | D10: ='Financial statements'!BS44 -> 419655 | E10: ='Financial statements'!BT44 -> 398153 | F10: =('Financial statements'!BU44) -> 401277 | G10: =('Financial statements'!BV44) -> 356980 | H10: =('Financial statements'!BW44) -> 381991 | I10: =('Financial statements'!BX44) -> 490834 | J10: =('Financial statements'!BY44) -> 419898 | K10: =('Financial statements'!BZ44) -> 432199 | L10: =('Financial statements'!CA44) -> 473628 | M10: =('Financial statements'!CB44) -> 452372 | ... CV10: =('Financial statements'!FK44) -> 1053666.9 | CX10: ='Financial plan'!EZ39 -> 1102576 | CY10: =CJ10 -> 1023272.3 | CZ10: ='Financial statements'!$P44 -> 1000133.9 | DA10: =SUM('Financial plan'!$EY39:EZ39) -> 2205151.9 | DB10: =SUM($CI10:CJ10) -> 1997789.1
DB12: =SUM($AY12:CG12) -> 0
B13: Overheads | C13: =-'Financial statements'!BR59 -> 435543 | D13: =-'Financial statements'!BS59 -> 437365 | E13: =-'Financial statements'!BT59 -> 469899 | F13: =-'Financial statements'!BU59 -> 480330 | G13: =-'Financial statements'!BV59 -> 469990 | H13: =-'Financial statements'!BW59 -> 482644 | I13: =-'Financial statements'!BX59 -> 522475 | J13: =-'Financial statements'!BY59 -> 501279 | ... CV13: =-'Financial statements'!FK59 -> 880582.43 | CX13: =-'Financial plan'!EZ54 -> 936737.79 | CY13: =CJ13 -> 985290.43 | CZ13: =-'Financial statements'!$P59 -> 1773250.8 | DA13: =-SUM('Financial plan'!$EY54:EZ54) -> 1873475.6 | DB13: =SUM($CI13:CJ13) -> 1953022.7
B14: EBITDA before bonus | C14: =C10-C13 -> -62108 | D14: =D10-D13 -> -17710 | E14: =E10-E13 -> -71746 | F14: =F10-F13 -> -79053 | G14: =G10-G13 -> -113010 | H14: =H10-H13 -> -100653 | I14: =I10-I13 -> -31641 | J14: =J10-J13 -> -81381 | ... CV14: =CV10-CV13 -> 173084.52 | CX14: =CX10-CX13 -> 165838.18 | CY14: =CJ14 -> 37981.869 | CZ14: =CZ10-CZ13 -> -773116.93 | DA14: =SUM('Financial plan'!$EY55:EZ55) -> 331676.36 | DB14: =SUM($CI14:CJ14) -> 44766.431
B15: Bonus | BW15: -54619.972 | BX15: -54212.043 | BY15: -52009.545 | BZ15: -44091.326 | CA15: -52452.662 | CB15: -52654.67 | CC15: -1284.6888 | CD15: 8743.0523 | CE15: 21409.262 | CF15: 28411.953 | CG15: 78473.886 | CH15: 174286.75 | CI15: -61094.728 | CJ15: -60710.738 | CK15: -60921.487 | CL15: -58165.515 | CM15: -25110.533 | CN15: -1288.5775 | CO15: ='Financial statements'!FD61 -> -69.984466 | CP15: ='Financial statements'!FE61 -> -384 | CQ15: ='Financial statements'!FF61 -> -8825.2867 | CR15: ='Financial statements'!FG61 -> 0 | CS15: ='Financial statements'!FH61 -> -52268 | CT15: ='Financial statements'!FI61 -> -85639.578 | CU15: ='Financial statements'!FJ61 -> -57412 | CV15: ='Financial statements'!FK61 -> -57893 | CX15: ='Financial plan'!EZ56 -> -37964.188 | CY15: =CJ15 -> -60710.738 | CZ15: ='Financial statements'!$P61 -> -115305 | DA15: =SUM('Financial plan'!$EY56:EZ56) -> -75928.376 | DB15: =SUM($CI15:CJ15) -> -121805.47
B16: EBITDA after bonus | BW16: =SUM(BW14:BW15) -> -58768.553 | BX16: =SUM(BX14:BX15) -> -66765.881 | BY16: =SUM(BY14:BY15) -> 56193.687 | BZ16: =SUM(BZ14:BZ15) -> -86723.825 | CA16: =SUM(CA14:CA15) -> 6231.966 | CB16: =SUM(CB14:CB15) -> -86099.512 | CC16: =SUM(CC14:CC15) -> -42047.603 | CD16: =SUM(CD14:CD15) -> -26998.69 | ... CV16: =SUM(CV14:CV15) -> 115191.52 | CX16: =SUM(CX14:CX15) -> 127873.99 | CY16: =CJ16 -> -22728.868 | CZ16: =SUM(CZ14:CZ15) -> -888421.93 | DA16: =SUM(DA14:DA15) -> 255747.98 | DB16: =SUM($CI16:CJ16) -> -77039.035
B18: Operating cash inflow/(outflow) | C18: =('Financial statements'!BR101+'Financial statements'!BR103) -> -192575 | D18: =('Financial statements'!BS101+'Financial statements'!BS103) -> -373888 | E18: =('Financial statements'!BT101+'Financial statements'!BT103) -> -219141 | F18: =('Financial statements'!BU101+'Financial statements'!BU103) -> 137024 | G18: =('Financial statements'!BV101+'Financial statements'!BV103) -> -65158 | H18: =('Financial statements'!BW101+'Financial statements'!BW103) -> -275365 | I18: =('Financial statements'!BX101+'Financial statements'!BX103) -> -370534 | J18: =('Financial statements'!BY101+'Financial statements'!BY103) -> 15814 | ... CV18: =('Financial statements'!FK101+'Financial statements'!FK103) -> -234918.61 | CY18: =CJ18 -> 289614.82 | CZ18: =SUM($CU18:CV18) -> -609285.68 | DB18: =SUM($CI18:CJ18) -> -171479.14
B19: Cash | C19: ='Financial statements'!BR115 -> 1163323 | D19: ='Financial statements'!BS115 -> 787372 | E19: ='Financial statements'!BT115 -> 516015 | F19: ='Financial statements'!BU115 -> 609038 | G19: ='Financial statements'!BV115 -> 482329 | H19: ='Financial statements'!BW115 -> 730017 | I19: ='Financial statements'!BX115 -> 274252 | J19: ='Financial statements'!BY115 -> 685169 | ... CV19: ='Financial statements'!FK115 -> 4773852.1 | CY19: =CJ19 -> 3099115.3 | CZ19: =CV19 -> 4773852.1 | DB19: =CJ19 -> 3099115.3
B21: No of customers | C21: ='Customer data'!L268 -> 967 | D21: ='Customer data'!M268 -> 1008 | E21: ='Customer data'!N268 -> 1083 | F21: ='Customer data'!O268 -> 1120 | G21: ='Customer data'!P268 -> 1175 | H21: ='Customer data'!Q268 -> 1221 | I21: ='Customer data'!R268 -> 1216 | J21: ='Customer data'!S268 -> 1252 | ... CV21: ='Customer data'!DE268 -> 1076 | CY21: =CJ21 -> 1033 | CZ21: =SUM($CU21:CV21) -> 2132 | DB21: =CJ21 -> 1033
B22: No of devices | C22: ='Customer data'!L260 -> 1003681 | D22: ='Customer data'!M260 -> 1011809 | E22: ='Customer data'!N260 -> 1054447 | F22: ='Customer data'!O260 -> 946983 | G22: ='Customer data'!P260 -> 968106 | H22: ='Customer data'!Q260 -> 988289 | I22: ='Customer data'!R260 -> 999982 | J22: ='Customer data'!S260 -> 1019404 | ... CV22: ='Customer data'!DE260 -> 5032348 | CY22: =CJ22 -> 2642271 | CZ22: =SUM($CU22:CV22) -> 10035085 | DB22: =CJ22 -> 2642271
B23: % of devices paygo | C23: ='Customer data'!L265 -> 0.44055233 | D23: ='Customer data'!M265 -> 0.43709534 | E23: ='Customer data'!N265 -> 0.43224363 | F23: ='Customer data'!O265 -> 0.36389777 | G23: ='Customer data'!P265 -> 0.35595792 | H23: ='Customer data'!Q265 -> 0.34868849 | I23: ='Customer data'!R265 -> 0.34482721 | J23: ='Customer data'!S265 -> 0.33825745 | ... CV23: ='Customer data'!DE265 -> 0.014371224 | CY23: =CJ23 -> 0.045929051 | CZ23: =SUM($CU23:CV23) -> 0.028915063 | DB23: =CJ23 -> 0.045929051
B24: % of devices emerging markets | C24: ='Customer data'!L266 -> 0 | D24: ='Customer data'!M266 -> 0 | E24: ='Customer data'!N266 -> 0 | F24: ='Customer data'!O266 -> 0.37603949 | G24: ='Customer data'!P266 -> 0.37054207 | H24: ='Customer data'!Q266 -> 0.37522425 | I24: ='Customer data'!R266 -> 0.37162869 | J24: ='Customer data'!S266 -> 0.3764121 | ... CV24: ='Customer data'!DE266 -> 0.10323908 | CY24: =CJ24 -> 0.20056686 | CZ24: =SUM($CU24:CV24) -> 0.20797535 | DB24: =CJ24 -> 0.20056686
B26: Total ARPU (£s) *
B27: Deploying | C27: ='Revenue data'!D67 -> 0 | D27: ='Revenue data'!E67 -> 0 | E27: ='Revenue data'!F67 -> 0 | F27: ='Revenue data'!G67 -> 0.4739376 | G27: ='Revenue data'!H67 -> 0.44698155 | H27: ='Revenue data'!I67 -> 0.4811228 | I27: ='Revenue data'!J67 -> 0.53460122 | J27: ='Revenue data'!K67 -> 0.42195686 | ... CV27: ='Revenue data'!CW67 -> 0.68113994 | CY27: =CJ27 -> 0.62197061
B28: Pre-deployment | C28: ='Revenue data'!D68 -> 0 | D28: ='Revenue data'!E68 -> 0 | E28: ='Revenue data'!F68 -> 0 | F28: ='Revenue data'!G68 -> 1.326 | G28: ='Revenue data'!H68 -> 1.8687671 | H28: ='Revenue data'!I68 -> 2.1264 | I28: ='Revenue data'!J68 -> 3.2501351 | J28: ='Revenue data'!K68 -> 2.6760811 | ... CV28: ='Revenue data'!CW68 -> 0.15024505 | CY28: =CJ28 -> 0.16641292
B29: Other accounts | C29: ='Revenue data'!D69 -> 0 | D29: ='Revenue data'!E69 -> 0 | E29: ='Revenue data'!F69 -> 0 | F29: ='Revenue data'!G69 -> 1.4341518 | G29: ='Revenue data'!H69 -> 1.5458215 | H29: ='Revenue data'!I69 -> 1.3286054 | I29: ='Revenue data'!J69 -> 1.422076 | J29: ='Revenue data'!K69 -> 1.7304567 | ... CV29: ='Revenue data'!CW69 -> 1.2279208 | CY29: =CJ29 -> 1.1809964
B30: Brazil | C30: ='Revenue data'!D70 -> 0 | D30: ='Revenue data'!E70 -> 0 | E30: ='Revenue data'!F70 -> 0 | F30: ='Revenue data'!G70 -> 1.7337056 | G30: ='Revenue data'!H70 -> 1.6915672 | H30: ='Revenue data'!I70 -> 0.98808661 | I30: ='Revenue data'!J70 -> 1.5106707 | J30: ='Revenue data'!K70 -> 1.1871073 | ... CV30: ='Revenue data'!CW70 -> 0.85075652 | CY30: =CJ30 -> 0.86771695
B31: All regions | C31: ='Revenue data'!D73 | D31: ='Revenue data'!E73 | E31: ='Revenue data'!F73 | F31: ='Revenue data'!G73 -> 0.68957537 | G31: ='Revenue data'!H73 -> 0.69043564 | H31: ='Revenue data'!I73 -> 0.6796909 | I31: ='Revenue data'!J73 -> 0.74783621 | J31: ='Revenue data'!K73 -> 0.70462127 | ... CV31: ='Revenue data'!CW73 -> 0.41970865 | CY31: =CJ31 -> 0.72278418
B34: * for consistency, prior period comparatives have been updated for reallocation of Tier 4 accounts and regions in August 2019
B36: Service revenue excl SIM sales | C36: 639147 | D36: 622382 | E36: 605883 | F36: 637640 | G36: 642498 | H36: 669885 | I36: 746354 | J36: 753906 | K36: 735804.27 | L36: 755020 | M36: 786812.81 | N36: 821137 | O36: =('Financial statements'!CD7-'Financial statements'!CD11) -> 802039 | P36: =('Financial statements'!CE7-'Financial statements'!CE11) -> 799566 | Q36: =('Financial statements'!CF7-'Financial statements'!CF11) -> 840978 | R36: =('Financial statements'!CG7-'Financial statements'!CG11) -> 829964.46 | S36: =('Financial statements'!CH7-'Financial statements'!CH11) -> 840841.92 | T36: =('Financial statements'!CI7-'Financial statements'!CI11) -> 854073 | U36: =('Financial statements'!CJ7-'Financial statements'!CJ11) -> 897330.29 | V36: =('Financial statements'!CK7-'Financial statements'!CK11) -> 932348.39 | ... CV36: =('Financial statements'!FK7-'Financial statements'!FK11) -> 1997378.2
B37: Service COS from above excl SIMs | C37: -253784.82 | D37: -223280.03 | E37: -221613.58 | F37: -274831.37 | G37: -275266.41 | H37: -276183.85 | I37: -296698.88 | J37: -334737.68 | K37: -313929.84 | L37: -301441.01 | M37: -336950.49 | N37: -261748.01 | O37: -358318.49 | P37: -374434.91 | Q37: -433952 | R37: -446927.98 | S37: -426542 | T37: -475745.53 | U37: -473212.71 | V37: -489166.48 | W37: -512771.55 | X37: -492932.86 | Y37: -486789.05 | Z37: -520508.88 | AA37: -540281.29 | AB37: -544638.95 | AC37: -521877.28 | AD37: -500224.97 | AE37: -525698.37 | AF37: -490930.38 | AG37: -527790.56 | AH37: -496612.21 | AI37: -478920.58 | AJ37: -487671.28 | AK37: -489808.53 | AL37: -490328.1 | AM37: -476672.98 | AN37: -480585.02 | AO37: -489223.81 | AP37: -492939.29 | AQ37: -502357.39 | AR37: -508518.51 | AS37: -563486.09 | AT37: -610546.9 | AU37: -588358.14 | AV37: -623265.16 | AW37: -638209.67 | AX37: -626478.01 | AY37: -641602.08 | AZ37: -656573.28 | BA37: -687946.19 | BB37: -736431.94 | BC37: -770425.05 | BD37: -781268.71 | BE37: -853578.88 | BF37: -841171 | BG37: -888188.48 | BH37: -844912.75 | BI37: -820049.93 | BJ37: -777082.46 | BK37: -773105.38 | BL37: -769185.26 | BM37: -803811.66 | BN37: -807633.22 | BO37: -818541.91 | BP37: ='Financial statements'!EE28+81815.52 -> -850574.01 | BQ37: ='Financial statements'!EF28-39296.05+155656.07 -> -835206.55 | BR37: -833702.69 | BS37: -834493.98 | BT37: -843928.03 | BU37: -862625.28 | BV37: -839983.69 | BW37: -820294.42 | BX37: -825606.73 | BY37: -875623.64 | BZ37: -886195.76 | CA37: -876476.56 | CB37: -892632.66 | CC37: -890287.7 | CD37: -900034.36 | CE37: -904632.7 | CF37: -901978.8 | CG37: -923068.28 | CH37: -893177.63 | CI37: -905740.26 | CJ37: -911726.59 | CK37: -899445.97 | CL37: -909998.43 | CM37: -902434.5 | CN37: -904871.73 | CO37: -973813.84 | CP37: -989227.46 | CQ37: -1005662.9 | CR37: -985394.19 | CS37: -985185.83 | CT37: -962071.94 | CU37: -966952.22 | CV37: -961251.51
B38: Gross service profit excl SIMS | C38: =SUM(C36:C37) -> 385362.18 | D38: =SUM(D36:D37) -> 399101.97 | E38: =SUM(E36:E37) -> 384269.42 | F38: =SUM(F36:F37) -> 362808.63 | G38: =SUM(G36:G37) -> 367231.59 | H38: =SUM(H36:H37) -> 393701.15 | I38: =SUM(I36:I37) -> 449655.12 | J38: =SUM(J36:J37) -> 419168.32 | ... CV38: =SUM(CV36:CV37) -> 1036126.7
B39: Managed services GM% EXC SIMS | C39: =C38/C36 -> 0.60293201 | D39: =D38/D36 -> 0.64124921 | E39: =E38/E36 -> 0.6342304 | F39: =F38/F36 -> 0.56898662 | G39: =G38/G36 -> 0.57156846 | H39: =H38/H36 -> 0.58771453 | I39: =I38/I36 -> 0.60246896 | J39: =J38/J36 -> 0.55599547 | ... CV39: =CV38/CV36 -> 0.51874337
AX44: 2021 | BJ44: 2022 | BK44: 2023
AL45: =AL22 -> 1431382 | AX45: =AX22 -> 1890458 | BJ45: =BJ22 -> 2311815 | BK45: =BV22 -> 2452291 | BL45: =BK45*1.2 -> 2942749.2
AX46: =AX45-AL45 -> 459076 | BJ46: =BJ45-AX45 -> 421357 | BK46: =BK45-BJ45 -> 140476
AX47: =AX46/AL45 -> 0.32072221 | AY47: =AY46/AM45 -> #DIV/0! | AZ47: =AZ46/AN45 -> #DIV/0! | BA47: =BA46/AO45 -> #DIV/0! | BB47: =BB46/AP45 -> #DIV/0! | BC47: =BC46/AQ45 -> #DIV/0! | BD47: =BD46/AR45 -> #DIV/0! | BE47: =BE46/AS45 -> #DIV/0! | ... BJ47: =BJ46/AX45 -> 0.2228862 | BK47: =BK46/BJ45 -> 0.060764378
BK49: =(BK45/AL45)^(1/3)-1 -> 0.19657195

Sheet Financial statements
A1: Auto+Hide+Values
B2: GBP | F2: FY16 | G2: FY17 | H2: FY18 | I2: FY19 | J2: FY20 | K2: FY21 | L2: FY22 | M2: FY23 | N2: FY24 | O2: FY25 | P2: FY26 | R2: Q1-17 | S2: Q2-17 | T2: Q3-17 | U2: Q4-17 | V2: Q1-18 | W2: Q2-18 | X2: Q3-18 | Y2: Q4-18 | Z2: Q1-19 | AA2: Q2-19 | AB2: Q3-19 | AC2: Q4-19 | AD2: Q1-20 | AE2: Q2-20 | AF2: Q3-20 | AG2: Q4-20 | AH2: Q1-21 | AI2: Q2-21 | AJ2: Q3-21 | AK2: Q4-21 | AL2: Q1-22 | AM2: Q2-22 | AN2: Q3-22 | AO2: Q4-22 | AP2: Q1-23 | AQ2: Q2-23 | AR2: Q3-23 | AS2: Q4-23 | AT2: Q1-24 | AU2: Q2-24 | AV2: Q3-24 | AW2: Q4-24 | AX2: Q1-25 | AY2: Q2-25 | AZ2: Q3-25 | BA2: Q4-25 | BB2: Q1-26 | BC2: Q2-26 | BD2: Q3-26 | BE2: Q4-26 | BF2: 42736 | BG2: 42767 | BH2: 42795 | BI2: 42826 | BJ2: 42856 | BK2: 42887 | BL2: 42917 | BM2: 42948 | BN2: 42979 | BO2: 43009 | BP2: 43040 | BQ2: 43070 | BR2: 43101 | BS2: 43132 | BT2: 43160 | BU2: 43191 | BV2: 43221 | BW2: 43252 | BX2: 43282 | BY2: 43313 | BZ2: 43344 | CA2: 43374 | CB2: 43405 | CC2: 43435 | CD2: 43466 | CE2: 43497 | CF2: 43525 | CG2: 43556 | CH2: 43586 | CI2: 43617 | CJ2: 43647 | CK2: 43678 | CL2: 43709 | CM2: 43739 | CN2: 43770 | CO2: 43800 | CP2: 43831 | CQ2: 43862 | CR2: 43891 | CS2: 43922 | CT2: 43952 | CU2: 43983 | CV2: 44013 | CW2: 44044 | CX2: 44075 | CY2: 44105 | CZ2: 44136 | DA2: 44166 | DB2: 44197 | DC2: 44228 | DD2: 44256 | DE2: 44287 | DF2: 44317 | DG2: 44348 | DH2: 44378 | DI2: 44409 | DJ2: 44440 | DK2: 44470 | DL2: 44501 | DM2: 44531 | DN2: 44562 | DO2: 44593 | DP2: 44621 | DQ2: 44652 | DR2: 44682 | DS2: 44713 | DT2: 44743 | DU2: 44774 | DV2: 44805 | DW2: 44835 | DX2: 44866 | DY2: 44896 | DZ2: 44927 | EA2: 44958 | EB2: 44986 | EC2: 45017 | ED2: 45047 | EE2: 45078 | EF2: 45108 | EG2: 45139 | EH2: 45170 | EI2: 45200 | EJ2: 45231 | EK2: 45261 | EL2: 45292 | EM2: 45323 | EN2: 45352 | EO2: 45383 | EP2: 45413 | EQ2: 45444 | ER2: 45474 | ES2: 45505 | ET2: 45536 | EU2: 45566 | EV2: 45597 | EW2: 45627 | EX2: 45658 | EY2: 45689 | EZ2: 45717 | FA2: 45748 | FB2: 45778 | FC2: 45809 | FD2: 45839 | FE2: 45870 | FF2: 45901 | FG2: 45931 | FH2: 45962 | FI2: 45992 | FJ2: 46023 | FK2: 46054 | FN2: 46054 | FO2: Var to Jan-26 | FP2: Var to Jan-26 budget | FQ2: Var to Jan-26 budget | FR2: Var to Jan-26 budget | FS2: Var to Feb-26 budget | FT2: YTD-26 | FU2: YTD-26 | FV2: Var to YTD-26 budget
F3: actual | G3: plan | H3: actual | I3: actual | J3: actual | K3: actual | L3: actual | M3: actual | N3: actual | O3: actual | P3: actual | R3: actual | S3: actual | T3: actual | U3: actual | V3: actual | W3: actual | X3: actual | Y3: actual | Z3: actual | AA3: actual | AB3: actual | AC3: actual | AD3: actual | AE3: actual | AF3: actual | AG3: actual | AH3: actual | AI3: actual | AJ3: actual | AK3: actual | AL3: actual | AM3: actual | AN3: actual | AO3: actual | AP3: actual | AQ3: actual | AR3: actual | AS3: actual | AT3: actual | AU3: actual | AV3: actual | AW3: actual | AX3: actual | AY3: actual | AZ3: actual | BA3: actual | BB3: actual | BC3: actual | BD3: actual | BE3: actual | BR3: actual | BS3: actual | BT3: actual | BU3: actual | BV3: actual | BW3: actual | BX3: actual | BY3: actual | BZ3: actual | CA3: actual | CB3: actual | CC3: actual | CD3: actual | CE3: actual | CF3: actual | CG3: actual | CH3: actual | CI3: actual | CJ3: actual | CK3: actual | CL3: actual | CM3: actual | CN3: actual | CO3: actual | CP3: actual | CQ3: actual | CR3: actual | CS3: actual | CT3: actual | CU3: actual | CV3: actual | CW3: actual | CX3: actual | CY3: actual | CZ3: actual | DA3: actual | DB3: actual | DC3: actual | DD3: actual | DE3: actual | DF3: actual | DG3: actual | DH3: actual | DI3: actual | DJ3: actual | DK3: actual | DL3: actual | DM3: actual | DN3: actual | DO3: actual | DP3: actual | DQ3: actual | DR3: actual | DS3: actual | DT3: actual | DU3: actual | DV3: actual | DW3: actual | DX3: actual | DY3: actual | DZ3: actual | EA3: actual | EB3: actual | EC3: actual | ED3: actual | EE3: actual | EF3: actual | EG3: actual | EH3: actual | EI3: actual | EJ3: actual | EK3: actual | EL3: actual | EM3: actual | EN3: actual | EO3: actual | EP3: actual | EQ3: actual | ER3: actual | ES3: actual | ET3: actual | EU3: actual | EV3: actual | EW3: actual | EX3: actual | EY3: actual | EZ3: actual | FA3: actual | FB3: actual | FC3: actual | FD3: actual | FE3: actual | FF3: actual | FG3: actual | FH3: actual | FI3: actual | FJ3: actual | FK3: actual | FN3: budget | FT3: actual | FU3: budget
B4: Profit & loss account | AQ4: 3 | AR4: 6 | AS4: 9 | AT4: 2 | AU4: 3 | AV4: 6 | AW4: 9
D6: Revenue
E7: Managed services | F7: 5243000 | G7: =SUM(R7:U7) -> 6817494 | H7: =SUM(V7:Y7) -> 8562442 | I7: =SUM(Z7:AC7) -> 11137767 | J7: =SUM(AD7:AG7) -> 12663055 | K7: =SUM(AH7:AK7) -> 15236724 | L7: =SUM(AL7:AO7) -> 19841951 | M7: =SUM(AP7:AS7) -> 22122280 | N7: =SUM(AT7:AW7) -> 22910027 | O7: =SUM(AX7:BA7) -> 23609043 | P7: =SUM($FJ7:FK7) -> 4098084.7 | R7: =SUM(BF7:BH7) -> 1504042 | S7: =SUM(BI7:BK7) -> 1661076 | T7: =SUM(BL7:BN7) -> 1803269 | U7: =SUM(BO7:BQ7) -> 1849107 | V7: =SUM(BR7:BT7) -> 1925089 | W7: =SUM(BU7:BW7) -> 1973172 | X7: =SUM(BX7:BZ7) -> 2270128 | Y7: =SUM(CA7:CC7) -> 2394053 | Z7: =SUM(CD7:CF7) -> 2503013 | AA7: =SUM(CG7:CI7) -> 2652640 | AB7: =SUM(CJ7:CL7) -> 2862560 | AC7: =SUM(CM7:CO7) -> 3119554 | AD7: =SUM(CP7:CR7) -> 3227336 | AE7: =SUM(CS7:CU7) -> 3126544 | AF7: =SUM(CV7:CX7) -> 3129665 | AG7: =SUM(CY7:DA7) -> 3179509.9 | AH7: =SUM(DB7:DD7) -> 3285464.2 | AI7: =SUM(DE7:DG7) -> 3598475.4 | AJ7: =SUM(DH7:DJ7) -> 4039992.2 | AK7: =SUM(DK7:DM7) -> 4312791.9 | AL7: =SUM(DN7:DP7) -> 4324050 | AM7: =SUM(DQ7:DS7) -> 4836138.7 | AN7: =SUM(DT7:DV7) -> 5140234.2 | AO7: =SUM(DW7:DY7) -> 5541528 | AP7: =SUM(DZ7:EB7) -> 5429734.5 | AQ7: =OFFSET($DZ7,0,AQ$4)+OFFSET($EA7,0,AQ$4)+OFFSET($EB7,0,AQ$4) -> 5446302.2 | AR7: =OFFSET($DZ7,0,AR$4)+OFFSET($EA7,0,AR$4)+OFFSET($EB7,0,AR$4) -> 5584122.4 | AS7: =OFFSET($DZ7,0,AS$4)+OFFSET($EA7,0,AS$4)+OFFSET($EB7,0,AS$4) -> 5662121.2 | AT7: =SUM(EL7:EN7) -> 5807553.7 | AU7: =OFFSET($EL7,0,AU$4)+OFFSET($EM7,0,AU$4)+OFFSET($EN7,0,AU$4) -> 5777611.7 | AV7: =OFFSET($EL7,0,AV$4)+OFFSET($EM7,0,AV$4)+OFFSET($EN7,0,AV$4) -> 5659968.2 | AW7: =OFFSET($EL7,0,AW$4)+OFFSET($EM7,0,AW$4)+OFFSET($EN7,0,AW$4) -> 5664893.9 | AX7: =SUM(EX7:EZ7) -> 5620968.6 | AY7: =SUM(FA7:FC7) -> 5626791 | AZ7: =SUM(FD7:FF7) -> 6040665 | BA7: =SUM(FG7:FI7) -> 6320618.9 | BB7: =SUM(FJ7:FL7) -> 4098084.7 | BF7: 499065 | BG7: 471161 | BH7: 533816 | BI7: 544008 | BJ7: 573225 | BK7: 543843 | BL7: 569705 | BM7: 627045 | BN7: 606519 | BO7: 623258 | BP7: 611216 | BQ7: 614633 | BR7: 651796 | BS7: 641723 | BT7: 631570 | BU7: 642402 | BV7: 652594 | BW7: 678176 | BX7: =839078-90000 -> 749078 | BY7: 761402 | BZ7: 759648 | CA7: 774937 | CB7: =792087+5000 -> 797087 | CC7: 822029 | CD7: =831828-6500 -> 825328 | CE7: 826846 | CF7: 850839 | CG7: =881601-2000 -> 879601 | CH7: 883292 | CI7: 889747 | CJ7: 932124 | CK7: 948245 | CL7: =972191+10000 -> 982191 | CM7: =993575+10000 -> 1003575 | CN7: =1030522+20000 -> 1050522 | CO7: 1065457 | CP7: 1067087 | CQ7: 1078237 | CR7: 1082012 | CS7: 1063341 | CT7: 1032987 | CU7: 1030216 | CV7: 1044271 | CW7: 1034501.2 | CX7: 1050892.7 | CY7: 1055268.6 | CZ7: 1066025.1 | DA7: 1058216.2 | DB7: 1082826.5 | DC7: 1089809.2 | DD7: 1112828.5 | DE7: 1193927.1 | DF7: 1174221.9 | DG7: 1230326.4 | DH7: 1272166.2 | DI7: 1385697.3 | DJ7: 1382128.6 | DK7: 1438639.5 | DL7: 1453159.5 | DM7: 1420993 | DN7: 1430084.2 | DO7: 1435938.1 | DP7: 1458027.7 | DQ7: 1574785.9 | DR7: 1608150.5 | DS7: 1653202.3 | DT7: 1686256.9 | DU7: 1670379.2 | DV7: 1783598.2 | DW7: 1782606.8 | DX7: 1898032.2 | DY7: 1860889 | DZ7: 1779915.2 | EA7: 1806110 | EB7: 1843709.3 | EC7: 1827965.7 | ED7: 1776744.8 | EE7: 1841591.7 | EF7: 1851580.9 | EG7: 1841623.1 | EH7: 1890918.4 | EI7: 1845701.8 | EJ7: 1884822.5 | EK7: 1931596.9 | EL7: 1868668.5 | EM7: 1942526.1 | EN7: 1996359.1 | EO7: 1955878.3 | EP7: 1925178.5 | EQ7: 1896554.9 | ER7: 1892327.6 | ES7: 1897669.7 | ET7: 1869970.9 | EU7: 1903531.7 | EV7: 1909338.7 | EW7: 1852023.5 | EX7: 1881547.8 | EY7: 1913349.3 | EZ7: 1826071.4 | FA7: 1890987.3 | FB7: 1835211.3 | FC7: 1900592.4 | FD7: 1937480 | FE7: 1996687.5 | FF7: 2106497.5 | FG7: 2081008.8 | FH7: 2102511.8 | FI7: 2137098.3 | FJ7: 2066378.5 | FK7: 2031706.2 | FN7: ='Financial plan'!EZ8 -> 2134808.7 | FO7: =FK7-FJ7 -> -34672.39 | FP7: =FK7-FN7 -> -103102.55 | FQ7: =FL7-#REF! -> #REF! | FR7: =FM7-FO7 -> 34672.39 | FS7: =FK7-FN7 -> -103102.55 | FT7: =SUM($FJ7:FK7) -> 4098084.7 | FU7: =SUM('Financial plan'!$EY8:EZ8) -> 4269617.4 | FV7: =FT7-FU7 -> -171532.71
E8: Connectivity | H8: =SUM(V8:Y8) -> 0 | L8: =SUM(AL8:AO8) -> 16191409 | M8: =SUM(AP8:AS8) -> 18545178 | N8: =SUM(AT8:AW8) -> 18942230 | O8: =SUM(AX8:BA8) -> 19381277 | AJ8: =SUM(DH8:DJ8) -> 3145685.8 | AK8: =SUM(DK8:DM8) -> 3429560 | AL8: =SUM(DN8:DP8) -> 3594702.5 | AM8: =SUM(DQ8:DS8) -> 3936053 | AN8: =SUM(DT8:DV8) -> 4180409.2 | AO8: =SUM(DW8:DY8) -> 4480244.2 | AP8: =SUM(DZ8:EB8) -> 4616510.1 | AQ8: =OFFSET($DZ8,0,AQ$4)+OFFSET($EA8,0,AQ$4)+OFFSET($EB8,0,AQ$4) -> 4642098.7 | AR8: =OFFSET($DZ8,0,AR$4)+OFFSET($EA8,0,AR$4)+OFFSET($EB8,0,AR$4) -> 4575717.3 | AS8: =OFFSET($DZ8,0,AS$4)+OFFSET($EA8,0,AS$4)+OFFSET($EB8,0,AS$4) -> 4710851.5 | AT8: =SUM(EL8:EN8) -> 4825956 | AU8: =OFFSET($EL8,0,AU$4)+OFFSET($EM8,0,AU$4)+OFFSET($EN8,0,AU$4) -> 4830694.7 | AV8: =OFFSET($EL8,0,AV$4)+OFFSET($EM8,0,AV$4)+OFFSET($EN8,0,AV$4) -> 4663263.4 | AW8: =OFFSET($EL8,0,AW$4)+OFFSET($EM8,0,AW$4)+OFFSET($EN8,0,AW$4) -> 4622316 | AX8: =SUM(EX8:EZ8) -> 4681426.9 | AY8: =SUM(FA8:FC8) -> 4617999.9 | AZ8: =SUM(FD8:FF8) -> 4968774.3 | BA8: =SUM(FG8:FI8) -> 5113075.9 | BF8: 499065 | CD8: 649914.65 | CE8: 681816.84 | CF8: 686818.05 | CG8: 706085.33 | CH8: 721614.65 | CI8: 745628.79 | CJ8: 784828.18 | CK8: 811360.14 | CL8: 807040.97 | CM8: 819251.52 | CN8: 834555.22 | CO8: 826333.14 | CP8: 852657.06 | CQ8: 871151.98 | CR8: 887552.88 | CS8: 869608.72 | CT8: 858430.71 | CU8: 872676.06 | CV8: 877679.48 | CW8: 877817.22 | CX8: 894364 | CY8: 904984.66 | CZ8: 902572.94 | DA8: 907463.8 | DB8: 914883.48 | DC8: 923861.36 | DD8: 921084.36 | DE8: 921218.86 | DF8: 945230.31 | DG8: 972248.69 | DH8: 1019061.1 | DI8: 1078991.3 | DJ8: 1047633.3 | DK8: 1111496.4 | DL8: 1143557.7 | DM8: 1174505.9 | DN8: 1167208.2 | DO8: 1190776.2 | DP8: 1236718.2 | DQ8: 1274583.4 | DR8: 1313786.4 | DS8: 1347683.2 | DT8: 1367994.9 | DU8: 1364861.3 | DV8: 1447553 | DW8: 1499541.8 | DX8: 1491842.8 | DY8: 1488859.5 | DZ8: 1534812.5 | EA8: 1539169.7 | EB8: 1542527.9 | EC8: 1542706.9 | ED8: =1544033.79561978 -> 1544033.8 | EE8: 1555358 | EF8: 1499181.4 | EG8: 1524805.9 | EH8: 1551730.1 | EI8: 1559962.4 | EJ8: 1579492.6 | EK8: 1571396.4 | EL8: 1598122.5 | EM8: 1615036.4 | EN8: 1612797.1 | EO8: 1606008.7 | EP8: 1613232.2 | EQ8: 1611453.8 | ER8: 1589514.1 | ES8: 1561702.4 | ET8: 1512047 | EU8: 1516975.1 | EV8: 1564706.8 | EW8: 1540634.1 | EX8: 1554387.3 | EY8: 1575260.9 | EZ8: 1551778.6 | FA8: 1533379.3 | FB8: 1537217.6 | FC8: 1547402.9 | FD8: 1628511.8 | FE8: 1649960 | FF8: 1690302.6 | FG8: 1676517 | FH8: 1729604.5 | FI8: 1706954.4 | FJ8: 1689488.1 | FK8: 1672630.6 | FO8: =FK8-FJ8 -> -16857.479 | FS8: =FK8-FN8 -> 1672630.6 | FT8: =SUM($FJ8:FK8) -> 3362118.7
E9: AddOns | H9: =SUM(V9:Y9) -> 0 | L9: =SUM(AL9:AO9) -> 1284247 | M9: =SUM(AP9:AS9) -> 1338044.3 | N9: =SUM(AT9:AW9) -> 1412569.9 | O9: =SUM(AX9:BA9) -> 1568018.7 | AJ9: =SUM(DH9:DJ9) -> 283167.75 | AK9: =SUM(DK9:DM9) -> 289688.79 | AL9: =SUM(DN9:DP9) -> 308558.35 | AM9: =SUM(DQ9:DS9) -> 316546.78 | AN9: =SUM(DT9:DV9) -> 327240 | AO9: =SUM(DW9:DY9) -> 331901.87 | AP9: =SUM(DZ9:EB9) -> 325457.31 | AQ9: =OFFSET($DZ9,0,AQ$4)+OFFSET($EA9,0,AQ$4)+OFFSET($EB9,0,AQ$4) -> 325603.29 | AR9: =OFFSET($DZ9,0,AR$4)+OFFSET($EA9,0,AR$4)+OFFSET($EB9,0,AR$4) -> 339970.17 | AS9: =OFFSET($DZ9,0,AS$4)+OFFSET($EA9,0,AS$4)+OFFSET($EB9,0,AS$4) -> 347013.56 | AT9: =SUM(EL9:EN9) -> 335426.66 | AU9: =OFFSET($EL9,0,AU$4)+OFFSET($EM9,0,AU$4)+OFFSET($EN9,0,AU$4) -> 339342.55 | AV9: =OFFSET($EL9,0,AV$4)+OFFSET($EM9,0,AV$4)+OFFSET($EN9,0,AV$4) -> 368529.73 | AW9: =OFFSET($EL9,0,AW$4)+OFFSET($EM9,0,AW$4)+OFFSET($EN9,0,AW$4) -> 369270.93 | AX9: =SUM(EX9:EZ9) -> 373465.58 | AY9: =SUM(FA9:FC9) -> 376116.08 | AZ9: =SUM(FD9:FF9) -> 393616.64 | BA9: =SUM(FG9:FI9) -> 424820.45 | BF9: 499065 | CD9: 36859.29 | CE9: 44348.864 | CF9: 43639.913 | CG9: 44970.84 | CH9: 45780.697 | CI9: 50743.463 | CJ9: 48705.546 | CK9: 52394.197 | CL9: 57081.888 | CM9: 55048.636 | CN9: 56835.674 | CO9: 54750.02 | CP9: 62069.802 | CQ9: 57378.902 | CR9: 63279.561 | CS9: 62477.314 | CT9: 59353.216 | CU9: 57107.825 | CV9: 60740.504 | CW9: 59045.584 | CX9: 59229.911 | CY9: 55992.25 | CZ9: 63583.127 | DA9: 74498.473 | DB9: 74617.088 | DC9: 74820.536 | DD9: 74115.377 | DE9: 77672.938 | DF9: 78378.376 | DG9: 77683.002 | DH9: 84580.315 | DI9: 113345.31 | DJ9: 85242.12 | DK9: 87640.482 | DL9: 102842.86 | DM9: 99205.452 | DN9: 102385.1 | DO9: 102010.1 | DP9: 104163.14 | DQ9: 105466.17 | DR9: 105518.01 | DS9: 105562.6 | DT9: 106301.98 | DU9: 103742.32 | DV9: 117195.7 | DW9: 113559.1 | DX9: 112845.07 | DY9: 105497.7 | DZ9: 107727.63 | EA9: 108828.44 | EB9: 108901.25 | EC9: 107874.92 | ED9: 107164.95 | EE9: 110563.42 | EF9: 114057.54 | EG9: 112571.73 | EH9: 113340.9 | EI9: 116453.03 | EJ9: 116873.71 | EK9: 113686.82 | EL9: 110115.54 | EM9: 112345.63 | EN9: 112965.49 | EO9: 112636.17 | EP9: 111453.7 | EQ9: 115252.68 | ER9: 117996.57 | ES9: 119977.75 | ET9: 130555.41 | EU9: 121134.64 | EV9: 124189.01 | EW9: 123947.28 | EX9: 127027.11 | EY9: 120080.45 | EZ9: 126358.02 | FA9: 126480.71 | FB9: 124680.07 | FC9: 124955.29 | FD9: 126338.74 | FE9: 133037.76 | FF9: 134240.14 | FG9: 142709.25 | FH9: 145014.65 | FI9: 137096.55 | FJ9: 135720.34 | FK9: 148231.81 | FO9: =FK9-FJ9 -> 12511.47 | FS9: =FK9-FN9 -> 148231.81 | FT9: =SUM($FJ9:FK9) -> 283952.16
E10: Variable | H10: =SUM(V10:Y10) -> 0 | L10: =SUM(AL10:AO10) -> 1428728.8 | M10: =SUM(AP10:AS10) -> 1615107.7 | N10: =SUM(AT10:AW10) -> 1652962.7 | O10: =SUM(AX10:BA10) -> 1855901.6 | AJ10: =SUM(DH10:DJ10) -> 331899.66 | AK10: =SUM(DK10:DM10) -> 377831.98 | AL10: =SUM(DN10:DP10) -> 250233.31 | AM10: =SUM(DQ10:DS10) -> 304123.1 | AN10: =SUM(DT10:DV10) -> 394740.8 | AO10: =SUM(DW10:DY10) -> 479631.63 | AP10: =SUM(DZ10:EB10) -> 372003.41 | AQ10: =OFFSET($DZ10,0,AQ$4)+OFFSET($EA10,0,AQ$4)+OFFSET($EB10,0,AQ$4) -> 353720.92 | AR10: =OFFSET($DZ10,0,AR$4)+OFFSET($EA10,0,AR$4)+OFFSET($EB10,0,AR$4) -> 418521.96 | AS10: =OFFSET($DZ10,0,AS$4)+OFFSET($EA10,0,AS$4)+OFFSET($EB10,0,AS$4) -> 470861.41 | AT10: =SUM(EL10:EN10) -> 412730.42 | AU10: =OFFSET($EL10,0,AU$4)+OFFSET($EM10,0,AU$4)+OFFSET($EN10,0,AU$4) -> 413770.95 | AV10: =OFFSET($EL10,0,AV$4)+OFFSET($EM10,0,AV$4)+OFFSET($EN10,0,AV$4) -> 390449.89 | AW10: =OFFSET($EL10,0,AW$4)+OFFSET($EM10,0,AW$4)+OFFSET($EN10,0,AW$4) -> 436011.47 | AX10: =SUM(EX10:EZ10) -> 399003.81 | AY10: =SUM(FA10:FC10) -> 406872.76 | AZ10: =SUM(FD10:FF10) -> 525545.57 | BA10: =SUM(FG10:FI10) -> 524479.43 | CD10: 115265.06 | CE10: 73400.298 | CF10: 110520.03 | CG10: 78908.288 | CH10: 73446.58 | CI10: 57700.747 | CJ10: 63796.568 | CK10: 68594.054 | CL10: 110272.22 | CM10: 114969.85 | CN10: 109016.1 | CO10: 148342.53 | CP10: 134624.61 | CQ10: 119228.13 | CR10: 116947.82 | CS10: 87540.765 | CT10: 100803.65 | CU10: 85470.339 | CV10: 95643.46 | CW10: 85534.126 | CX10: 54786.481 | CY10: 63422.039 | CZ10: 51677.73 | DA10: 52458.945 | DB10: 59966.895 | DC10: 70716.794 | DD10: 69099.117 | DE10: 89731.045 | DF10: 95975.835 | DG10: 89080.428 | DH10: 93721.34 | DI10: 108308.03 | DJ10: 129870.29 | DK10: 111176.15 | DL10: 119661.18 | DM10: 146994.65 | DN10: 95809.609 | DO10: 100039.77 | DP10: 54383.936 | DQ10: 94127.176 | DR10: 107269.93 | DS10: 102726 | DT10: 119312.79 | DU10: 141159.21 | DV10: 134268.8 | DW10: 125073.6 | DX10: 134559.81 | DY10: 219998.22 | DZ10: 121179.36 | EA10: 135522.96 | EB10: 115301.09 | EC10: 138343.65 | ED10: 104276.51 | EE10: 111100.76 | EF10: 135028.2 | EG10: 124028.09 | EH10: 159465.67 | EI10: 116480.37 | EJ10: 146149.99 | EK10: 208231.04 | EL10: 124658.72 | EM10: 133202.46 | EN10: 154869.24 | EO10: 183304.36 | EP10: 127767.04 | EQ10: 102699.56 | ER10: 112158.63 | ES10: 128419.14 | ET10: 149872.12 | EU10: 132883.23 | EV10: 160801.78 | EW10: 142326.47 | EX10: 150188.56 | EY10: 125467.55 | EZ10: 123347.7 | FA10: 133927.93 | FB10: 129671.2 | FC10: 143273.64 | FD10: 159021.78 | FE10: 172412.62 | FF10: 194111.17 | FG10: 173698.1 | FH10: 177777.09 | FI10: 173004.23 | FJ10: 162529.94 | FK10: 176515.8 | FO10: =FK10-FJ10 -> 13985.861 | FS10: =FK10-FN10 -> 176515.8 | FT10: =SUM($FJ10:FK10) -> 339045.73
E11: SIM Sales | H11: =SUM(V11:Y11) -> 0 | L11: =SUM(AL11:AO11) -> 937577.31 | M11: =SUM(AP11:AS11) -> 581736.07 | N11: =SUM(AT11:AW11) -> 821325.35 | O11: =SUM(AX11:BA11) -> 802927.44 | AJ11: =SUM(DH11:DJ11) -> 279239.17 | AK11: =SUM(DK11:DM11) -> 215711.05 | AL11: =SUM(DN11:DP11) -> 170534.04 | AM11: =SUM(DQ11:DS11) -> 279448.86 | AN11: =SUM(DT11:DV11) -> 237844.28 | AO11: =SUM(DW11:DY11) -> 249750.14 | AP11: =SUM(DZ11:EB11) -> 115763.7 | AQ11: =OFFSET($DZ11,0,AQ$4)+OFFSET($EA11,0,AQ$4)+OFFSET($EB11,0,AQ$4) -> 118022.66 | AR11: =OFFSET($DZ11,0,AR$4)+OFFSET($EA11,0,AR$4)+OFFSET($EB11,0,AR$4) -> 229393.18 | AS11: =OFFSET($DZ11,0,AS$4)+OFFSET($EA11,0,AS$4)+OFFSET($EB11,0,AS$4) -> 118556.53 | AT11: =SUM(EL11:EN11) -> 209862.3 | AU11: =OFFSET($EL11,0,AU$4)+OFFSET($EM11,0,AU$4)+OFFSET($EN11,0,AU$4) -> 171081.41 | AV11: =OFFSET($EL11,0,AV$4)+OFFSET($EM11,0,AV$4)+OFFSET($EN11,0,AV$4) -> 222837.8 | AW11: =OFFSET($EL11,0,AW$4)+OFFSET($EM11,0,AW$4)+OFFSET($EN11,0,AW$4) -> 217543.84 | AX11: =SUM(EX11:EZ11) -> 168953.57 | AY11: =SUM(FA11:FC11) -> 224202.27 | AZ11: =SUM(FD11:FF11) -> 152728.45 | BA11: =SUM(FG11:FI11) -> 257043.14 | CD11: 23289 | CE11: 27280 | CF11: 9861 | CG11: 49636.538 | CH11: 42450.077 | CI11: 35674 | CJ11: 34793.706 | CK11: 15896.612 | CL11: 7795.9174 | CM11: 14305 | CN11: 50115 | CO11: 35602 | CP11: 17402.333 | CQ11: 30416.103 | CR11: 14232 | CS11: 43714.435 | CT11: 14430.765 | CU11: 14993.349 | CV11: 10207.669 | CW11: 12104.249 | CX11: 42512.312 | CY11: 31461.706 | CZ11: 48191.385 | DA11: 23794.565 | DB11: 33359.074 | DC11: 20369.052 | DD11: 48529.665 | DE11: 105305.01 | DF11: 54637.385 | DG11: 91605.607 | DH11: 74803.47 | DI11: 85052.698 | DJ11: 119383 | DK11: 128326.36 | DL11: 87097.78 | DM11: 286.90206 | DN11: 64659.563 | DO11: 43112.054 | DP11: 62762.421 | DQ11: 100642.12 | DR11: 81576.157 | DS11: 97230.584 | DT11: 92647.184 | DU11: 60616.364 | DV11: 84580.73 | DW11: 44432.29 | DX11: 158784.3 | DY11: 46533.546 | DZ11: 16195.721 | EA11: 22588.916 | EB11: 76979.067 | EC11: 39040.245 | ED11: 21269.585 | EE11: 57712.828 | EF11: 96567.482 | EG11: 73396.968 | EH11: 59428.727 | EI11: 47781.628 | EJ11: 37356.638 | EK11: 33418.262 | EL11: 27919.988 | EM11: 74067.919 | EN11: 107874.39 | EO11: 46017.345 | EP11: 64850.202 | EQ11: 60213.863 | ER11: 65770.981 | ES11: 83570.394 | ET11: 73496.426 | EU11: 124709.57 | EV11: 51718.627 | EW11: 41115.648 | EX11: 48944.892 | EY11: 91540.353 | EZ11: 28468.33 | FA11: 95899.364 | FB11: 43342.372 | FC11: 84960.537 | FD11: 23607.711 | FE11: 41277.143 | FF11: 87843.597 | FG11: 86884.464 | FH11: 50115.492 | FI11: 120043.19 | FJ11: 78640.174 | FK11: 34327.932 | FO11: =FK11-FJ11 -> -44312.242 | FS11: =FK11-FN11 -> 34327.932 | FT11: =SUM($FJ11:FK11) -> 112968.11
E12: Launchpad | L12: =SUM(AL12:AO12) -> 0 | M12: =SUM(AP12:AS12) -> 42214.701 | N12: =SUM(AT12:AW12) -> 80939.47 | O12: =SUM(AX12:BA12) -> 5800 | AA12: =SUM(CG12:CI12) -> 0 | AJ12: =SUM(DH12:DJ12) -> 0 | AK12: =SUM(DK12:DM12) -> 0 | AL12: =SUM(DN12:DP12) -> 0 | AM12: =SUM(DQ12:DS12) -> 0 | AN12: =SUM(DT12:DV12) -> 0 | AO12: =SUM(DW12:DY12) -> 0 | AP12: =SUM(DZ12:EB12) -> 0 | AQ12: =OFFSET($DZ12,0,AQ$4)+OFFSET($EA12,0,AQ$4)+OFFSET($EB12,0,AQ$4) -> 6856.6718 | AR12: =OFFSET($DZ12,0,AR$4)+OFFSET($EA12,0,AR$4)+OFFSET($EB12,0,AR$4) -> 20519.793 | AS12: =OFFSET($DZ12,0,AS$4)+OFFSET($EA12,0,AS$4)+OFFSET($EB12,0,AS$4) -> 14838.236 | AT12: =SUM(EL12:EN12) -> 23578.326 | AU12: =OFFSET($EL12,0,AU$4)+OFFSET($EM12,0,AU$4)+OFFSET($EN12,0,AU$4) -> 22722.132 | AV12: =OFFSET($EL12,0,AV$4)+OFFSET($EM12,0,AV$4)+OFFSET($EN12,0,AV$4) -> 14887.358 | AW12: =OFFSET($EL12,0,AW$4)+OFFSET($EM12,0,AW$4)+OFFSET($EN12,0,AW$4) -> 19751.654 | AX12: =SUM(EX12:EZ12) -> 3000 | AY12: =SUM(FA12:FC12) -> 1600 | AZ12: =SUM(FD12:FF12) -> 0 | BA12: =SUM(FG12:FI12) -> 1200 | BR12: =$V12/3 -> 0 | BS12: =$V12/3 -> 0 | BT12: =$V12/3 -> 0 | BU12: =$W12/3 -> 0 | BV12: =$W12/3 -> 0 | BW12: =$W12/3 -> 0 | BX12: =$X12/3 -> 0 | BY12: =$X12/3 -> 0 | BZ12: =$X12/3 -> 0 | CA12: =$Y12/3 -> 0 | CB12: =$Y12/3 -> 0 | CC12: =$Y12/3 -> 0 | CD12: =$Y12/3 -> 0 | EE12: 6856.6718 | EF12: 6746.3506 | EG12: 6820.439 | EH12: 6953.0032 | EI12: 5024.3569 | EJ12: 4949.5379 | EK12: 4864.3413 | EL12: 7851.7911 | EM12: 7873.6906 | EN12: 7852.8444 | EO12: 7911.7828 | EP12: 7875.4042 | EQ12: 6934.9447 | ER12: 6887.3582 | ES12: 4000 | ET12: 4000 | EU12: 7829.1538 | EV12: 7922.5001 | EW12: 4000 | EX12: 1000 | EY12: 1000 | EZ12: 1000 | FA12: 1300 | FB12: 300 | FC12: 0 | FD12: 0 | FE12: 0 | FF12: 0 | FG12: 1200 | FH12: 0 | FI12: 0 | FJ12: 0 | FK12: 0 | FO12: =FK12-FJ12 -> 0 | FS12: =FK12-FN12 -> 0 | FT12: =SUM($FJ12:FK12) -> 0
E13: Hardware | F13: 3463000 | G13: =SUM(R13:U13) -> 2366877 | H13: =SUM(V13:Y13) -> 988091 | I13: =SUM(Z13:AC13) -> 1242439 | J13: =SUM(AD13:AG13) -> 1617692.9 | K13: =SUM(AH13:AK13) -> 1112186.6 | L13: =SUM(AL13:AO13) -> 1417113.5 | M13: =SUM(AP13:AS13) -> 1100085.6 | N13: =SUM(AT13:AW13) -> 762730.39 | O13: =SUM(AX13:BA13) -> 1154651.5 | P13: =FJ13 -> 35492.031 | R13: =SUM(BF13:BH13) -> 743655 | S13: =SUM(BI13:BK13) -> 371572 | T13: =SUM(BL13:BN13) -> 373641 | U13: =SUM(BO13:BQ13) -> 878009 | V13: =SUM(BR13:BT13) -> 128748 | W13: =SUM(BU13:BW13) -> 240084 | X13: =SUM(BX13:BZ13) -> 199978 | Y13: =SUM(CA13:CC13) -> 419281 | Z13: =SUM(CD13:CF13) -> 276645 | AA13: =SUM(CG13:CI13) -> 297568 | AB13: =SUM(CJ13:CL13) -> 366985 | AC13: =SUM(CM13:CO13) -> 301241 | AD13: =SUM(CP13:CR13) -> 457553 | AE13: =SUM(CS13:CU13) -> 690431 | AF13: =SUM(CV13:CX13) -> 259512.28 | AG13: =SUM(CY13:DA13) -> 210196.58 | AH13: =SUM(DB13:DD13) -> 232662.11 | AI13: =SUM(DE13:DG13) -> 309222.63 | AJ13: =SUM(DH13:DJ13) -> 413104.04 | AK13: =SUM(DK13:DM13) -> 157197.77 | AL13: =SUM(DN13:DP13) -> 241145.52 | AM13: =SUM(DQ13:DS13) -> 313656.01 | AN13: =SUM(DT13:DV13) -> 478260.9 | AO13: =SUM(DW13:DY13) -> 384051.08 | AP13: =SUM(DZ13:EB13) -> 208481.71 | AQ13: =OFFSET($DZ13,0,AQ$4)+OFFSET($EA13,0,AQ$4)+OFFSET($EB13,0,AQ$4) -> 285083.34 | AR13: =OFFSET($DZ13,0,AR$4)+OFFSET($EA13,0,AR$4)+OFFSET($EB13,0,AR$4) -> 226270.69 | AS13: =OFFSET($DZ13,0,AS$4)+OFFSET($EA13,0,AS$4)+OFFSET($EB13,0,AS$4) -> 380249.86 | AT13: =SUM(EL13:EN13) -> 241769.57 | AU13: =OFFSET($EL13,0,AU$4)+OFFSET($EM13,0,AU$4)+OFFSET($EN13,0,AU$4) -> 270294.94 | AV13: =OFFSET($EL13,0,AV$4)+OFFSET($EM13,0,AV$4)+OFFSET($EN13,0,AV$4) -> 111667.39 | AW13: =OFFSET($EL13,0,AW$4)+OFFSET($EM13,0,AW$4)+OFFSET($EN13,0,AW$4) -> 138998.49 | AX13: =SUM(EX13:EZ13) -> 185596.49 | AY13: =SUM(FA13:FC13) -> 241618.85 | AZ13: =SUM(FD13:FF13) -> 579986.7 | BA13: =SUM(FG13:FI13) -> 147449.46 | BB13: =SUM(FJ13:FL13) -> 41459.954 | BF13: 654126 | BG13: 11580 | BH13: 77949 | BI13: 57451 | BJ13: 255545 | BK13: 58576 | BL13: 57120 | BM13: 138179 | BN13: 178342 | BO13: 665930 | BP13: 146843 | BQ13: 65236 | BR13: 9430 | BS13: 48105 | BT13: 71213 | BU13: 157072 | BV13: 48958 | BW13: 34054 | BX13: 140299 | BY13: 20342 | BZ13: 39337 | CA13: 128471 | CB13: 16346 | CC13: 274464 | CD13: 129508 | CE13: 13152 | CF13: 133985 | CG13: 264786 | CH13: 18236 | CI13: 14546 | CJ13: 93059 | CK13: 68613 | CL13: 205313 | CM13: 62214 | CN13: 133730 | CO13: 105297 | CP13: 303450 | CQ13: 32485 | CR13: 121618 | CS13: 116168 | CT13: 330962 | CU13: 243301 | CV13: 27193 | CW13: 2790.5 | CX13: 229528.78 | CY13: 150115.17 | CZ13: =30356.92-0.09 -> 30356.83 | DA13: 29724.58 | DB13: 183477.43 | DC13: =35596.47-0.09 -> 35596.38 | DD13: 13588.3 | DE13: 12172.14 | DF13: 27121.33 | DG13: 269929.16 | DH13: 244135.2 | DI13: 128273.85 | DJ13: 40694.99 | DK13: 27195.9 | DL13: 24129.56 | DM13: 105872.31 | DN13: 35574.36 | DO13: 14132.3 | DP13: 191438.86 | DQ13: 138850.63 | DR13: 162944.53 | DS13: 11860.85 | DT13: 25840.52 | DU13: 147417.4 | DV13: 305002.98 | DW13: 14502.12 | DX13: 50499 | DY13: 319049.96 | DZ13: 23688.56 | EA13: 5833.56 | EB13: 178959.59 | EC13: 63193.34 | ED13: 64965.84 | EE13: 156924.16 | EF13: 132446.09 | EG13: 81073.888 | EH13: 12750.715 | EI13: 152529.23 | EJ13: 126874.81 | EK13: 100845.82 | EL13: 18673.033 | EM13: 44687.518 | EN13: 178409.02 | EO13: 16172.264 | EP13: 116334.87 | EQ13: 137787.8 | ER13: 26635.98 | ES13: 66614.784 | ET13: 18416.63 | EU13: 33514.747 | EV13: 98079.36 | EW13: 7404.38 | EX13: 5699.8505 | EY13: 171809.88 | EZ13: 8086.7602 | FA13: 54512.492 | FB13: 176384.02 | FC13: 10722.343 | FD13: 194362.9 | FE13: 140511.83 | FF13: 245111.98 | FG13: 22686.995 | FH13: 5096.3657 | FI13: 119666.1 | FJ13: 35492.031 | FK13: 5967.9228 | FN13: ='Financial plan'!EZ18 -> 94532.828 | FO13: =FK13-FJ13 -> -29524.109 | FP13: =FK13-FN13 -> -88564.905 | FQ13: =FL13-#REF! -> #REF! | FR13: =FM13-FO13 -> 29524.109 | FS13: =FK13-FN13 -> -88564.905 | FT13: =SUM($FJ13:FK13) -> 41459.954 | FU13: =SUM('Financial plan'!$EY18:EZ18) -> 189065.66 | FV13: =FT13-FU13 -> -147605.7
E14: Consultancy | F14: 173000 | G14: =SUM(R14:U14) -> 151312 | H14: =SUM(V14:Y14) -> 166181 | I14: =SUM(Z14:AC14) -> 117066 | J14: =SUM(AD14:AG14) -> 532586.26 | K14: =SUM(AH14:AK14) -> 319517.41 | L14: =SUM(AL14:AO14) -> 537797.18 | M14: =SUM(AP14:AS14) -> 749820.46 | N14: =SUM(AT14:AW14) -> 878350.6 | O14: =SUM(AX14:BA14) -> 852881.87 | P14: =FJ14 -> 17700.495 | R14: =SUM(BF14:BH14) -> 42801 | S14: =SUM(BI14:BK14) -> 52523 | T14: =SUM(BL14:BN14) -> 45989 | U14: =SUM(BO14:BQ14) -> 9999 | V14: =SUM(BR14:BT14) -> 25890 | W14: =SUM(BU14:BW14) -> 3100 | X14: =SUM(BX14:BZ14) -> 68820 | Y14: =SUM(CA14:CC14) -> 68371 | Z14: =SUM(CD14:CF14) -> 17525 | AA14: =SUM(CG14:CI14) -> 8596 | AB14: =SUM(CJ14:CL14) -> 17440 | AC14: =SUM(CM14:CO14) -> 73505 | AD14: =SUM(CP14:CR14) -> 72280 | AE14: =SUM(CS14:CU14) -> 97187 | AF14: =SUM(CV14:CX14) -> 154889.26 | AG14: =SUM(CY14:DA14) -> 208230 | AH14: =SUM(DB14:DD14) -> 101944.35 | AI14: =SUM(DE14:DG14) -> 98946.47 | AJ14: =SUM(DH14:DJ14) -> 46289.61 | AK14: =SUM(DK14:DM14) -> 72336.98 | AL14: =SUM(DN14:DP14) -> 91170.09 | AM14: =SUM(DQ14:DS14) -> 144447.63 | AN14: =SUM(DT14:DV14) -> 166988.99 | AO14: =SUM(DW14:DY14) -> 135190.47 | AP14: =SUM(DZ14:EB14) -> 104909.41 | AQ14: =OFFSET($DZ14,0,AQ$4)+OFFSET($EA14,0,AQ$4)+OFFSET($EB14,0,AQ$4) -> 131801.87 | AR14: =OFFSET($DZ14,0,AR$4)+OFFSET($EA14,0,AR$4)+OFFSET($EB14,0,AR$4) -> 219953.36 | AS14: =OFFSET($DZ14,0,AS$4)+OFFSET($EA14,0,AS$4)+OFFSET($EB14,0,AS$4) -> 293155.82 | AT14: =SUM(EL14:EN14) -> 279442.49 | AU14: =OFFSET($EL14,0,AU$4)+OFFSET($EM14,0,AU$4)+OFFSET($EN14,0,AU$4) -> 287024.3 | AV14: =OFFSET($EL14,0,AV$4)+OFFSET($EM14,0,AV$4)+OFFSET($EN14,0,AV$4) -> 297140.74 | AW14: =OFFSET($EL14,0,AW$4)+OFFSET($EM14,0,AW$4)+OFFSET($EN14,0,AW$4) -> 14743.069 | AX14: =SUM(EX14:EZ14) -> 221862.7 | AY14: =SUM(FA14:FC14) -> 175682.49 | AZ14: =SUM(FD14:FF14) -> 224583.26 | BA14: =SUM(FG14:FI14) -> 230753.41 | BB14: =SUM(FJ14:FL14) -> 27768.797 | BF14: 10000 | BG14: 12937 | BH14: 19864 | BI14: 20159 | BJ14: 9575 | BK14: 22789 | BL14: 10960 | BM14: 15029 | BN14: 20000 | BO14: 8333 | BP14: 833 | BQ14: 833 | BR14: 17364 | BS14: 0 | BT14: 8526 | BU14: 0 | BV14: 3100 | BW14: 0 | BX14: 43231 | BY14: 8500 | BZ14: 17089 | CA14: 27493 | CB14: 37878 | CC14: 3000 | CD14: 1500 | CE14: 16025 | CF14: 0 | CG14: 0 | CH14: 288 | CI14: 8308 | CJ14: 0 | CK14: 10582 | CL14: 6858 | CM14: 30100 | CN14: =1000+10000 -> 11000 | CO14: 32405 | CP14: 7581 | CQ14: 46547 | CR14: 18152 | CS14: 29327 | CT14: 27211 | CU14: 40649 | CV14: 53633 | CW14: 51256.26 | CX14: 50000 | CY14: 75707.83 | CZ14: 67025 | DA14: 65497.17 | DB14: 40000.28 | DC14: 40000 | DD14: 21944.07 | DE14: 30182.6 | DF14: 31415.43 | DG14: 37348.44 | DH14: 12811.89 | DI14: 3986.54 | DJ14: 29491.18 | DK14: 7509.78 | DL14: 14039.72 | DM14: 50787.48 | DN14: 9634.47 | DO14: 10864.91 | DP14: 70670.71 | DQ14: 49612.77 | DR14: 79154.94 | DS14: 15679.92 | DT14: 13657.19 | DU14: 44891.384 | DV14: 108440.42 | DW14: 25877.37 | DX14: 72782.48 | DY14: 36530.62 | DZ14: 27724.44 | EA14: 23263.95 | EB14: 53921.02 | EC14: 23160.78 | ED14: 76654.2 | EE14: 31986.89 | EF14: 28256.076 | EG14: 57130.256 | EH14: 134567.02 | EI14: 80414.973 | EJ14: 75914.929 | EK14: 136825.92 | EL14: 76987.468 | EM14: 90733.98 | EN14: 111721.04 | EO14: 29006.563 | EP14: 148282.31 | EQ14: 109735.43 | ER14: 104906.03 | ES14: 114396.43 | ET14: 77838.281 | EU14: 41890.712 | EV14: 28596.837 | EW14: -55744.48 | EX14: 65568.137 | EY14: 92252.94 | EZ14: 64041.624 | FA14: 51555.678 | FB14: 42881.247 | FC14: 81245.563 | FD14: 79485.141 | FE14: 84359.948 | FF14: 60738.173 | FG14: 65842.484 | FH14: 83846.499 | FI14: 81064.431 | FJ14: 17700.495 | FK14: 10068.302 | FN14: ='Financial plan'!EZ19 -> 45000 | FO14: =FK14-FJ14 -> -7632.1926 | FP14: =FK14-FN14 -> -34931.698 | FQ14: =FL14-#REF! -> #REF! | FR14: =FM14-FO14 -> 7632.1926 | FS14: =FK14-FN14 -> -34931.698 | FT14: =SUM($FJ14:FK14) -> 27768.797 | FU14: =SUM('Financial plan'!$EY19:EZ19) -> 90000 | FV14: =FT14-FU14 -> -62231.203
E15: General Consultancy | CD15: 1500 | CE15: 16025 | CF15: 0 | CG15: 0 | CH15: 288 | CI15: 8308 | CJ15: 0 | CK15: 10582 | CL15: 6858 | CM15: 30100 | CN15: 11000 | CO15: 32405 | CP15: 7581 | CQ15: 46547 | CR15: 18152 | CS15: 29327 | CT15: 27211 | CU15: 40649 | CV15: 53633.572 | CW15: 51256.26 | CX15: 50000 | CY15: 75707.831 | CZ15: 67025 | DA15: 65497.17 | DB15: 40000.28 | DC15: 40000 | DD15: -10469.436 | DE15: 6995.2635 | DF15: 18946.8 | DG15: 37348.444 | DH15: 12811.892 | DI15: 0 | DJ15: 24150 | DK15: 0 | DL15: 7707.51 | DM15: 0 | DN15: 0 | DO15: 0 | DP15: 20.24 | DR15: 15854.5 | DU15: 12406.01 | EC15: 2200 | FA15: 3801.3223 | FO15: =FK15-FJ15 -> 0 | FP15: =FK15-FN15 -> 0 | FQ15: =FL15-#REF! -> #REF! | FR15: =FM15-FO15 -> 0 | FS15: =FK15-FN15 -> 0 | FT15: =SUM($FJ15:FK15) -> 0
E16: Deployment Services | P16: =FJ16 -> 2259.2952 | AZ16: =SUM(FD16:FG16) -> 40576.867 | BB16: =SUM(FJ16:FL16) -> 4053.8648 | CD16: 0 | CE16: 0 | CF16: 0 | CG16: 0 | CH16: 0 | CI16: 0 | CJ16: 0 | CK16: 0 | CL16: 0 | CM16: 0 | CN16: 0 | CO16: 0 | CP16: 0 | CQ16: 0 | CR16: 0 | CS16: 0 | CT16: 0 | CU16: 0 | CV16: 0 | CW16: 0 | CX16: 0 | CY16: 0 | CZ16: 0 | DA16: 0 | DB16: 0 | DC16: 0 | DD16: 32413.092 | DE16: 23187.34 | DF16: 12469.034 | DG16: 0 | DH16: -1.8189894e-12 | DI16: 3986.537 | DJ16: 5341.1812 | DK16: 7509.7799 | DL16: 4132.8898 | DM16: 12069.793 | DN16: 5511.619 | DO16: 10864.909 | DP16: 8264.1201 | DQ16: 1792.28 | DR16: 17334.931 | DS16: 4516.1613 | DT16: 7878.1 | DU16: 13642.28 | DV16: 13924.119 | DW16: 18312.24 | DX16: 9205.8079 | DY16: 16697.674 | DZ16: 19168.4 | EA16: 6512.6125 | EB16: 3730.1279 | EC16: 7363.3933 | ED16: 2275.9012 | EE16: 1908.9262 | EF16: 14439.366 | EG16: 5060.5621 | EH16: 11540.3 | EI16: 11896.457 | EJ16: 2165.9 | EK16: 36612.435 | EL16: 455.3202 | EM16: 14527.95 | EN16: 2809.5048 | EO16: 3733.0272 | EP16: 14615.479 | EQ16: 6177.2445 | ER16: 14530.97 | ES16: 16602.27 | ET16: =6205.802403313 -> 6205.8024 | EU16: 4745.3868 | EV16: 9414.48 | EW16: 4080.87 | EX16: 10280 | EY16: 4907.6078 | EZ16: =7185.22654141451+15000 -> 22185.227 | FA16: 3982.4 | FB16: 1931.3745 | FC16: =2014.12455963009+22500 -> 24514.125 | FD16: =11472.7883077621+2156.85+16302.46 -> 29932.098 | FE16: 2079.7384 | FF16: 924.36051 | FG16: 7640.67 | FH16: 11328.987 | FI16: =2605+1076 -> 3681 | FJ16: 2259.2952 | FK16: 1794.5695 | FO16: =FK16-FJ16 -> -464.72571 | FP16: =FK16-FN16 -> 1794.5695 | FQ16: =FL16-#REF! -> #REF! | FR16: =FM16-FO16 -> 464.72571 | FS16: =FK16-FN16 -> 1794.5695 | FT16: =SUM($FJ16:FK16) -> 4053.8648
E17: Migration Services | P17: =FJ17 -> 0 | AZ17: =SUM(FD17:FG17) -> 0 | BB17: =SUM(FJ17:FL17) -> 0 | ES17: 19320.456 | ET17: 3785.1656 | EU17: 20000 | EV17: 0 | EZ17: 0 | FA17: 9015.73 | FB17: 1500 | FC17: 0 | FE17: 0 | FH17: 10250 | FJ17: 0 | FK17: 0 | FO17: =FK17-FJ17 -> 0 | FP17: =FK17-FN17 -> 0 | FQ17: =FL17-#REF! -> #REF! | FR17: =FM17-FO17 -> 0 | FS17: =FK17-FN17 -> 0 | FT17: =SUM($FJ17:FK17) -> 0
E18: Software Licensing Service | P18: =FJ18 -> 0 | AZ18: =SUM(FD18:FG18) -> 20209.931 | BB18: =SUM(FJ18:FL18) -> 0 | EK18: 11843.044 | EO18: 16779.516 | EP18: 0 | EQ18: 0 | ER18: 0 | ES18: 0 | FD18: 7574.2674 | FE18: 12635.664 | FO18: =FK18-FJ18 -> 0 | FP18: =FK18-FN18 -> 0 | FQ18: =FL18-#REF! -> #REF! | FR18: =FM18-FO18 -> 0 | FS18: =FK18-FN18 -> 0 | FT18: =SUM($FJ18:FK18) -> 0
E19: Device Design | P19: =FJ19 -> 0 | AZ19: =SUM(FD19:FG19) -> 15543.78 | BB19: =SUM(FJ19:FL19) -> 0 | CD19: 0 | CE19: 0 | CF19: 0 | CG19: 0 | CH19: 0 | CI19: 0 | CJ19: 0 | CK19: 0 | CL19: 0 | CM19: 0 | CN19: 0 | CO19: 0 | CP19: 0 | CQ19: 0 | CR19: 0 | CS19: 0 | CT19: 0 | CU19: 0 | CV19: 0 | CW19: 0 | CX19: 0 | CY19: 0 | CZ19: 0 | DA19: 0 | DB19: 0 | DC19: 0 | DD19: 0 | DE19: 0 | DF19: 0 | DG19: 0 | DH19: 0 | DI19: 0 | DJ19: 0 | DK19: 0 | DL19: -7.2759576e-12 | DM19: 38717.69 | DN19: 0 | DO19: 0 | DP19: 60088.42 | DR19: 28466.546 | DS19: 5600 | DU19: 8400 | DV19: 33434.848 | DX19: 54262.96 | DY19: 18756.366 | DZ19: 3364.3183 | EA19: 15841.811 | EB19: 13678.378 | EC19: 9907.56 | ED19: 44009.465 | EE19: 6042.36 | EF19: 4000 | EG19: 6474.26 | EH19: 40745.3 | EI19: 0 | EJ19: 1146.7085 | EK19: 9338.2086 | EL19: 0 | EM19: 0 | EN19: 25000 | EP19: 10468.994 | EQ19: 37116.698 | ER19: =23369.4812214799+6219.77 -> 29589.251 | ES19: 18403 | EU19: 3063.3231 | EW19: 5000 | EY19: 51016.436 | FD19: 15543.78 | FE19: 0 | FO19: =FK19-FJ19 -> 0 | FP19: =FK19-FN19 -> 0 | FQ19: =FL19-#REF! -> #REF! | FR19: =FM19-FO19 -> 0 | FS19: =FK19-FN19 -> 0 | FT19: =SUM($FJ19:FK19) -> 0
E20: IOT Advisory Services | P20: =FJ20 -> 4316.1994 | AZ20: =SUM(FD20:FG20) -> 126971.08 | BB20: =SUM(FJ20:FL20) -> 8589.9319 | CD20: 0 | CE20: 0 | CF20: 0 | CG20: 0 | CH20: 0 | CI20: 0 | CJ20: 0 | CK20: 0 | CL20: 0 | CM20: 0 | CN20: 0 | CO20: 0 | CP20: 0 | CQ20: 0 | CR20: 0 | CS20: 0 | CT20: 0 | CU20: 0 | CV20: 0 | CW20: 0 | CX20: 0 | CY20: 0 | CZ20: 0 | DA20: 0 | DB20: 0 | DC20: 0 | DD20: 0 | DE20: 0 | DF20: 0 | DG20: 0 | DH20: 0 | DI20: 0 | DJ20: 0 | DK20: 0 | DL20: 2199.32 | DM20: 0 | DN20: 4122.85 | DO20: 0 | DP20: 2297.93 | DQ20: 9254.82 | DR20: 7980.92 | DS20: 5563.76 | DT20: 5779.08 | DU20: 5789.47 | DV20: 6035.6 | DW20: 7565.1 | DX20: 9313.71 | DY20: 1000 | DZ20: 5272.38 | EA20: 909.52819 | EB20: 30340.89 | EC20: 3689.8247 | ED20: 30368.83 | EE20: 18142.89 | EF20: 4681.72 | EG20: 35755.803 | EH20: 11544.1 | EI20: 8063.3305 | EJ20: 11629.683 | EK20: 13078.083 | EL20: 16563.25 | EM20: 14376.744 | EN20: 15721.417 | EO20: 1312.0775 | EQ20: 3150 | ER20: 1000 | ET20: 7610.4655 | EU20: 7620.2123 | EV20: 10109.34 | EW20: 7746.8703 | EX20: 22201.701 | EY20: 7814.628 | EZ20: =6205.86619233899+7645.76 -> 13851.626 | FA20: 7603.931 | FB20: 12589.983 | FC20: 29500.406 | FE20: 86043.574 | FF20: 30244.577 | FG20: 10682.929 | FH20: 7783.3664 | FI20: 29383.194 | FJ20: 4316.1994 | FK20: 4273.7325 | FO20: =FK20-FJ20 -> -42.46688 | FP20: =FK20-FN20 -> 4273.7325 | FQ20: =FL20-#REF! -> #REF! | FR20: =FM20-FO20 -> 42.46688 | FS20: =FK20-FN20 -> 4273.7325 | FT20: =SUM($FJ20:FK20) -> 8589.9319
E21: Device Certification Services | P21: =FJ21 -> 0 | AZ21: =SUM(FD21:FG21) -> 0 | BB21: =SUM(FJ21:FL21) -> 0 | DR21: 9518.04 | DU21: 4653.62 | DV21: 11009.17 | EG21: 9839.6 | EH21: 11205.2 | EO21: 0 | FO21: =FK21-FJ21 -> 0 | FP21: =FK21-FN21 -> 0 | FQ21: =FL21-#REF! -> #REF! | FR21: =FM21-FO21 -> 0 | FS21: =FK21-FN21 -> 0 | FT21: =SUM($FJ21:FK21) -> 0
E22: Interconnect | P22: =FJ22 -> 0 | AZ22: =SUM(FD22:FG22) -> 100398.11 | BB22: =SUM(FJ22:FL22) -> 0 | CD22: 0 | CE22: 0 | CF22: 0 | CG22: 0 | CH22: 0 | CI22: 0 | CJ22: 0 | CK22: 0 | CL22: 0 | CM22: 0 | CN22: 0 | CO22: 0 | CP22: 0 | CQ22: 0 | CR22: 0 | CS22: 0 | CT22: 0 | CU22: 0 | CV22: 0 | CW22: 0 | CX22: 0 | CY22: 0 | CZ22: 0 | DA22: 0 | DB22: 0 | DC22: 0 | DD22: 0 | DE22: 0 | DF22: 0 | DG22: 0 | DH22: 0 | DI22: 0 | DJ22: 0 | DK22: 0 | DL22: 0 | DM22: -2.9132252e-13 | DN22: 0 | DO22: 0 | DP22: 0 | DQ22: 38565.67 | DV22: 44036.679 | EB22: 6171.62 | EE22: 5892.71 | EF22: 5134.99 | EH22: 59532.1 | EI22: 60455.186 | EJ22: 60972.67 | EK22: 59497.589 | EL22: 58746.152 | EM22: 58444.205 | EN22: 58502.622 | EP22: 120586.73 | EQ22: 59980.513 | ER22: 59785.807 | ES22: 60070.817 | ET22: 60236.847 | EV22: 9073.02 | EW22: -75072.217 | EX22: 28900.831 | EY22: 28514.268 | EZ22: 27704.755 | FA22: 27152.298 | FB22: 26715.191 | FC22: 26356.032 | FD22: 26434.99 | FF22: 26444.236 | FG22: 47518.886 | FH22: 48394.427 | FI22: 48000.368 | FO22: =FK22-FJ22 -> 0 | FP22: =FK22-FN22 -> 0 | FQ22: =FL22-#REF! -> #REF! | FR22: =FM22-FO22 -> 0 | FS22: =FK22-FN22 -> 0 | FT22: =SUM($FJ22:FK22) -> 0
E23: VPN Set Up Fees | P23: =FJ23 -> 4000 | AZ23: =SUM(FD23:FG23) -> 0 | BB23: =SUM(FJ23:FL23) -> 4000 | EK23: 6456.5588 | EL23: 1222.75 | EM23: 3385.08 | EN23: 9687.5 | EO23: 7181.943 | EP23: 2611.1058 | EQ23: 3310.9724 | EU23: 6461.79 | EW23: 2500 | EX23: 4185.57 | EZ23: 300.02 | FB23: 144.69816 | FC23: 875 | FH23: 2964.7183 | FJ23: 4000 | FO23: =FK23-FJ23 -> -4000 | FP23: =FK23-FN23 -> 0 | FQ23: =FL23-#REF! -> #REF! | FR23: =FM23-FO23 -> 4000 | FS23: =FK23-FN23 -> 0 | FT23: =SUM($FJ23:FK23) -> 4000
E24: Recurring Professional Services | P24: =FJ24 -> 7125 | BB24: =SUM(FJ24:FL24) -> 11125 | FF24: 3125 | FG24: 0 | FH24: 3125 | FJ24: 7125 | FK24: 4000 | FO24: =FK24-FJ24 -> -3125 | FP24: =FK24-FN24 -> 4000 | FQ24: =FL24-#REF! -> #REF! | FR24: =FM24-FO24 -> 3125 | FS24: =FK24-FN24 -> 4000 | FT24: =SUM($FJ24:FK24) -> 11125
