Workbook
Name Buildings: #REF!
Name Buildings: #REF!
Name Buildings: #REF!
Name CCDebt: #REF!
Name CCDebt: #REF!
Name CCDebt: #REF!
Name CommLoan: #REF!
Name CommLoan: #REF!
Name CommLoan: #REF!
Name CommMortgage: #REF!
Name CommMortgage: #REF!
Name CommMortgage: #REF!
Name Equipment: #REF!
Name Equipment: #REF!
Name Equipment: #REF!
Name Furniture: #REF!
Name Furniture: #REF!
Name Furniture: #REF!
Name Inventory: #REF!
Name Inventory: #REF!
Name Inventory: #REF!
Name Land: #REF!
Name Land: #REF!
Name Land: #REF!
Name LeaseImprovements: #REF!
Name LeaseImprovements: #REF!
Name LeaseImprovements: #REF!
Name NetIncomeY1: #REF!
Name NetIncomeY1: #REF!
Name NetIncomeY1: #REF!
Name NetIncomeY2: #REF!
Name NetIncomeY2: #REF!
Name NetIncomeY2: #REF!
Name NetIncomeY3: #REF!
Name NetIncomeY3: #REF!
Name NetIncomeY3: #REF!
Name OtherBankDebt: #REF!
Name OtherBankDebt: #REF!
Name OtherBankDebt: #REF!
Name OtherFixedAssets: #REF!
Name OtherFixedAssets: #REF!
Name OtherFixedAssets: #REF!
Name OtherStartUp: #REF!
Name OtherStartUp: #REF!
Name OtherStartUp: #REF!
Name OutsideInvest: #REF!
Name OutsideInvest: #REF!
Name OutsideInvest: #REF!
Name OwnerEquity: #REF!
Name OwnerEquity: #REF!
Name OwnerEquity: #REF!
Name TotalOperatingCapital: #REF!
Name TotalOperatingCapital: #REF!
Name TotalOperatingCapital: #REF!
Name VehicleLoan: #REF!
Name VehicleLoan: #REF!
Name VehicleLoan: #REF!
Name Vehicles: #REF!
Name Vehicles: #REF!
Name Vehicles: #REF!

Sheet KPIs
A1: KPIs | B1: 45688 | C1: =EOMONTH(B1,1) -> 45716 | D1: =EOMONTH(C1,1) -> 45747 | E1: =EOMONTH(D1,1) -> 45777 | F1: =EOMONTH(E1,1) -> 45808 | G1: =EOMONTH(F1,1) -> 45838 | H1: =EOMONTH(G1,1) -> 45869 | I1: =EOMONTH(H1,1) -> 45900 | J1: =EOMONTH(I1,1) -> 45930 | ... P1: =EOMONTH(O1,1) -> 46112
A2: Users & Portfolio
A3: Registered Users (#) | B3: 494297 | C3: 504031 | D3: 513981 | E3: 522500 | F3: 538436 | G3: 543695 | H3: 552633 | I3: 559897 | J3: 567121 | K3: 573478 | L3: 579855 | M3: 584965 | N3: 591016 | O3: 596742 | P3: 600172
A4: Active Users (#) | B4: 226146 | C4: 231773 | D4: 236870 | E4: 241746 | F4: 247892 | G4: 248511 | H4: 252520 | I4: 255609 | J4: 258711 | K4: 261795 | L4: 265348 | M4: 267784 | N4: 273948 | O4: 276036 | P4: 276453
A5: New Drawdowns - Unique Requesting Users (#) | B5: 42683 | C5: 43134 | D5: 43821 | E5: 40160 | F5: 39726 | G5: 17845 | H5: 30709 | I5: 30976 | J5: 31051 | K5: 29324 | L5: 28620 | M5: 28047 | N5: 28830 | O5: 27628 | P5: 28083
A6: Repeat Users (#) | B6: 38934 | C6: 39521 | D6: 40272 | E6: 37102 | F6: 34752 | G6: 16769 | H6: 28742 | I6: 29008 | J6: 29335 | K6: 27605 | L6: 27090 | M6: 26638 | N6: 27083 | O6: 25590 | P6: 26866
A7: Cards Issued | B7: 5122 | C7: 4899 | D7: 3252 | E7: 4760 | F7: 6403 | G7: 3374 | H7: 5999 | I7: 4623 | J7: 4392 | K7: 3462 | L7: 3505 | M7: 2180 | N7: 3744 | O7: 3864 | P7: 2187
A8: Transaction volume (#) | B8: 103802 | C8: 98457 | D8: 99541 | E8: 85519 | F8: 83805 | G8: 36808 | H8: 68162 | I8: 69070 | J8: 67892 | K8: 64241 | L8: 61358 | M8: 61470 | N8: 62474 | O8: 56834 | P8: 59121
A9: Disbursements excl. pre-funded payroll (USD). | B9: 2034326 | C9: 2434497.2 | D9: 3067014.7 | E9: 2290037.7 | F9: 3760153.5 | G9: 932695.52 | H9: 1491979.3 | I9: 1508302.2 | J9: 1523537.4 | K9: 1430445.2 | L9: 1371619 | M9: 1384192.6 | N9: 1509027 | O9: 1615851.4 | P9: 1431445.3
A10: Total Disbursements (USD) | B10: 4756632.1 | C10: 6256569.5 | D10: 7169230.5 | E10: 5467515.2 | F10: 6581188.3 | G10: 7066496 | H10: 6642667.2 | I10: 6875077.6 | J10: 6855507.9 | K10: 6726503.7 | L10: 6829381.2 | M10: 7991266.4 | N10: 6087382 | O10: 4999903.1 | P10: 5161476.2
A11: Outstanding loan portfolio USD | B11: 11061301 | C11: 11639441 | D11: 12389538 | E11: 13117178 | F11: 15154152 | G11: 14238202 | H11: 14078838 | I11: 13734582 | J11: 13548324 | K11: 13241065 | L11: 12817595 | M11: 12199561 | N11: =BS!C5 -> 12205653 | O11: =BS!D5 -> 12003091 | P11: =BS!E5 -> 10289266
A12: EOM FX Rate (USD/EGP) | B12: 50.24 | C12: 50.66 | D12: 50.58 | E12: 50.81 | F12: 49.74 | G12: 49.6 | H12: 48.68 | I12: 48.48 | J12: 47.87 | K12: 47.22 | L12: 47.57895 | M12: 47.68 | N12: 46.91 | O12: 47.93 | P12: 54.59
A13: Active Users - Outstanding Balance | B13: 99096 | C13: 100196 | D13: 100800 | E13: 104050 | F13: 109045 | G13: 103374 | H13: 102580 | I13: 100534 | J13: 100156 | K13: 99104 | L13: 98455 | M13: 96504 | N13: 95897 | O13: 95956 | P13: 94320
A14: Avg Outstanding Loan Amount USD | B14: =B11/B13 -> 111.62207 | C14: =C11/C13 -> 116.16672 | D14: =D11/D13 -> 122.91208 | E14: =E11/E13 -> 126.06611 | F14: =F11/F13 -> 138.97154 | G14: =G11/G13 -> 137.73485 | H14: =H11/H13 -> 137.24739 | I14: =I11/I13 -> 136.61629 | ... P14: =P11/P13 -> 109.08891
A15: Net Defaults USD | B15: 11881.87 | C15: 5744.77 | D15: 18870.7 | E15: 12523.69 | F15: 14399.5 | G15: 17821.75 | H15: 2576.18 | I15: 457.34 | J15: 3322.4 | K15: 2531.36 | L15: -553.13 | M15: 75794.47 | N15: -46963 | O15: 95.614407 | P15: 700.4999
A16: PAR 30 (%) | B16: 0.0072 | C16: 0.0078 | D16: 0.0081 | E16: 0.008 | F16: 0.0075 | G16: 0.0078 | H16: 0.0099 | I16: 0.009 | J16: 0.0086 | K16: 0.0084 | L16: 0.0081 | M16: 0.0078 | N16: 0.0099 | O16: 0.0088 | P16: 0.0099
A17: PAR 90 (%) | B17: 0.0034 | C17: 0.0038 | D17: 0.0043 | E17: 0.0043 | F17: 0.0042 | G17: 0.0045 | H17: 0.005 | I17: 0.0049 | J17: 0.0054 | K17: 0.0052 | L17: 0.0053 | M17: 0.0044 | N17: 0.005 | O17: 0.0043 | P17: 0.0062
A18: Financial KPIs
A19: Average FX Rate (USD/EGP) | B19: 50.42 | C19: 50.5 | D19: 50.62 | E19: 51.07 | F19: 50.22 | G19: 50.03 | H19: 49.25 | I19: 48.48 | J19: 48.22 | K19: 47.58 | L19: 47.39204 | M19: 47.57 | N19: 47.25 | O19: 47.2 | P19: 52.01
A20: Monthly Revenue USD | B20: 745050 | C20: 794773 | D20: 970779 | E20: 835694 | F20: 985554 | G20: 814277 | H20: 816611 | I20: 808339 | J20: 791822.05 | K20: 788082.44 | L20: 776560.51 | M20: 773913.75 | N20: ='PL - Consolidated'!C5 -> 759509.94 | O20: ='PL - Consolidated'!D5 -> 761899.95 | P20: ='PL - Consolidated'!E5 -> 646844.04
A21: Yield | B21: 0.068170984 | C21: 0.070021767 | D21: 0.080800689 | E21: 0.065527369 | F21: 0.069721092 | G21: 0.055407403 | H21: 0.057676297 | I21: 0.058125827 | J21: 0.058045286 | K21: 0.058835415 | L21: 0.059600955 | M21: 0.061870644 | N21: =N20/AVERAGE(BS!B5:C5) -> 0.062241613 | O21: =O20/AVERAGE(BS!C5:D5) -> 0.062944193 | P21: =P20/AVERAGE(BS!D5:E5) -> 0.058032808
A22: Monthly Credit Revenue | B22: 691975 | C22: 736166 | D22: 870916 | E22: 779896 | F22: 897696 | G22: 789359 | H22: 784734 | I22: 773040 | J22: 760350.15 | K22: 756243.61 | L22: 743422.73 | M22: 727680.51 | N22: 724327.09 | O22: 715425.42 | P22: 620759.21
A23: Monthly Non-Credit Revenue | B23: 53075 | C23: 58607 | D23: 99863 | E23: 55799 | F23: 87858 | G23: 24919 | H23: 31877 | I23: 34070 | J23: 29156.65 | K23: 31838.83 | L23: 33137.78 | M23: 46233.24 | N23: =N20-N22 -> 35182.85 | O23: =O20-O22 -> 46474.53 | P23: 26084.81
A24: ARR USD | B24: =B20*12 -> 8940600 | C24: =C20*12 -> 9537276 | D24: =D20*12 -> 11649348 | E24: =E20*12 -> 10028328 | F24: =F20*12 -> 11826648 | G24: =G20*12 -> 9771324 | H24: =H20*12 -> 9799332 | I24: =I20*12 -> 9700068 | ... P24: =P20*12 -> 7762128.5
A25: Operating Profit | B25: -377388.13 | C25: -223886.37 | D25: -178402.62 | E25: -195184.86 | F25: -286199.22 | G25: -175204.64 | H25: -288182.98 | I25: -308458.22 | J25: -285954.11 | K25: -372683.22 | L25: -433063.2 | M25: -261404.93 | N25: ='PL - Consolidated'!C39 -> -360974.62 | O25: ='PL - Consolidated'!D39 -> -261553.73 | P25: ='PL - Consolidated'!E39 -> -361897.67
A26: Team
A27: Full Time Employees (#) | B27: 345 | C27: 345 | D27: 348 | E27: 354 | F27: 353 | G27: 355 | H27: 361 | I27: 359 | J27: 375 | K27: 377 | L27: 381 | M27: 386 | N27: 383 | O27: 376 | P27: =368+1+4 -> 373
A28: Full time Employees (Female) | B28: 142 | C28: 141 | D28: 142 | E28: 141 | F28: 140 | G28: 138 | H28: 143 | I28: 140 | J28: 141 | K28: 144 | L28: 152 | M28: 152 | N28: 149 | O28: 146 | P28: =P27-224-5 -> 144
A29: Full time Employees (Female Managers) | B29: 17 | C29: 18 | D29: 18 | E29: 18 | F29: 18 | G29: 20 | H29: 18 | I29: 20 | J29: 19 | K29: 19 | L29: 25 | M29: 25 | N29: 25 | O29: 25 | P29: 25
A30: Full time Employees (Minority/Previously Excluded) | B30: 17 | C30: 14 | D30: 14 | E30: 14 | F30: 14 | G30: 16 | H30: 17 | I30: 19 | J30: 18 | K30: 19 | L30: 17 | M30: 18 | N30: 17 | O30: 15 | P30: 16
A31: Full time Employees (Minority/Previously Excluded Senior Managers) | B31: 2 | C31: 2 | D31: 2 | E31: 2 | F31: 2 | G31: 4 | H31: 4 | I31: 4 | J31: 4 | K31: 4 | L31: 4 | M31: 4 | N31: 4 | O31: 4 | P31: 4
A32: Board of Directors (Female) | B32: 1 | C32: 1 | D32: 1 | E32: 1 | F32: 1 | G32: 1 | H32: 1 | I32: 1 | J32: 1 | K32: 1 | L32: 1 | M32: 1 | N32: 1 | O32: 1 | P32: 1
A33: Board of Directors (Minority/Previously Excluded) | B33: 0 | C33: 0 | D33: 0 | E33: 0 | F33: 0 | G33: 0 | H33: 0 | I33: 0 | J33: 0 | K33: 0 | L33: 0 | M33: 0 | N33: 0 | O33: 0 | P33: 0

Sheet PL - Consolidated
A1: Account | B1: FY2025 | C1: 46053 | D1: 46081 | E1: 46112
A2: Corporate Revenue | B2: 9311479 | C2: 724718.43 | D2: 746541 | E2: 621111.32
A3: Merchant Rebate Revenue | B3: 183219.21 | C3: 683.41 | D3: 669.08 | E3: 137.08
A4: Card Revenue | B4: 406757.54 | C4: 34108.1 | D4: 14689.87 | E4: 25595.64
A5: Gross Revenues | B5: =SUM(B2:B4) -> 9901455.8 | C5: =SUM(C2:C4) -> 759509.94 | D5: =SUM(D2:D4) -> 761899.95 | E5: =SUM(E2:E4) -> 646844.04
A6: VAT | B6: -1091360.6 | C6: -86646.148 | D6: -85913.016 | E6: -80771
A7: Discount | B7: -1765196 | C7: -124095 | D7: -116404 | E7: -77213.818
A8: Net Revenue | B8: =SUM(B5:B7) -> 7044899.1 | C8: =SUM(C5:C7) -> 548768.79 | D8: =SUM(D5:D7) -> 559582.93 | E8: =SUM(E5:E7) -> 488859.22
A9: Interest Expense | B9: -1585753.9 | C9: -145819.98 | D9: -113162.94 | E9: -101629.74
A10: Bad Debt Expenses (Provision) | B10: -81460.892 | C10: -17526.938 | D10: -9743.23 | E10: -14413.846
A11: Total Cost of Goods Sold | B11: =SUM(B9:B10) -> -1667214.8 | C11: =SUM(C9:C10) -> -163346.92 | D11: =SUM(D9:D10) -> -122906.17 | E11: =SUM(E9:E10) -> -116043.59
A12: Gross Margin | B12: =B8+B11 -> 5377684.3 | C12: =C8+C11 -> 385421.87 | D12: =D8+D11 -> 436676.76 | E12: =E8+E11 -> 372815.63
A13: % of Gross Margin | B13: =B12/B5 -> 0.54312057 | C13: =C12/C5 -> 0.50746126 | D13: =D12/D5 -> 0.57314187 | E13: =E12/E5 -> 0.57636093
A14: Operating Expenses
A15: Salaries | B15: -5687573.7 | C15: -525229.67 | D15: -475082.17 | E15: -520969.08
A16: Advertising | B16: -29061.217 | C16: -519.0065 | D16: -517.93 | E16: -430.88978
A17: Web Hosting | B17: -262466.72 | C17: -26769.107 | D17: -25987.05 | E17: -24896.551
A18: CAC | B18: -2941.2566 | C18: -111.91319 | D18: -315.64 | E18: -69.335937
A19: Card Expenses | B19: -579424.47 | C19: -52848.73 | D19: -59934.21 | E19: -47611.761
A20: SMS Expense | B20: -48704.537 | C20: -1485.1659 | D20: -2973.58 | E20: -1367.5631
A21: Tech Expense | B21: -152934.17 | C21: -16318.67 | D21: -21529.16 | E21: -23439.505
A22: Dues and subscriptions | B22: -182598.66 | C22: -15279.255 | D22: -15573.42 | E22: -14259.604
A23: Commissions and Fees | B23: -177117.01 | C23: -3810.5403 | D23: -7343.77 | E23: -2655.1765
A24: Medical Insurance | B24: -143130.53 | C24: -12921.399 | D24: -12932.22 | E24: -10981.342
A25: Customer Service Expenses | B25: -167253.78 | C25: -14389.127 | D25: -14459.54 | E25: -8894.5997
A26: Miscellaneous | B26: -20218.743 | C26: -3646.8215 | D26: -3641.5093 | E26: -4928.7274
... A37: Hot line Expense | B37: -5620.8515 | C37: -996.7793 | D37: -245.81312 | E37: -219.50612
A38: Total Operating Expenses | B38: =(SUM(B15:B37)) -> -8763696.8 | C38: =(SUM(C15:C37)) -> -746396.49 | D38: =(SUM(D15:D37)) -> -698230.5 | E38: =(SUM(E15:E37)) -> -734713.3
A39: Operating Profit | B39: =B12+B38 -> -3386012.5 | C39: =C12+C38 -> -360974.62 | D39: =D12+D38 -> -261553.73 | E39: =E12+E38 -> -361897.67
A40: Other Expenses & Revenues | B40: =B39/B5 -> -0.34197118 | C40: =C39/C5 -> -0.47527307 | D40: =D39/D5 -> -0.34329144 | E40: =E39/E5 -> -0.55948211
A41: Other Expenses
A42: Depreciation & Amortization | B42: -57024.994 | C42: -7407.9306 | D42: -7405.0994 | E42: -6865.9249
A43: FX Loss | B43: 553466.61 | C43: 141802.71 | D43: -185573.07 | E43: -1074972.5
A44: Other Loss | B44: -916582.05 | C44: 0 | D44: 0 | E44: -98978.76
A45: Revenue Stamp Tax Expenses | B45: -17304.548 | C45: -1286.4819 | D45: -1411.3941 | E45: -1162.4024
A46: Total Other Expenses | B46: =SUM(B42:B45) -> -437444.99 | C46: =SUM(C42:C45) -> 133108.29 | D46: =SUM(D42:D45) -> -194389.56 | E46: =SUM(E42:E45) -> -1181979.6
A47: Other Revenues
A48: Interest on Deposit | B48: 110140.29 | C48: 6477.3017 | D48: 5331.7954 | E48: 4156.1753
A49: Recovery of Bad debts | B49: 31876.977 | C49: 1091.6192 | D49: 196.40134 | E49: 1136.6594
A50: Other Gain | B50: 367988.11 | C50: 211.63613 | D50: 211.86768 | E50: 576.83808
...

Sheet BS
A1: ASSETS | B1: =EOMONTH(C1,-1) -> 46022 | C1: ='PL - Consolidated'!C1 -> 46053 | D1: ='PL - Consolidated'!D1 -> 46081 | E1: ='PL - Consolidated'!E1 -> 46112
A2: Current Assets
A3: Cash | B3: 4671257.8 | C3: 4537433.9 | D3: 4091707.1 | E3: 4957634.9
A4: Time Deposits | B4: 1000000 | C4: 0 | D4: 0
A5: Accounts Receivable | B5: 12199561 | C5: 12205653 | D5: 12003091 | E5: 10289266
A6: Goodwill | B6: 577598.76 | C6: 586905.04 | D6: 574529.74 | E6: 504351.19
A7: Customer Lists | B7: 23707.542 | C7: 24089.519 | D7: 23581.574 | E7: 20701.096
A8: Human Capital | B8: 15516.391 | C8: 15766.392 | D8: 15433.946 | E8: 13548.697
A9: License | B9: 339947.33 | C9: 345424.56 | D9: 338141.04 | E9: 296837.27
A10: Financial Assets | B10: 303506.12 | C10: 305505.47 | D10: 279735.39 | E10: 247831.81
A11: Prepaid Expenses | B11: 193112.52 | C11: 192694.16 | D11: 143786.21 | E11: 307049.68
A12: Accrued Revenue | B12: 364177.37 | C12: 386146.85 | D12: 392089.84 | E12: 360745.43
A13: Taxes (Assets) | B13: 51447.275 | C13: 82310.231 | D13: 83161.573 | E13: 97391.361
A14: Other Debtors | B14: 970062.17 | C14: 1000554.3 | D14: 1010360.1 | E14: 983501.98
A15: Total Current Assets | B15: =SUM(B3:B14) -> 20709894 | C15: =SUM(C3:C14) -> 19682484 | D15: =SUM(D3:D14) -> 18955618 | E15: =SUM(E3:E14) -> 18078859
A17: Fixed Assets
A18: Laptops | B18: 242740.52 | C18: 246568.04 | D18: 242312.67 | E18: 213450.56
A19: Machinery & Equipment | B19: 15567.279 | C19: 15779.278 | D19: 15497.37 | E19: 13898.794
A20: Mobile | B20: 10126.686 | C20: 10289.858 | D20: 10072.878 | E20: 8842.4808
A21: Office Furniture | B21: 57104.162 | C21: 57826.185 | D21: 56866.069 | E21: 51421.67
A22: Leasehold Improvements | B22: 40577.789 | C22: 40852.434 | D22: 40487.222 | E22: 38416.262
A23: Total Fixed Assets | B23: =SUM(B18:B22) -> 366116.44 | C23: =SUM(C18:C22) -> 371315.79 | D23: =SUM(D18:D22) -> 365236.22 | E23: =SUM(E18:E22) -> 326029.76
A24: (Less Accumulated Depreciation) | B24: 192910.95 | C24: 200235.63 | D24: 193467.97 | E24: 181468.06
A25: Net Fixed Assets | B25: =B23-B24 -> 173205.48 | C25: =C23-C24 -> 171080.16 | D25: =D23-D24 -> 171768.25 | E25: =E23-E24 -> 144561.7
A26: Intangible Assets
A27: Software | B27: 199358.16 | C27: 202570.24 | D27: 198298.88 | E27: 174076.76
A28: Software Under Development | B28: 69237.288 | C28: 232812.29 | D28: 231328.78 | E28: 240434.87
A29: (Less Accumulated Amortization) | B29: 85516.13 | C29: 89979.164 | D29: 91101.999 | E29: 82625.149
A30: Net Intangible Assets | B30: =B27+B28-B29 -> 183079.31 | C30: =C27+C28-C29 -> 345403.36 | D30: =D27+D28-D29 -> 338525.66 | E30: =E27+E28-E29 -> 331886.49
A31: ROU
A32: ROU | B32: 448040.66 | C32: 453668.2 | D32: 446184.93 | E32: 403750.57
A33: (Less Accumulated Amortization) | B33: 170219.76 | C33: 182595.54 | D33: 189259.04 | E33: 179362.58
A34: Net ROU | B34: =B32-B33 -> 277820.9 | C34: =C32-C33 -> 271072.66 | D34: =D32-D33 -> 256925.89 | E34: =E32-E33 -> 224387.99
A35: Total Non-Current Assets | B35: =B34+B30+B25 -> 634105.7 | C35: =C34+C30+C25 -> 787556.18 | D35: =D34+D30+D25 -> 767219.8 | E35: =E34+E30+E25 -> 700836.18
A36: Total Assets | B36: =B35+B15 -> 21344000 | C36: =C35+C15 -> 20470040 | D36: =D35+D15 -> 19722837 | E36: =E35+E15 -> 18779695
A38: LIABILITIES & EQUITY
A39: Current Liabilities
A40: Accounts Payable | B40: 437573.99 | C40: 582693 | D40: 438298.13 | E40: 551636.58
A41: Taxes | B41: 2260204 | C41: 2352033.7 | D41: 2459434.4 | E41: 2187735.7
A42: Accrued Expenses | B42: 264893.74 | C42: 112650.51 | D42: 128689.28 | E42: 138934.46
...

Sheet CFS
A1: CASH FLOW STATEMENT | B1: =BS!C1 -> 46053 | C1: =BS!D1 -> 46081 | D1: =BS!E1 -> 46112
A2: Net Profit/Loss | B2: ='PL - Consolidated'!C55 -> -220085.77 | C2: ='PL - Consolidated'!D55 -> -450203.23 | D2: ='PL - Consolidated'!E55 -> -1538007.6
A3: Depreciation | B3: =-'PL - Consolidated'!C42 -> 7407.9306 | C3: =-'PL - Consolidated'!D42 -> 7405.0994 | D3: =-'PL - Consolidated'!E42 -> 6865.9249
A4: Amortization | B4: =-'PL - Consolidated'!C28 -> 9988.955 | C4: =-'PL - Consolidated'!D28 -> 9995.3803 | D4: =-'PL - Consolidated'!E28 -> 9451.8276
A5: Bad Debt Expense | B5: =-'PL - Consolidated'!C10 -> 17526.938 | C5: =-'PL - Consolidated'!D10 -> 9743.23 | D5: =-'PL - Consolidated'!E10 -> 14413.846
A6: Unrealized Loss/Gain | B6: =-'PL - Consolidated'!C43 -> -141802.71 | C6: =-'PL - Consolidated'!D43 -> 185573.07 | D6: =-'PL - Consolidated'!E43 -> 1074972.5
A8: CFO
A9: Accounts Receivable | B9: =-(BS!C5-BS!B5) -> -6092.6504 | C9: =-(BS!D5-BS!C5) -> 202562.18 | D9: =-(BS!E5-BS!D5) -> 1713825.4
A10: Goodwill | B10: =-(BS!C6-BS!B6) -> -9306.2797 | C10: =-(BS!D6-BS!C6) -> 12375.302 | D10: =-(BS!E6-BS!D6) -> 70178.552
A11: List of customer | B11: =-(BS!C7-BS!B7) -> -381.97627 | C11: =-(BS!D7-BS!C7) -> 507.94432 | D11: =-(BS!E7-BS!D7) -> 2880.4788
A12: Captial Human | B12: =-(BS!C8-BS!B8) -> -250.00033 | C12: =-(BS!D8-BS!C8) -> 332.44538 | D12: =-(BS!E8-BS!D8) -> 1885.2497
A13: License | B13: =-(BS!C9-BS!B9) -> -5477.2363 | C13: =-(BS!D9-BS!C9) -> 7283.518 | D13: =-(BS!E9-BS!D9) -> 41303.778
A14: Financial Assets | B14: =-(BS!C10-BS!B10) -> -1999.3583 | C14: =-(BS!D10-BS!C10) -> 25770.082 | D14: =-(BS!E10-BS!D10) -> 31903.58
A15: Prepaid Expenses | B15: =-(BS!C11-BS!B11) -> 418.3591 | C15: =-(BS!D11-BS!C11) -> 48907.948 | D15: =-(BS!E11-BS!D11) -> -163263.48
A16: Accrued Revenue | B16: =-(BS!C12-BS!B12) -> -21969.481 | C16: =-(BS!D12-BS!C12) -> -5942.9889 | D16: =-(BS!E12-BS!D12) -> 31344.413
A17: Taxes (Assets) | B17: =-(BS!C13-BS!B13) -> -30862.956 | C17: =-(BS!D13-BS!C13) -> -851.34216 | D17: =-(BS!E13-BS!D13) -> -14229.787
A18: Other Debitors | B18: =-(BS!C14-BS!B14) -> -30492.115 | C18: =-(BS!D14-BS!C14) -> -9805.7893 | D18: =-(BS!E14-BS!D14) -> 26858.099
A19: Accounts Payable | B19: =BS!C40-BS!B40 -> 145119.01 | C19: =BS!D40-BS!C40 -> -144394.86 | D19: =BS!E40-BS!D40 -> 113338.45
A20: Taxes (Liability) | B20: =BS!C41-BS!B41 -> 91829.676 | C20: =BS!D41-BS!C41 -> 107400.71 | D20: =BS!E41-BS!D41 -> -271698.69
A21: Accrued Expenses | B21: =BS!C42-BS!B42 -> -152243.22 | C21: =BS!D42-BS!C42 -> 16038.762 | D21: =BS!E42-BS!D42 -> 10245.186
A22: CF Payables | B22: =BS!C43-BS!B43 -> 26478.595 | C22: =BS!D43-BS!C43 -> 11922.111 | D22: =BS!E43-BS!D43 -> -67808.446
A23: Other Current Liabilities | B23: =BS!C44-BS!B44 -> -357831.35 | C23: =BS!D44-BS!C44 -> 24525.151 | D23: =BS!E44-BS!D44 -> 19434.321
A24: Cash Flow from Operations | B24: =SUM(B2:B23) -> -680025.64 | C24: =SUM(C2:C23) -> 59144.718 | D24: =SUM(D2:D23) -> 1113893.6
A26: CFI
A27: Capex | B27: -5199.3548 | C27: 6079.58 | D27: 39206.453
A28: Software | B28: -166787.08 | C28: 5754.87 | D28: 15116.02
A29: Right of Use Assets | B29: -5627.5398 | C29: 7483.2639 | D29: 42434.363
A30: Cash Flow from Investing | B30: =SUM(B27:B29) -> -177613.97 | C30: =SUM(C27:C29) -> 19317.714 | D30: =SUM(D27:D29) -> 96756.837
A32: CFF
A33: Debt | B33: =BS!C47-BS!B47 -> -474735.16 | C33: =BS!D47-BS!C47 -> -200200 | D33: =BS!E47-BS!D47 -> 1195391.9
A34: Lease Liability | B34: =BS!C48-BS!B48 -> -16982.972 | C34: =BS!D48-BS!C48 -> -1098.5891 | D34: =BS!E48-BS!D48 -> -52156.285
A35: Paid-In Capital | B35: 0 | C35: 0 | D35: 0
A36: Cash Flow from Financing | B36: =SUM(B33:B35) -> -491718.13 | C36: =SUM(C33:C35) -> -201298.59 | D36: =SUM(D33:D35) -> 1143235.6
A38: Cash BoP | B38: =SUM(BS!B3:B4) -> 5671257.8 | C38: =SUM(BS!C3:C4) -> 4537433.9 | D38: =SUM(BS!D3:D4) -> 4091707.1
A39: Change in Cash | B39: =B24+B30+B36 -> -1349357.7 | C39: =C24+C30+C36 -> -122836.16 | D39: =D24+D30+D36 -> 2353886.1
A40: Adjustment for FX Translation | B40: 215533.83 | C40: -322890.59 | D40: -1487958.2
A41: Cash EoP | B41: =SUM(B38:B40) -> 4537433.9 | C41: =SUM(C38:C40) -> 4091707.1 | D41: =SUM(D38:D40) -> 4957634.9
A42: Check | B42: =ROUND(B41-BS!C3,5) -> 0 | C42: =ROUND(C41-BS!D3,5) -> 0 | D42: =ROUND(D41-BS!E3,5) -> 0

Sheet PL - Egypt Standalone
A1: Account | B1: FY2025 | C1: ='PL - Consolidated'!C1 -> 46053 | D1: ='PL - Consolidated'!D1 -> 46081 | E1: ='PL - Consolidated'!E1 -> 46112
A2: Corporate Revenue | B2: 9301394.8 | C2: 720862.19 | D2: 741958.55 | E2: 615347.66
A3: Merchant Rebate Revenue | B3: 183219.21 | C3: 683.41 | D3: 669.08 | E3: 137.08
A4: Card Revenue | B4: 406757.54 | C4: 34108.1 | D4: 14689.87 | E4: 25595.64
A5: Gross Revenues | B5: =SUM(B2:B4) -> 9891371.5 | C5: =SUM(C2:C4) -> 755653.7 | D5: =SUM(D2:D4) -> 757317.5 | E5: =SUM(E2:E4) -> 641080.38
A6: VAT | B6: -1091360.6 | C6: -86646.148 | D6: -85913.016 | E6: -80771
A7: Discount | B7: -1765196 | C7: -124095 | D7: -101422.86 | E7: -77213.818
A8: Net Revenue | B8: =SUM(B5:B7) -> 7034814.9 | C8: =SUM(C5:C7) -> 544912.55 | D8: =SUM(D5:D7) -> 569981.63 | E8: =SUM(E5:E7) -> 483095.56
A9: Interest Expense | B9: -1585753.9 | C9: -134322.59 | D9: -113162.94 | E9: -86648.599
A10: Bad Debt Expenses (Provision) | B10: -81460.892 | C10: -17526.938 | D10: -9743.23 | E10: -14413.846
A11: Total Cost of Goods Sold | B11: =SUM(B9:B10) -> -1667214.8 | C11: =SUM(C9:C10) -> -151849.53 | D11: =SUM(D9:D10) -> -122906.17 | E11: =SUM(E9:E10) -> -101062.44
A12: Gross Margin | B12: =B8+B11 -> 5367600.1 | C12: =C8+C11 -> 393063.03 | D12: =D8+D11 -> 447075.46 | E12: =E8+E11 -> 382033.12
A13: % of Gross Margin | B13: =B12/B5 -> 0.54265479 | C13: =C12/C5 -> 0.52016291 | D13: =D12/D5 -> 0.59034085 | E13: =E12/E5 -> 0.59592078
A14: Operating Expenses
A15: Salaries | B15: -4801652.5 | C15: -450982.95 | D15: -405193.62 | E15: -431321.95
A16: Advertising | B16: -29061.217 | C16: -519.0065 | D16: -517.93 | E16: -430.88978
A17: Web Hosting | B17: -238713.4 | C17: -21459.875 | D17: -20151.4 | E17: -19719.446
A18: CAC | B18: -2941.2566 | C18: -111.91319 | D18: -315.64 | E18: -69.335937
A19: Card Expenses | B19: -579424.47 | C19: -52848.73 | D19: -59934.21 | E19: -47611.761
A20: SMS Expense | B20: -48704.537 | C20: -1485.1659 | D20: -2973.58 | E20: -1367.5631
A21: Tech Expense | B21: -152934.17 | C21: -16318.67 | D21: -21529.16 | E21: -19062.821
A22: Dues and subscriptions | B22: -182598.66 | C22: -15279.255 | D22: -15224.507 | E22: -13910.691
A23: Commissions and Fees | B23: -133606.09 | C23: -3810.5403 | D23: -7040.3792 | E23: -2188.7598
A24: Medical Insurance | B24: -114953.66 | C24: -9892.9345 | D24: -9903.756 | E24: -7816.2535
A25: Customer Service Expenses | B25: -167253.78 | C25: -14389.127 | D25: -12593.34 | E25: -8894.5997
A26: Miscellaneous | B26: -20218.743 | C26: -3646.8215 | D26: -3641.5093 | E26: -4928.7274
... A37: Hot line Expense | B37: -5620.8515 | C37: -996.7793 | D37: -245.81312 | E37: -219.50612
A38: Total Operating Expenses | B38: =(SUM(B15:B37)) -> -7648211.8 | C38: =(SUM(C15:C37)) -> -646598.79 | D38: =(SUM(D15:D37)) -> -611488.24 | E38: =(SUM(E15:E37)) -> -619052.07
A39: Operating Profit | B39: =B12+B38 -> -2280611.7 | C39: =C12+C38 -> -253535.76 | D39: =D12+D38 -> -164412.78 | E39: =E12+E38 -> -237018.95
A40: Other Expenses & Revenues | B40: =B39/B5 -> -0.23056577 | C40: =C39/C5 -> -0.33551845 | D40: =D39/D5 -> -0.21709888 | E40: =E39/E5 -> -0.36971799
A41: Other Expenses
A42: Depreciation & Amortization | B42: -43817.685 | C42: -6011.2718 | D42: -7405.0994 | E42: -5446.0908
A43: FX Loss | B43: 553474.73 | C43: 141802.71 | D43: -185573.07 | E43: -1074972.5
A44: Other Loss | B44: -916582.05 | C44: 0 | D44: 0 | E44: -98978.76
A45: Revenue Stamp Tax Expenses | B45: -17304.548 | C45: -1286.4819 | D45: -1411.3941 | E45: -1162.4024
A46: Total Other Expenses | B46: =SUM(B42:B45) -> -424229.55 | C46: =SUM(C42:C45) -> 134504.95 | D46: =SUM(D42:D45) -> -194389.56 | E46: =SUM(E42:E45) -> -1180559.8
A47: Other Revenues
A48: Interest on Deposit | B48: 110140.29 | C48: 6477.3017 | D48: 5331.7954 | E48: 4156.1753
A49: Recovery of Bad debts | B49: 31876.977 | C49: 1091.6192 | D49: 196.40134 | E49: 1136.6594
A50: Other Gain | B50: 367988.11 | C50: 211.63613 | D50: 211.86768 | E50: 576.83808
...
