Workbook
Name _1_0REPLA: [2]PXMODEL!#REF!
Name _1_0REPLA: #REF!
Name _2_0pric: [3]Sheet1!#REF!
Name _2_0pric: #REF!
Name _3_0TAB: [2]PXMODEL!#REF!
Name _3_0TAB: #REF!
Name _4_0TAB: [2]PXMODEL!#REF!
Name _4_0TAB: #REF!
Name _5_0TAB: [2]PXMODEL!#REF!
Name _5_0TAB: #REF!
Name _Table1_In1: #REF!
Name _Table1_Out: #REF!
Name AllData: [5]Data!$F$5:$BS$240
Name AllData: #REF!
Name asda: #REF!
Name Asia_Pipeline_Biolight: '[7]GP - Pipeline'!$J$8:$J$127
Name Asia_Pipeline_Biolight: #REF!
Name Asia_Pipeline_Eco: '[7]GP - Pipeline'!$E$8:$E$127
Name Asia_Pipeline_Eco: #REF!
Name Asia_Pipeline_Eco_mini: '[7]GP - Pipeline'!$M$135:$M$254
Name Asia_Pipeline_Eco_mini: #REF!
Name Asia_Pipeline_Est_Ship_Quarter: '[7]GP - Pipeline'!$O$8:$O$127
Name Asia_Pipeline_Est_Ship_Quarter: #REF!
Name Asia_Pipeline_Home_System_10W: '[7]GP - Pipeline'!$L$8:$L$127
Name Asia_Pipeline_Home_System_10W: #REF!
Name Asia_Pipeline_Home_System_5w: '[7]GP - Pipeline'!$K$8:$K$127
Name Asia_Pipeline_Home_System_5w: #REF!
Name Asia_Pipeline_Mobile: '[7]GP - Pipeline'!$I$8:$I$127
Name Asia_Pipeline_Mobile: #REF!
Name Asia_Pipeline_Pro: '[7]GP - Pipeline'!$G$8:$G$127
Name Asia_Pipeline_Pro: #REF!
Name Asia_Pipeline_Pro2: '[7]GP - Pipeline'!$H$8:$H$127
Name Asia_Pipeline_Pro2: #REF!
Name Asia_Pipeline_Solo: '[7]GP - Pipeline'!$F$8:$F$127
Name Asia_Pipeline_Solo: #REF!
Name astq: #REF!
Name astq: #REF!
Name bal: #REF!
Name bal: #REF!
Name balstr: #REF!
Name balstr: #REF!
Name BLPH1: #REF!
Name BLPH2: #REF!
Name BLPH3: #REF!
Name brneng: #REF!
Name brneng: #REF!
Name brneng2: #REF!
Name brneng2: #REF!
Name brneng3: #REF!
Name brneng3: #REF!
Name brnfrn: #REF!
Name brnfrn: #REF!
Name brnspn: #REF!
Name brnspn: #REF!
Name dat: #REF!
Name dat: #REF!
Name dateng: [5]Data!#REF!
Name dateng: #REF!
Name dateng1: [5]Data!#REF!
Name dateng1: #REF!

Sheet KPI's
B2: Key Performance Indicators
D4: Q4 | E4: Q3 | F4: Q2 | G4: Q1 | H4: Q4 | I4: Q3 | J4: Q2 | K4: Q1 | L4: Q4 | M4: Q3 | N4: Q2 | O4: Q1 | P4: Q4
D5: December 2025 | E5: September 2025 | F5: June 2025 | G5: March 2025 | H5: December 2024 | I5: September 2024 | J5: June 2024 | K5: March 2024 | L5: December 2023 | M5: September 2023 | N5: June 2023 | O5: March 2023 | P5: December 2022
B6: 1. | C6: Financial Metrics
B7: 1.1 | C7: Credit Revenue | D7: =SUM('P&L -Dec25'!DP10:DR12) -> 1.8414588e+08 | E7: 1.8062808e+08 | F7: 188579765 | G7: 1.9233536e+08 | H7: 2.0778243e+08 | I7: 2.039527e+08 | J7: 1.8187705e+08 | K7: 1.6141535e+08 | L7: 1.3756157e+08 | M7: 1.1350807e+08 | N7: 95112059 | O7: 81434822 | P7: 72661909
B8: 1.2 | C8: EBITDA | D8: =SUM('P&L -Dec25'!DP193:DR193) -> 1875504.4 | E8: 667728.6 | F8: 1607086.7 | G8: -6027694.8 | H8: -2239794.4 | I8: 7230381.3 | J8: 3398808.1 | K8: 15765215 | L8: 11078509 | M8: 4787161 | N8: 7546615.8 | O8: 2877871.6 | P8: 670856.47
B9: 2. | C9: Operational Metrics
B10: 2.1 | C10: Loans Disbursed (number) | D10: =SUM('Advance Analysis - Dec25'!H129:H131) -> 4732 | E10: 4634 | F10: 4637 | G10: 4960 | H10: 6041 | I10: 5967 | J10: 5847 | K10: 5806 | L10: 4903 | M10: 4079 | N10: 3319 | O10: 2831 | P10: 2451
B11: 2.2 | C11: Loans Financed (value) | D11: =SUM('Advance Analysis - Dec25'!C129:C131) -> 7.7965187e+08 | E11: 7.1808045e+08 | F11: 682236875 | G11: 694787927 | H11: 877464420 | I11: 9.0962379e+08 | J11: 891190309 | K11: 965864749 | L11: 874151968 | M11: 7.1614809e+08 | N11: 565912078 | O11: 5.2008684e+08 | P11: 408919831
B12: 2.3 | C12: Average Loan Size Disbursed | D12: =D11/D10 -> 164761.6 | E12: 154959.1 | F12: 147128.94 | G12: 140078.21 | H12: 145251.52 | I12: 152442.4 | J12: 152418.39 | K12: 166356.31 | L12: 178289.2 | M12: 175569.52 | N12: 170506.8 | O12: 183711.35 | P12: 166837.96
B13: 2.4 | C13: Net Loan Portfolio | D13: ='Notes - Dec25'!C8 -> 1.5068569e+09 | E13: 1.5291501e+09 | F13: 1.6068918e+09 | G13: 1.6977565e+09 | H13: 1806577762 | I13: 1825326392 | J13: 1.7082092e+09 | K13: 1.588821e+09 | L13: 1.3099124e+09 | M13: 1.0865726e+09 | N13: 9.0562427e+08 | O13: 7.6787109e+08 | P13: 6.4040303e+08
B14: 2.5 | C14: Charge offs:
B15: 2.5.1 | C15: -Per Quarter | D15: ='Notes - Dec25'!C5-'Notes - Dec25'!I5 -> -80270700 | E15: -48307722 | F15: -1.1465888e+08 | G15: -24489772 | H15: -19085600 | I15: -27153340 | J15: -23730180 | K15: -26910923 | L15: -16763889 | M15: -14493891 | N15: -9124086 | O15: -12700787 | P15: -6666991
B16: 2.5.2 | C16: -YTD (December 2025) | D16: -251569961 | E16: -171299261 | F16: -120682891 | G16: -6024016 | H16: -77417697 | I16: -58332097 | J16: -31178757 | K16: -7448576.7 | L16: -42875697 | M16: -26111808 | N16: -11617917 | O16: -2493831 | P16: -19102882
B17: 2.5.3 | C17: -Since inception | D17: -4.7614752e+08 | E17: -3.9587682e+08 | F17: -3.4526045e+08 | G17: -2.3060158e+08 | H17: -206111803 | I17: -1.870262e+08 | J17: -1.5987286e+08 | K17: -1.3614268e+08 | L17: -1.0923176e+08 | M17: -92467871 | N17: -77973980 | O17: -68849894 | P17: -56149107
B18: 2.6 | C18: Average Annualized Interest Rate | D18: =AVERAGE('Advance Analysis - Dec25'!G129:G131) -> 0.40932423 | E18: 0.39655377 | F18: 0.41968004 | G18: 0.39253481 | H18: 0.4120476 | I18: 0.4253749 | J18: 0.41325824 | K18: 0.42848331 | L18: 0.44249042 | M18: 0.44428702 | N18: 0.44507762 | O18: 0.45498687 | P18: 0.46200035
B19: 2.7 | C19: Par 30 + Restructured loans | D19: ='Balance Sheet - Dec25'!C53 -> 0.078022146 | E19: 0.080367317 | F19: 0.086420848 | G19: 0.11733451 | H19: 0.09013019 | I19: 0.069128131 | J19: 0.056762139 | K19: 0.044721985 | L19: 0.042817934 | M19: 0.040916738 | N19: 0.042591592 | O19: 0.044835966 | P19: 0.050030707
B20: 2.8 | C20: Par 90 | D20: ='Covenants - Dec25'!G47/'Covenants - Dec25'!G54 -> 0.053955519 | E20: 0.053493269 | F20: 0.051156311 | G20: 0.085042421 | H20: 0.06119064 | I20: 0.038681647 | J20: 0.027314633 | K20: 0.021083442 | L20: 0.021114483 | M20: 0.022365324 | N20: 0.026563286 | O20: 0.020694972 | P20: 0.025214518
B21: 3. | C21: Impact Metrics
B22: 3.1 | C22: Total businesses funded - Unique Q3 - '25 | D22: =SUM('Advance Analysis - Dec25'!I129:I131) -> 1200 | E22: 1050 | F22: 984 | G22: 1087 | H22: 1598 | I22: 1688 | J22: 1624 | K22: 1699 | L22: 1699 | M22: 1685 | N22: 1289 | O22: 1039 | P22: 1052
B23: 3.1.1 | C23: -Total active clients | D23: ='Advance Analysis - Dec25'!K131 -> 9920 | E23: 10294 | F23: 10597 | G23: 12288 | H23: 11182 | I23: 10455 | J23: 9558 | K23: 9415 | L23: 7737 | M23: 7075 | N23: 5934 | O23: 5356 | P23: 4730
B24: 3.2 | C24: Number of SMEs - Unique to date | D24: ='Advance Analysis - Dec25'!I132 -> 24921 | E24: 23721 | F24: 22671 | G24: 21687 | H24: 20600 | I24: 19002 | J24: 17314 | K24: 15690 | L24: 13991 | M24: 12292 | N24: 10607 | O24: 9318 | P24: 8279
B25: 3.3 | C25: Fulltime employees (in Lulalend) | D25: 242 | E25: 244 | F25: 241 | G25: 236 | H25: 235 | I25: 224 | J25: 202 | K25: 177 | L25: 168 | M25: 151 | N25: 129 | O25: 119 | P25: 118
B26: 3.4 | C26: of which # of female employees | D26: 116 | E26: 118 | F26: 110 | G26: 112 | H26: 111 | I26: 107 | J26: 102 | K26: 88 | L26: 80 | M26: 75 | N26: 63 | O26: 58 | P26: 59
B27: 3.5 | C27: Countries in operation | D27: 1 | E27: 1 | F27: 1 | G27: 1 | H27: 1 | I27: 1 | J27: 1 | K27: 1 | L27: 1 | M27: 1 | N27: 1 | O27: 1 | P27: 1

Sheet P&L -Dec25
A1: Profit & Loss | T1: Profit & Loss
A2: Lula Lend (Pty) Ltd | T2: Lula Lend (Pty) Ltd
A3: For the month ended 31 December 2025 | T3: For the month ended 28 February 2019
B5: YTD - Feb 16 | C5: Dec-16 | D5: Jan-17 | E5: Feb-17 | F5: YTD - Feb 17 | G5: Mar-17 | H5: Apr-17 | I5: May-17 | J5: June-17 | K5: July-17 | L5: Aug-17 | M5: Sept-17 | N5: Oct-17 | O5: Nov-17 | P5: Dec-17 | Q5: Jan-18 | R5: Feb-18 | S5: YTD - Feb 18 | T5: Mar-18 | U5: Apr-18 | V5: May-18 | W5: Jun-18 | X5: Jul-18 | Y5: Aug-18 | Z5: Sep-18 | AA5: Oct-18 | AB5: Nov-18 | AC5: Dec-18 | AD5: Jan-19 | AE5: Feb-19 | AF5: YTD - Feb 19 | AG5: Mar-19 | AH5: Apr-19 | AI5: May-19 | AJ5: Jun-19 | AK5: Jul-19 | AL5: Aug-19 | AM5: Sep-19 | AN5: Oct-19 | AO5: Nov-19 | AP5: Dec-19 | AQ5: Jan-20 | AR5: Feb-20 | AS5: YTD - Feb 20 | AT5: YE Journals | AU5: YTD - Feb 20 | AV5: Mar-20 | AW5: Apr-20 | AX5: May-20 | AY5: Jun-20 | AZ5: Jul-20 | BA5: Aug-20 | BB5: Sep-20 | BC5: Oct-20 | BD5: Nov-20 | BE5: Dec-20 | BF5: Jan-21 | BG5: Feb-21 | BH5: YTD - Feb 21 | BI5: Mar-21 | BJ5: Apr-21 | BK5: May-21 | BL5: Jun-21 | BM5: Jul-21 | BN5: Aug-21 | BO5: Sep-21 | BP5: Oct-21 | BQ5: Nov-21 | BR5: Dec-21 | BS5: Jan-22 | BT5: Feb-22 | BU5: YTD - Feb 22 | BV5: Mar-22 | BW5: Apr-22 | BX5: May-22 | BY5: Jun-22 | BZ5: Jul-22 | CA5: Aug-22 | CB5: Sep-22 | CC5: Oct-22 | CD5: Nov-22 | CE5: Dec-22 | CF5: Jan-23 | CG5: Feb-23 | CH5: YTD - Feb 23 | CI5: Mar-23 | CJ5: Apr-23 | CK5: May-23 | CL5: Jun-23 | CM5: Jul-23 | CN5: Aug-23 | CO5: Sep-23 | CP5: Oct-23 | CQ5: Nov-23 | CR5: Dec-23 | CS5: Jan-24 | CT5: Feb-24 | CU5: YTD - Feb 24 | CV5: Mar-24 | CW5: Apr-24 | CX5: May-24 | CY5: Jun-24 | CZ5: Jul-24 | DA5: Aug-24 | DB5: Sep-24 | DC5: Oct-24 | DD5: Nov-24 | DE5: Dec-24 | DF5: Jan-25 | DG5: Feb-25 | DH5: YTD - Feb 25 | DI5: Mar-25 | DJ5: Apr-25 | DK5: May-25 | DL5: Jun-25 | DM5: Jul-25 | DN5: Aug-25 | DO5: Sep-25 | DP5: Oct-25 | DQ5: Nov-25 | DR5: Dec-25 | DS5: Jan-26 | DT5: Feb-26 | DU5: YTD - Feb 26
A7: Income
A9: Total credit revenue
A10: Fee Income | B10: 1612107.5 | C10: 376479.18 | D10: 380118.85 | E10: 366150.87 | F10: 3994702 | G10: 503039 | H10: 497939.76 | I10: 518376.5 | J10: 616800.86 | K10: 683198.24 | L10: 818281.91 | M10: 845743.59 | N10: 802652.41 | O10: 857386.41 | P10: 1024526.4 | Q10: 1009094.9 | R10: 1035779.8 | S10: 9212819.9 | T10: 1309133.1 | U10: 1150151 | V10: 1253953.7 | W10: 1420249.1 | X10: 1475498.8 | Y10: 1777647.5 | Z10: 1743165.8 | AA10: 2056626.7 | AB10: 2327350.5 | AC10: 2617279 | AD10: 2646158 | AE10: 2949013.9 | AF10: 22726227 | AG10: 3421586.8 | AH10: 3454018.5 | AI10: 3472579 | AJ10: 3574012.1 | AK10: 4132800.6 | AL10: 4371043.4 | AM10: 4309601.7 | AN10: 4926256.8 | AO10: 5542864.8 | AP10: 6758421.6 | AQ10: 6942007.6 | AR10: 6729387.7 | AS10: 57634581 | AU10: 57634581 | AV10: 7590219.6 | AW10: 6319900.3 | AX10: 5290066.5 | AY10: 5848754.2 | AZ10: 6420536.7 | BA10: 6300848.2 | BB10: 6382928.9 | BC10: 7051063.7 | BD10: 7017252.1 | BE10: 7834691.7 | BF10: 7647493.5 | BG10: 7958422.9 | BH10: 81662178 | BI10: 9539930.6 | BJ10: 10195342 | BK10: 10553393 | BL10: 9931901 | BM10: 11752286 | BN10: =12143711.46+100000 -> 12243711 | BO10: 13476587 | BP10: 14804007 | BQ10: 14687672 | BR10: 15634881 | BS10: 17092559 | BT10: 16070903 | BU10: =SUM(BI10:BT10) -> 1.5598317e+08 | BV10: 19214302 | BW10: 17427762 | BX10: 18349718 | BY10: 19078922 | BZ10: 20717685 | CA10: 20747708 | CB10: 20074617 | CC10: 23489683 | CD10: 23054635 | CE10: 26117592 | CF10: 26162566 | CG10: 26314765 | CH10: =SUM(BV10:CG10) -> 2.6074995e+08 | CI10: 28957491 | CJ10: 28813278 | CK10: 32665912 | CL10: 33632869 | CM10: 36817300 | CN10: 37636512 | CO10: 39054254 | CP10: 43228923 | CQ10: 45193130 | CR10: 49139513 | CS10: 51746873 | CT10: 73149316 | CU10: =SUM(CI10:CT10) -> 5.0003537e+08 | CV10: 56078872 | CW10: 60749393 | CX10: 60040503 | CY10: 61087157 | CZ10: 67698354 | DA10: 68072377 | DB10: 68181972 | DC10: 66088564 | DD10: 70263806 | DE10: 71430062 | DF10: 64703646 | DG10: 28937022 | DH10: =SUM(CV10:DG10) -> 7.4333173e+08 | DI10: 67585759 | DJ10: 64064942 | DK10: 64447739 | DL10: 60067084 | DM10: 60007608 | DN10: 60524917 | DO10: 60098551 | DP10: 61925143 | DQ10: 56622421 | DR10: 65156273 | DU10: =SUM(DI10:DT10) -> 6.2050044e+08
A12: Total non-credit revenue | BZ12: =SUM(BZ13:BZ16) -> 69.56 | CA12: =SUM(CA13:CA16) -> 536.52 | CB12: =SUM(CB13:CB16) -> 906.97 | CC12: =SUM(CC13:CC16) -> 434.03 | CD12: =SUM(CD13:CD16) -> 1119 | CE12: =SUM(CE13:CE16) -> 1493.15 | CF12: =SUM(CF13:CF16) -> 1885.9 | CG12: =SUM(CG13:CG16) -> 5584.8 | ... CT12: =SUM(CT13:CT16) -> 63539.56 | CU12: =SUM(CI12:CT12) -> 616118.32 | CV12: =SUM(CV13:CV16) -> 105369.42 | CW12: =SUM(CW13:CW16) -> 74645.51 | CX12: =SUM(CX13:CX16) -> 91409.26 | CY12: =SUM(CY13:CY16) -> 89509.09 | CZ12: =SUM(CZ13:CZ16) -> 94073.53 | DA12: =SUM(DA13:DA16) -> 103920.73 | DB12: =SUM(DB13:DB16) -> 105585.35 | DC12: =SUM(DC13:DC16) -> 115719.57 | ... DG12: =SUM(DG13:DG16) -> 134436.15 | DH12: =SUM(CV12:DG12) -> 1285525.5 | DI12: =SUM(DI13:DI16) -> 198582.65 | DJ12: =SUM(DJ13:DJ16) -> 172253.48 | DK12: =SUM(DK13:DK16) -> 203976.26 | DL12: =SUM(DL13:DL16) -> 213038.06 | DM12: =SUM(DM13:DM16) -> 258775.85 | DN12: =SUM(DN13:DN16) -> 255560.01 | DO12: =SUM(DO13:DO16) -> 258897.04 | DP12: =SUM(DP13:DP16) -> 292689.97 | ... DT12: =SUM(DT13:DT16) -> 0 | DU12: =SUM(DI12:DT12) -> 2003126.7
A13: Subscription Revenue | CI13: 870 | CJ13: 1739 | CK13: 869.57 | CL13: 0.01 | CM13: 1739.13 | CN13: 1304.35 | CO13: 1304.35 | CP13: 1304.35 | CQ13: 2173.91 | CR13: 3043.48 | CS13: 3913.04 | CT13: 0 | CU13: =SUM(CI13:CT13) -> 18261.19 | CV13: 3478.26 | CW13: 4347.83 | CX13: 2608.7 | CY13: 6521.74 | CZ13: 5217.39 | DA13: 5652.17 | DB13: 5652.17 | DC13: 6086.96 | DD13: 7826.09 | DE13: 6521.74 | DF13: 7826.09 | DG13: 12608.7 | DH13: =SUM(CV13:DG13) -> 74347.84 | DI13: 17826.09 | DJ13: 20869.57 | DK13: 25652.17 | DL13: 37826.09 | DM13: 40869.57 | DN13: 42608.7 | DO13: 36521.74 | DP13: 40434.78 | DQ13: 55652.17 | DR13: 0 | DU13: =SUM(DI13:DT13) -> 318260.88
A14: Transaction Revenue | BZ14: 69.56 | CA14: 536.52 | CB14: 906.97 | CC14: 434.03 | CD14: 976.52 | CE14: 1326.98 | CF14: 1641.75 | CG14: 1578.61 | CH14: =SUM(BV14:CG14) -> 7470.94 | CI14: 898.69 | CJ14: 635.96 | CK14: 4435.32 | CL14: 6836.98 | CM14: 8926.09 | CN14: 9564.27 | CO14: 8440.11 | CP14: 8305.77 | CQ14: 11852.44 | CR14: 13236.59 | CS14: 13837.77 | CT14: 15874.22 | CU14: =SUM(CI14:CT14) -> 102844.21 | CV14: 10415.3 | CW14: 8378.28 | CX14: 25040.25 | CY14: 20814.29 | CZ14: 29856 | DA14: 28522.36 | DB14: 35713.75 | DC14: 33811.72 | DD14: 35012.36 | DE14: 39839.5 | DF14: 36024.12 | DG14: 41791.63 | DH14: =SUM(CV14:DG14) -> 345219.56 | DI14: 45332.57 | DJ14: 38881.38 | DK14: 56283.99 | DL14: 52846.44 | DM14: 51880.19 | DN14: 52795.31 | DO14: 59198.46 | DP14: 71298.91 | DQ14: 40487.15 | DR14: 0 | DU14: =SUM(DI14:DT14) -> 469004.4
A15: Interchange Revenue | CV15: 9827.49 | CW15: 14353.43 | CX15: 21706.18 | CY15: 19723.26 | CZ15: 19642.17 | DA15: 22854.31 | DB15: 25922.92 | DC15: 29936.25 | DD15: 31825.98 | DE15: 27573.78 | DF15: 22524.37 | DG15: 22248.08 | DH15: =SUM(CV15:DG15) -> 268138.22 | DI15: 33126.09 | DJ15: 24511.73 | DK15: 28501.73 | DL15: 28289.25 | DM15: 40168.1 | DN15: 36418.6 | DO15: 37338.99 | DP15: 65118.13 | DQ15: 32687.22 | DR15: 0 | DU15: =SUM(DI15:DT15) -> 326159.84
A16: Earned interest | BV16: 0 | BW16: 0 | BX16: 0 | BY16: 0 | BZ16: 0 | CA16: 0 | CB16: 0 | CC16: 0 | CD16: 142.48 | CE16: 166.17 | CF16: 244.15 | CG16: 4006.19 | CH16: =SUM(BV16:CG16) -> 4558.99 | CI16: 6600.42 | CJ16: 8953.13 | CK16: 6729.73 | CL16: 36721.44 | CM16: 49757.5 | CN16: 69495.45 | CO16: 59589.89 | CP16: 60807.24 | CQ16: 53460.95 | CR16: 51489.63 | CS16: 43742.2 | CT16: 47665.34 | CU16: =SUM(CI16:CT16) -> 495012.92 | CV16: 81648.37 | CW16: 47565.97 | CX16: 42054.13 | CY16: 42449.8 | CZ16: 39357.97 | DA16: 46891.89 | DB16: 38296.51 | DC16: 45884.64 | DD16: 36635.99 | DE16: 63304.89 | DF16: 55942 | DG16: 57787.74 | DH16: =SUM(CV16:DG16) -> 597819.9 | DI16: 102297.9 | DJ16: 87990.8 | DK16: 93538.37 | DL16: 94076.28 | DM16: 125857.99 | DN16: 123737.4 | DO16: 125837.85 | DP16: 115838.15 | DQ16: 20526.79 | DR16: 0 | DU16: =SUM(DI16:DT16) -> 889701.53
A18: Total Revenue | B18: =SUM(B10) -> 1612107.5 | C18: =SUM(C10) -> 376479.18 | D18: =SUM(D10) -> 380118.85 | E18: =SUM(E10) -> 366150.87 | F18: =SUM(F10) -> 3994702 | G18: =SUM(G10) -> 503039 | H18: =SUM(H10) -> 497939.76 | I18: =SUM(I10) -> 518376.5 | ... S18: =SUM(S10) -> 9212819.9 | T18: =T10 -> 1309133.1 | U18: 1150151 | V18: =+V10 -> 1253953.7 | W18: =+W10 -> 1420249.1 | X18: =+X10 -> 1475498.8 | Y18: =SUM(Y10) -> 1777647.5 | Z18: =SUM(Z10) -> 1743165.8 | AA18: =SUM(AA10) -> 2056626.7 | AB18: =SUM(AB10) -> 2327350.5 | AC18: =SUM(AC10) -> 2617279 | AD18: =SUM(AD10) -> 2646158 | AE18: =+AE10 -> 2949013.9 | AF18: 22726227 | AG18: 3421586.8 | AH18: 3454018.5 | AI18: 3472579 | AJ18: 3574012.1 | AK18: 4132800.6 | AL18: 4371043.4 | AM18: 4309601.7 | AN18: 4926256.8 | AO18: 5542864.8 | AP18: 6758421.6 | AQ18: 6942007.6 | AR18: 6729387.7 | AS18: 57634581 | AT18: 0 | AU18: 57634581 | AV18: 7590219.6 | AW18: 6319900.3 | AX18: 5290066.5 | AY18: 5848754.2 | AZ18: 6420536.7 | BA18: 6300848.2 | BB18: 6382928.9 | BC18: 7051063.7 | BD18: 7017252.1 | BE18: 7834691.7 | BF18: 7647493.5 | BG18: 7958422.9 | BH18: 81662178 | BI18: =+BI10 -> 9539930.6 | BJ18: =+BJ10 -> 10195342 | BK18: =+BK10 -> 10553393 | BL18: =+BL10 -> 9931901 | BM18: =+BM10 -> 11752286 | BN18: =+BN10 -> 12243711 | BO18: =+BO10 -> 13476587 | BP18: =+BP10 -> 14804007 | ... BT18: =+BT10 -> 16070903 | BU18: =BU10 -> 1.5598317e+08 | BV18: =+BV10+BV14 -> 19214302 | BW18: =+BW10+BW14 -> 17427762 | BX18: =+BX10+BX14 -> 18349718 | BY18: =+BY10+BY14 -> 19078922 | BZ18: =+BZ10+BZ14 -> 20717754 | CA18: =+CA10+CA14 -> 20748245 | CB18: =+CB10+CB14 -> 20075524 | CC18: =+CC10+CC14 -> 23490117 | CD18: =+CD10+CD14+CD16 -> 23055754 | CE18: =+CE10+CE14+CE16 -> 26119085 | CF18: =+CF10+CF14+CF16 -> 26164452 | CG18: =+CG10+CG14+CG16 -> 26320350 | CH18: =+CH10+CH14+CH16 -> 2.6076198e+08 | CI18: =CI10+CI12 -> 28965860 | CJ18: =CJ10+CJ12 -> 28824606 | CK18: =CK10+CK12 -> 32677947 | CL18: =CL10+CL12 -> 33676427 | CM18: =CM10+CM12 -> 36877722 | CN18: =CN10+CN12 -> 37716876 | CO18: =CO10+CO12 -> 39123589 | CP18: =CP10+CP12 -> 43299341 | ... CT18: =CT10+CT12 -> 73212856 | CU18: =SUM(CI18:CT18) -> 5.0065149e+08 | CV18: =CV10+CV12 -> 56184241 | CW18: =CW10+CW12 -> 60824039 | CX18: =CX10+CX12 -> 60131912 | CY18: =CY10+CY12 -> 61176666 | CZ18: =CZ10+CZ12 -> 67792428 | DA18: =DA10+DA12 -> 68176297 | DB18: =DB10+DB12 -> 68287557 | DC18: =DC10+DC12 -> 66204284 | ... DG18: =DG10+DG12 -> 29071458 | DH18: =SUM(CV18:DG18) -> 7.4461725e+08 | DI18: =DI10+DI12 -> 67784341 | DJ18: =DJ10+DJ12 -> 64237195 | DK18: =DK10+DK12 -> 64651716 | DL18: =DL10+DL12 -> 60280122 | DM18: =DM10+DM12 -> 60266384 | DN18: =DN10+DN12 -> 60780477 | DO18: =DO10+DO12 -> 60357448 | DP18: =DP10+DP12 -> 62217833 | ... DT18: =DT10+DT12 -> 0 | DU18: =SUM(DI18:DT18) -> 6.2250356e+08
A20: Lula Credit - cost of service
CR21: =(CR27-CQ27)/CQ27 -> 0.20414687
A23: Net Impairment and Provision on Advances | AF23: 0 | AS23: 0 | AU23: 0 | BH23: 0 | BU23: =AX23+AY23 -> 0 | CH23: =BK23+BL23 -> 0 | CU23: =AX23+AY23 -> 0 | DH23: =AZ23+BA23 -> 0
A24: Bad Debts Recovered | M24: -13283.32 | S24: -13283.32 | X24: -2000 | AF24: -2000 | AS24: 0 | AU24: 0 | BH24: 0 | BU24: =AX24+AY24 -> 0 | CH24: =BK24+BL24 -> 0 | CU24: =AX24+AY24 -> 0 | DH24: =AZ24+BA24 -> 0
A25: Default Advance Provision | B25: =155258.33+292400 -> 447658.33 | C25: 153445.65 | D25: 109675.82 | E25: =-678893.96+805220.97 -> 126327.01 | F25: =802881.94+805219.97 -> 1608101.9 | G25: 144889.46 | H25: 148380.47 | I25: 152114.61 | J25: 170205.57 | K25: =K27 -> 164711.88 | L25: 149999.75 | M25: 133307.94 | N25: 118941.39 | O25: 157201.49 | S25: 1339752.6 | X25: 63852.33 | AF25: 63852.33 | AS25: 0 | AU25: 0 | BH25: 0 | BU25: =AX25+AY25 -> 0 | CH25: =BK25+BL25 -> 0 | CU25: =AX25+AY25 -> 0 | DH25: =AZ25+BA25 -> 0
A26: Default Advances Written Off | C26: 0 | D26: 0 | G26: 0 | H26: 0 | I26: 0 | M26: 0 | N26: 13893.08 | S26: 13893.08 | X26: 0 | AF26: 0 | AS26: 0 | AU26: 0 | BH26: 0 | BU26: =AX26+AY26 -> 0 | CH26: =BK26+BL26 -> 0 | CU26: =AX26+AY26 -> 0 | DH26: =AZ26+BA26 -> 0
A27: Total debtors cost net recoveries (write-offs & provision movement) | B27: =SUM(B25:B26) -> 447658.33 | C27: =SUM(C25:C26) -> 153445.65 | D27: =SUM(D25:D26) -> 109675.82 | E27: =SUM(E25:E26) -> 126327.01 | F27: =SUM(F25:F26) -> 1608101.9 | G27: 144889.46 | H27: 148380.47 | I27: =SUM(I25) -> 152114.61 | J27: =SUM(J25) -> 170205.57 | K27: 164711.88 | L27: =SUM(L24:L26) -> 149999.75 | M27: =SUM(M24:M26) -> 120024.62 | N27: =SUM(N24:N26) -> 132834.47 | O27: =SUM(O24:O26) -> 157201.49 | P27: 219400.02 | Q27: 183902.08 | R27: 40602.42 | S27: 1784267 | T27: 56589.38 | U27: 69493 | V27: 122213.81 | W27: 47577.37 | X27: =SUM(X24:X26) -> 61852.33 | Y27: 184180.48 | Z27: 148020.35 | AA27: 149280.6 | AB27: 340215.34 | AC27: 302147.57 | AD27: 138348.65 | AE27: 361059.64 | AF27: 1980978.5 | AG27: 179876.68 | AH27: 106580.96 | AI27: 299597.62 | AJ27: 271085.5 | AK27: 308139.93 | AL27: 358637.46 | AM27: 491334.5 | AN27: 576970.53 | AO27: 615552.06 | AP27: 778503.51 | AQ27: 640191.21 | AR27: 676046.12 | AS27: 5302516.1 | AU27: 5302516.1 | AV27: 3551871.3 | AW27: 4240585.1 | AX27: 3335482.6 | AY27: 2195810 | AZ27: 1844635.4 | BA27: 391389.83 | BB27: 558275.99 | BC27: 400813.53 | BD27: 339820.6 | BE27: 932271.93 | BF27: 1013947.4 | BG27: 1025001.2 | BH27: 19829905 | BI27: 970793.34 | BJ27: 1046312.3 | BK27: 1219502.8 | BL27: 771882.63 | BM27: 1186052.8 | BN27: 2003127.2 | BO27: 1855119.1 | BP27: 2823572.9 | BQ27: 2766723 | BR27: 2617642.3 | BS27: 3839489.1 | BT27: 4885294.1 | BU27: =SUM(BI27:BT27) -> 25985512 | BV27: 3939284 | BW27: 2858473.5 | BX27: =2231829-183003 -> 2048826 | BY27: 1913351.3 | BZ27: 3548713 | CA27: 3019990 | CB27: 2210237 | CC27: 2517442 | CD27: 2030772 | CE27: 2972999 | CF27: 5090145 | CG27: 5203966 | CH27: =SUM(BV27:CG27) -> 37354199 | CI27: 6002804 | CJ27: 5697624.1 | CK27: 5804345 | CL27: 6442861 | CM27: 7110137.7 | CN27: 8114529.9 | CO27: 7083430.4 | CP27: 6787205.2 | CQ27: 7918572.2 | CR27: 9535124 | CS27: 12233977 | CT27: 51227944 | CU27: =SUM(CI27:CT27) -> 1.3395856e+08 | CV27: =CV28-CV29 -> 20189758 | CW27: =CW28-CW29 -> 13569169 | CX27: =CX28-CX29 -> 19610517 | CY27: =CY28-CY29 -> 19232876 | CZ27: =CZ28-CZ29 -> 17071962 | DA27: =DA28-DA29 -> 17643675 | DB27: =DB28-DB29 -> 18499466 | DC27: =DC28-DC29 -> 20772870 | ... DR27: =DR28-DR29 -> 9788800.6 | DU27: =SUM(DI27:DT27) -> 1.5212118e+08
A28: Debtors Cost | CV28: 20459176 | CW28: 13838730 | CX28: 19818534 | CY28: 19729726 | CZ28: 17477902 | DA28: 18024607 | DB28: 18816372 | DC28: 21072307 | DD28: 20315855 | DE28: 24754076 | DF28: 25697777 | DG28: -11788479 | DH28: 2.3970545e+08 | DI28: 19254241 | DJ28: 20551603 | DK28: 17787253 | DL28: 17601693 | DM28: 11549100 | DN28: 17966573 | DO28: 13616641 | DP28: 13712365 | DQ28: 20330617 | DR28: 10279097 | DU28: =SUM(DI28:DT28) -> 1.6264918e+08
A29: Bad debts recovered | CV29: 269418 | CW29: 269561.19 | CX29: 208017.2 | CY29: 496849.67 | CZ29: 405939.5 | DA29: 380932.25 | DB29: 316906.18 | DC29: 299437.39 | DD29: 228692.53 | DE29: 522373.28 | DF29: 354718.38 | DG29: 241450.34 | DH29: =SUM(CV29:DG29) -> 3994295.9 | DI29: 416655.6 | DJ29: 368893.54 | DK29: 2945608.4 | DL29: 833477.86 | DM29: 1195265 | DN29: 676323.5 | DO29: 1223568.3 | DP29: 1420530.5 | DQ29: 957383.22 | DR29: 490296.77 | DU29: =SUM(DI29:DQ29) -> 10037706
A32: Net Interest Expense
A33: Interest Expense: Commission | B33: 2801.79 | C33: 487.62 | D33: 451.1 | E33: 188.64 | F33: 5862.02 | G33: 813 | H33: 548.14 | I33: 563 | J33: 536.99 | K33: 549.2 | L33: 558.86 | M33: 531.05 | N33: 572.32 | O33: 591.8 | P33: 578.68 | Q33: 522.85 | R33: 443.2 | S33: 6809.03 | T33: 503.44 | U33: 496 | V33: 531.14 | W33: 540.93 | X33: 564.16 | Y33: 613.72 | Z33: 612.71 | AA33: 308.41 | AB33: 293.82 | AC33: 304.09 | AD33: 291.87 | AE33: 271.34 | AF33: 5331.63 | AG33: 306.4 | AH33: 287.01 | AI33: 302.77 | AJ33: 304.97 | AK33: 294.35 | AL33: 0 | AM33: 0 | AN33: 0 | AO33: 0 | AP33: 0 | AQ33: 0 | AR33: 0 | AS33: 1495.5 | AU33: 1495.5 | AV33: 0 | AW33: 0 | AX33: 0 | AY33: 0 | AZ33: 0 | BA33: 0 | BB33: 0 | BC33: 0 | BD33: 0 | BE33: 0 | BF33: 0 | BG33: 0 | BH33: 0 | BI33: 0 | BJ33: 0 | BU33: =SUM(BI33:BJ33) -> 0 | CH33: =SUM(BV33:BW33) -> 0 | CU33: =SUM(BI33:BJ33) -> 0 | DH33: =SUM(BK33:BL33) -> 0
A34: Interest Expense: Local | B34: 33261.5 | C34: 16237.47 | D34: 24866.29 | E34: 22719.67 | F34: 207865.5 | G34: 10354.8 | H34: 17258.97 | I34: 17834.26 | J34: 39253.11 | K34: 45863.02 | L34: 51267.15 | M34: 44383.56 | N34: 45863.02 | O34: 45647.26 | P34: 33357.88 | Q34: 31743.15 | R34: 13320.2 | S34: 396146.38 | T34: 8917.81 | U34: 8630 | V34: 9760.28 | W34: 17054.8 | X34: 17410.96 | Y34: 21000.01 | Z34: 52191.79 | AA34: 123575.34 | AB34: 159315.07 | AC34: 144808.22 | AD34: 144808.22 | AE34: 130794.52 | AF34: 838267.02 | AG34: 144808.22 | AH34: 140136.99 | AI34: 144808.22 | AJ34: 140136.99 | AK34: 144808.22 | AL34: 144808.22 | AM34: 140136.99 | AN34: 163169.1 | AO34: 131369.86 | AP34: 484754.7 | AQ34: 464623.28 | AR34: 461049.12 | AS34: 2704609.9 | AU34: 2704609.9 | AV34: 473867.86 | AW34: 337500 | AX34: 337500 | AY34: 110000 | AZ34: 255434.76 | BA34: 262554.73 | BB34: 254966.5 | BC34: 261953.31 | BD34: 252679.38 | BE34: 237827.84 | BF34: 175286.73 | BG34: 219020.59 | BH34: 3178591.7 | BI34: 451666.67 | BJ34: 437500 | BK34: 451666.67 | BL34: 436997.73 | BM34: 408560.39 | BN34: 120178.88 | BO34: 93752.7 | BP34: 96459.77 | BQ34: 93750 | BR34: 62291.67 | BS34: 0 | BT34: 0 | BU34: =SUM(BI34:BT34) -> 2652824.5 | BV34: 0 | BW34: 0 | BX34: 0 | BY34: 0 | BZ34: 0 | CA34: 0 | CB34: 0 | CC34: 0 | CD34: 0 | CE34: 0 | CF34: 0 | CG34: 0 | CH34: =SUM(BV34:CG34) -> 0 | CU34: =SUM(BV34:CJ34) -> 0 | CV34: 0 | CW34: 0 | CX34: 0 | CY34: 0 | CZ34: 0 | DA34: 0 | DB34: 0 | DC34: 0 | DD34: 0 | DE34: 0 | DF34: 0 | DG34: 0 | DH34: =SUM(CV34:DG34) -> 0
A35: Interest Expense: Long-term Liabilities | B35: 69234.04 | C35: 14556.77 | D35: 16492.17 | E35: 9899.67 | F35: 140613.66 | G35: 24192.36 | H35: 18163.23 | I35: 20992 | J35: 19077.4 | K35: 20790 | L35: 21333.86 | M35: 20457.48 | N35: 25498.94 | O35: 38555.17 | P35: 37700.78 | Q35: 34328.25 | R35: 41187.84 | S35: 322277.62 | T35: 109513.14 | U35: 110499.62 | V35: 115143.06 | W35: 117579.94 | X35: 132329.33 | Y35: 155776.13 | Z35: 186411.91 | AA35: 210261.12 | AB35: 334550.26 | AC35: 382446.21 | AD35: 442224.42 | AE35: 417350.19 | AF35: 2714085.3 | AG35: 469330.51 | AH35: 480051.21 | AI35: 502185.19 | AJ35: 535833.42 | AK35: 491701.03 | AL35: 515974.13 | AM35: 508859.66 | AN35: 556465.99 | AO35: 1048109.1 | AP35: 1190869.6 | AQ35: 1122329.9 | AR35: 1129177.7 | AS35: 8550887.4 | AU35: 8550887.4 | AV35: 1174731 | AW35: 1379466.1 | AX35: 1401092.9 | AY35: 1300734.3 | AZ35: 1308071 | BA35: 1339362.2 | BB35: 1408960.1 | BC35: 1774910.9 | BD35: 1639704.8 | BE35: 1497413.8 | BF35: 1437461.4 | BG35: 1315215.7 | BH35: 16977124 | BI35: 1444578.9 | BJ35: 1380716.7 | BK35: 1626891.6 | BL35: 1555560.3 | BM35: 1911126.5 | BN35: 2425047.4 | BO35: 3314643.2 | BP35: 3543492.5 | BQ35: 3906075 | BR35: 3877122.2 | BS35: 4105584.6 | BT35: 4018423.1 | BU35: =SUM(BI35:BT35) -> 33109262 | BV35: 4407573.1 | BW35: 4754546.7 | BX35: 4912001.7 | BY35: 4777058.5 | BZ35: 5637130.6 | CA35: 6078993 | CB35: 5984592.7 | CC35: 5998297.2 | CD35: 6537273.5 | CE35: 6648599.7 | CF35: 6101160 | CG35: 5105732.8 | CH35: =SUM(BV35:CG35) -> 66942960 | CI35: 5437328.9 | CJ35: 5969296.3 | CK35: 6550431.8 | CL35: 5941327 | CM35: 6434798 | CN35: 6222944.8 | CO35: 7628802.6 | CP35: 8747549.9 | CQ35: 9468807.4 | CR35: 10858966 | CS35: 11738763 | CT35: 10862088 | CU35: =SUM(CI35:CT35) -> 95861104 | CV35: 11804940 | CW35: 13279291 | CX35: 14683697 | CY35: 16017514 | CZ35: 16558260 | DA35: 15942279 | DB35: 16812205 | DC35: 17315169 | DD35: 17435284 | DE35: 17893639 | DF35: 17353034 | DG35: 15969163 | DH35: =SUM(CV35:DG35) -> 1.9106448e+08 | DI35: 16392934 | DJ35: 15284635 | DK35: 15733045 | DL35: 14927615 | DM35: 15224722 | DN35: 14630437 | DO35: 13509793 | DP35: 12886454 | DQ35: 12851992 | DR35: 14193631
A36: Interest Income: Bank | B36: -0.21 | C36: -66734.66 | D36: -67807.07 | E36: -67629.78 | F36: -206566.13 | G36: -57868.88 | H36: -59862.75 | I36: -52549.35 | J36: -54359.94 | K36: -50876.73 | L36: -46900.01 | M36: -37923.45 | N36: -35071 | O36: -42528.28 | P36: -31978.41 | Q36: -24472.72 | R36: -18334.26 | S36: -512725.78 | T36: -14356.93 | U36: -18902 | V36: -16629.43 | W36: -9589.28 | X36: -11967.2 | Y36: -4584.06 | Z36: -3552.72 | AA36: -9020.22 | AB36: -8221.88 | AC36: -38725.63 | AD36: -73438.58 | AE36: -62692.65 | AF36: -271680.58 | AG36: -25670.72 | AH36: -37622.92 | AI36: -60127.97 | AJ36: -14729.5 | AK36: -66292.97 | AL36: 0 | AM36: 0 | AN36: 0 | AO36: 0 | AP36: 0 | AQ36: 0 | AR36: 0 | AS36: -204444.08 | AU36: -204444.08 | AV36: 0 | AW36: 0 | AX36: 0 | AY36: 0 | AZ36: 0 | BA36: 0 | BB36: 0 | BC36: 0 | BD36: 0 | BH36: 0 | BI36: 0 | BJ36: 0 | BU36: =SUM(BI36:BJ36) -> 0 | CH36: =SUM(BV36:BW36) -> 0 | CU36: =SUM(BI36:BJ36) -> 0 | DH36: =SUM(BK36:BL36) -> 0 | DU36: =SUM(BX36:BY36) -> 0
A37: Total Net Interest Expense | B37: =SUM(B33:B36) -> 105297.12 | C37: =SUM(C33:C36) -> -35452.8 | D37: =SUM(D33:D36) -> -25997.51 | E37: =SUM(E33:E36) -> -34821.8 | F37: =SUM(F33:F36) -> 147775.05 | G37: =SUM(G33:G36) -> -22508.72 | H37: =SUM(H33:H36) -> -23892.41 | I37: =SUM(I33:I36) -> -13160.09 | ... AE37: =SUM(AE33:AE36) -> 485723.4 | AF37: 3286003.4 | AG37: 588774.41 | AH37: 582852.29 | AI37: 587168.21 | AJ37: 661545.88 | AK37: 570510.63 | AL37: 660782.35 | AM37: 648996.65 | AN37: 719635.09 | AO37: 1179479 | AP37: 1675624.3 | AQ37: 1586953.2 | AR37: 1590226.8 | AS37: 11052549 | AT37: 0 | AU37: 11052549 | AV37: 1648598.9 | AW37: 1716966.1 | AX37: 1738592.9 | AY37: 1410734.3 | AZ37: 1563505.7 | BA37: 1601916.9 | BB37: 1663926.6 | BC37: 2036864.2 | BD37: 1892384.2 | BE37: 1735241.6 | BF37: 1612748.1 | BG37: 1534236.3 | BH37: 20155716 | BI37: =SUM(BI33:BI36) -> 1896245.5 | BJ37: =SUM(BJ33:BJ36) -> 1818216.7 | BK37: =SUM(BK33:BK36) -> 2078558.2 | BL37: =SUM(BL33:BL36) -> 1992558.1 | BM37: =SUM(BM33:BM36) -> 2319686.9 | BN37: =SUM(BN33:BN36) -> 2545226.3 | BO37: =SUM(BO33:BO36) -> 3408395.9 | BP37: =SUM(BP33:BP36) -> 3639952.3 | ... BR37: =SUM(BR33:BR36) -> 3939413.9 | BS37: =SUM(BS34:BS35) -> 4105584.6 | BT37: =SUM(BT34:BT35) -> 4018423.1 | BU37: =SUM(BI37:BT37) -> 35762086 | BV37: =SUM(BV34:BV35) -> 4407573.1 | BW37: =SUM(BW33:BW36) -> 4754546.7 | BX37: =SUM(BX33:BX36) -> 4912001.7 | BY37: =SUM(BY33:BY36) -> 4777058.5 | BZ37: =SUM(BZ33:BZ36) -> 5637130.6 | CA37: =SUM(CA33:CA36) -> 6078993 | CB37: =SUM(CB33:CB36) -> 5984592.7 | CC37: =SUM(CC33:CC36) -> 5998297.2 | CD37: =SUM(CD33:CD36) -> 6537273.5 | ... CG37: =SUM(CG33:CG36) -> 5105732.8 | CH37: =SUM(BV37:CG37) -> 66942960 | CI37: =SUM(CI33:CI36) -> 5437328.9 | CJ37: =SUM(CJ33:CJ36) -> 5969296.3 | CK37: =SUM(CK33:CK36) -> 6550431.8 | CL37: =SUM(CL33:CL36) -> 5941327 | CM37: =SUM(CM33:CM36) -> 6434798 | CN37: =SUM(CN33:CN36) -> 6222944.8 | CO37: =SUM(CO33:CO36) -> 7628802.6 | CP37: =SUM(CP33:CP36) -> 8747549.9 | ... CT37: =SUM(CT33:CT36) -> 10862088 | CU37: =SUM(CI37:CT37) -> 95861104 | CV37: =SUM(CV33:CV36) -> 11804940 | CW37: =SUM(CW33:CW36) -> 13279291 | CX37: =SUM(CX33:CX36) -> 14683697 | CY37: =SUM(CY33:CY36) -> 16017514 | CZ37: =SUM(CZ33:CZ36) -> 16558260 | DA37: =SUM(DA33:DA36) -> 15942279 | DB37: =SUM(DB33:DB36) -> 16812205 | DC37: =SUM(DC33:DC36) -> 17315169 | ... DG37: =SUM(DG33:DG36) -> 15969163 | DH37: =SUM(CV37:DG37) -> 1.9106448e+08 | DI37: =SUM(DI33:DI36) -> 16392934 | DJ37: =SUM(DJ33:DJ36) -> 15284635 | DK37: =SUM(DK33:DK36) -> 15733045 | DL37: =SUM(DL33:DL36) -> 14927615 | DM37: =SUM(DM33:DM36) -> 15224722 | DN37: =SUM(DN33:DN36) -> 14630437 | DO37: =SUM(DO33:DO36) -> 13509793 | DP37: =SUM(DP33:DP36) -> 12886454 | ... DT37: =SUM(DT33:DT36) -> 0 | DU37: =SUM(DI37:DT37) -> 1.4563526e+08
A39: Total Default and Interest Charges | B39: =(0+(0)+(B27)+(B37))-(0) -> 552955.45 | C39: =(0+(0)+(C27)+(C37))-(0) -> 117992.85 | D39: =(0+(0)+(D27)+(D37))-(0) -> 83678.31 | E39: =(0+(0)+(E27)+(E37))-(0) -> 91505.21 | F39: =(0+(0)+(F27)+(F37))-(0) -> 1755877 | G39: =G27+G37 -> 122380.74 | H39: =H27+H37 -> 124488.06 | I39: =I27+I37 -> 138954.52 | J39: =J27+J37 -> 174713.13 | K39: =K27+K37 -> 181037.37 | L39: =L27+L37 -> 176259.61 | M39: =M27+M37 -> 147473.26 | N39: =N27+N37 -> 169697.75 | ... S39: =S27+S37 -> 1996774.3 | T39: =+T27+T37 -> 161166.84 | U39: =+U37+U27 -> 170216.62 | V39: =+V37+V27 -> 231018.86 | W39: =+W37+W27 -> 173163.76 | X39: =+X37+X27 -> 200189.58 | Y39: =+Y37+Y27 -> 356986.28 | Z39: =+Z37+Z27 -> 383684.04 | AA39: =+AA37+AA27 -> 474405.25 | AB39: =+AB37+AB27 -> 826152.61 | ... AE39: =+AE37+AE27 -> 846783.04 | AF39: 5266981.9 | AG39: 768651.09 | AH39: 689433.25 | AI39: 886765.83 | AJ39: 932472.65 | AK39: 879159.51 | AL39: 1019419.8 | AM39: 1140247.3 | AN39: 1296605.6 | AO39: 1795031 | AP39: 2454127.8 | AQ39: 2227144.4 | AR39: 2266272.9 | AS39: 16355331 | AT39: 0 | AU39: 16355331 | AV39: 5200470.2 | AW39: 5957551.1 | AX39: 5074075.5 | AY39: 3606544.3 | AZ39: 3408141.1 | BA39: 1993306.8 | BB39: 2222202.6 | BC39: 2437677.7 | BD39: 2232204.8 | BE39: 2667513.6 | BF39: 2626695.5 | BG39: 2559237.5 | BH39: 39985621 | BI39: =(0+(0)+('P&L -Dec25'!BI27)+('P&L -Dec25'!BI37))-(0) -> 2867038.9 | BJ39: =(0+(0)+('P&L -Dec25'!BJ27)+('P&L -Dec25'!BJ37))-(0) -> 2864528.9 | BK39: =(0+(0)+('P&L -Dec25'!BK27)+('P&L -Dec25'!BK37))-(0) -> 3298061 | BL39: =(0+(0)+('P&L -Dec25'!BL27)+('P&L -Dec25'!BL37))-(0) -> 2764440.7 | BM39: =(0+(0)+('P&L -Dec25'!BM27)+('P&L -Dec25'!BM37))-(0) -> 3505739.7 | BN39: =(0+(0)+('P&L -Dec25'!BN27)+('P&L -Dec25'!BN37))-(0) -> 4548353.5 | BO39: =(0+(0)+('P&L -Dec25'!BO27)+('P&L -Dec25'!BO37))-(0) -> 5263515.1 | BP39: =(0+(0)+('P&L -Dec25'!BP27)+('P&L -Dec25'!BP37))-(0) -> 6463525.2 | ... BT39: =(0+(0)+('P&L -Dec25'!BT27)+('P&L -Dec25'!BT37))-(0) -> 8903717.2 | BU39: =SUM(BI39:BT39) -> 61747598 | BV39: =(0+(0)+('P&L -Dec25'!BV27)+('P&L -Dec25'!BV37))-(0) -> 8346857.1 | BW39: =(0+(0)+('P&L -Dec25'!BW27)+('P&L -Dec25'!BW37))-(0) -> 7613020.2 | BX39: =(0+(0)+('P&L -Dec25'!BX27)+('P&L -Dec25'!BX37))-(0) -> 6960827.7 | BY39: =(0+(0)+('P&L -Dec25'!BY27)+('P&L -Dec25'!BY37))-(0) -> 6690409.8 | BZ39: =(0+(0)+('P&L -Dec25'!BZ27)+('P&L -Dec25'!BZ37))-(0) -> 9185843.6 | CA39: =(0+(0)+('P&L -Dec25'!CA27)+('P&L -Dec25'!CA37))-(0) -> 9098983 | CB39: =(0+(0)+('P&L -Dec25'!CB27)+('P&L -Dec25'!CB37))-(0) -> 8194829.7 | CC39: =(0+(0)+('P&L -Dec25'!CC27)+('P&L -Dec25'!CC37))-(0) -> 8515739.2 | ... CG39: =(0+(0)+('P&L -Dec25'!CG27)+('P&L -Dec25'!CG37))-(0) -> 10309699 | CH39: =SUM(BV39:CG39) -> 1.0429716e+08 | CI39: =(0+(0)+('P&L -Dec25'!CI27)+('P&L -Dec25'!CI37))-(0) -> 11440133 | CJ39: =(0+(0)+('P&L -Dec25'!CJ27)+('P&L -Dec25'!CJ37))-(0) -> 11666920 | CK39: =(0+(0)+('P&L -Dec25'!CK27)+('P&L -Dec25'!CK37))-(0) -> 12354777 | CL39: =(0+(0)+('P&L -Dec25'!CL27)+('P&L -Dec25'!CL37))-(0) -> 12384188 | CM39: =(0+(0)+('P&L -Dec25'!CM27)+('P&L -Dec25'!CM37))-(0) -> 13544936 | CN39: =(0+(0)+('P&L -Dec25'!CN27)+('P&L -Dec25'!CN37))-(0) -> 14337475 | CO39: =(0+(0)+('P&L -Dec25'!CO27)+('P&L -Dec25'!CO37))-(0) -> 14712233 | CP39: =(0+(0)+('P&L -Dec25'!CP27)+('P&L -Dec25'!CP37))-(0) -> 15534755 | ... CT39: =(0+(0)+('P&L -Dec25'!CT27)+('P&L -Dec25'!CT37))-(0) -> 62090032 | CU39: =SUM(CI39:CT39) -> 2.2981966e+08 | CV39: =(0+(0)+('P&L -Dec25'!CV27)+('P&L -Dec25'!CV37))-(0) -> 31994698 | CW39: =(0+(0)+('P&L -Dec25'!CW27)+('P&L -Dec25'!CW37))-(0) -> 26848460 | CX39: =(0+(0)+('P&L -Dec25'!CX27)+('P&L -Dec25'!CX37))-(0) -> 34294214 | CY39: =(0+(0)+('P&L -Dec25'!CY27)+('P&L -Dec25'!CY37))-(0) -> 35250390 | CZ39: =(0+(0)+('P&L -Dec25'!CZ27)+('P&L -Dec25'!CZ37))-(0) -> 33630223 | DA39: =(0+(0)+('P&L -Dec25'!DA27)+('P&L -Dec25'!DA37))-(0) -> 33585954 | DB39: =(0+(0)+('P&L -Dec25'!DB27)+('P&L -Dec25'!DB37))-(0) -> 35311671 | DC39: =(0+(0)+('P&L -Dec25'!DC27)+('P&L -Dec25'!DC37))-(0) -> 38088039 | ... DG39: =(0+(0)+('P&L -Dec25'!DG27)+('P&L -Dec25'!DG37))-(0) -> 3939233.2 | DH39: =SUM(CV39:DG39) -> 3.9528676e+08 | DI39: =(0+(0)+('P&L -Dec25'!DI27)+('P&L -Dec25'!DI37))-(0) -> 35230520 | DJ39: =(0+(0)+('P&L -Dec25'!DJ27)+('P&L -Dec25'!DJ37))-(0) -> 35467345 | DK39: =(0+(0)+('P&L -Dec25'!DK27)+('P&L -Dec25'!DK37))-(0) -> 30574690 | DL39: =(0+(0)+('P&L -Dec25'!DL27)+('P&L -Dec25'!DL37))-(0) -> 31695830 | DM39: =(0+(0)+('P&L -Dec25'!DM27)+('P&L -Dec25'!DM37))-(0) -> 25578557 | DN39: =(0+(0)+('P&L -Dec25'!DN27)+('P&L -Dec25'!DN37))-(0) -> 31920686 | DO39: =(0+(0)+('P&L -Dec25'!DO27)+('P&L -Dec25'!DO37))-(0) -> 25902866 | DP39: =(0+(0)+('P&L -Dec25'!DP27)+('P&L -Dec25'!DP37))-(0) -> 25178288 | ... DT39: =(0+(0)+('P&L -Dec25'!DT27)+('P&L -Dec25'!DT37))-(0) -> 0 | DU39: =SUM(DI39:DT39) -> 2.9775644e+08
A41: Other Charges
A42: Fixed Charges
A43: Funding Expense (Guarantees and Upfront fees) | R43: 10636.53 | S43: 10636.53 | T43: 10636.53 | U43: 10637 | V43: 11061.66 | W43: 11061.66 | X43: 25511.43 | Y43: 26208.44 | Z43: 30041.44 | AA43: 26899.68 | AB43: 53351.59 | AC43: 71339.79 | AD43: 56890.02 | AE43: 56217.75 | AF43: 389856.99 | AG43: 51592.29 | AH43: 88968.39 | AI43: 75955.68 | AJ43: 75955.68 | AK43: 75955.68 | AL43: 75700.02 | AM43: 65682.42 | AN43: 65682.42 | AO43: 47220.26 | AP43: 29232.06 | AQ43: 29232.06 | AR43: 28158.35 | AS43: 709335.31 | AU43: 709335.31 | AV43: 14773.93 | AW43: 4166.67 | AX43: 0 | AY43: 0 | AZ43: 0 | BA43: 0 | BB43: 0 | BC43: 0 | BD43: 0 | BE43: 0 | BF43: 0 | BG43: 0 | BH43: 18940.6 | BI43: 0 | BJ43: 0 | BK43: 0 | BL43: 0 | BM43: 0 | BN43: 0 | BO43: 0 | BP43: 0 | BQ43: 0 | BR43: 0 | BS43: 0 | BT43: 0 | BU43: =SUM(BI43:BT43) -> 0 | BV43: 0 | BW43: 0 | BX43: 0 | BY43: 0 | BZ43: 0 | CA43: 0 | CB43: 0 | CC43: 0 | CD43: 0 | CE43: 0 | CF43: 0 | CG43: 0 | CH43: =SUM(BV43:CG43) -> 0 | CI43: 0 | CJ43: 0 | CK43: 0 | CL43: 0 | CM43: 0 | CU43: =SUM(CI43:CM43) -> 0 | CV43: 0 | CW43: 0 | CX43: 0 | CY43: 0 | CZ43: 0 | DA43: 0 | DH43: =SUM(CV43:DG43) -> 0 | DU43: =SUM(DI43:DT43) -> 0
A45: Variable Charges
A46: Banking Fees - Intecon | B46: 14521.93 | C46: 3349.32 | D46: 3914.58 | E46: 3738.59 | F46: 39667.44 | G46: 4559.4 | H46: 4167.48 | I46: 4300.51 | J46: 4525.51 | K46: 4572.84 | L46: 5476.67 | M46: 5403.02 | N46: 4938.56 | O46: 5313.34 | P46: 5708.39 | Q46: 6019.64 | R46: 5623.65 | S46: 60609.01 | T46: 6995.65 | U46: 6002 | V46: 6555.64 | W46: 7451.39 | X46: 8194.87 | Y46: 9416.96 | Z46: 8881.13 | AA46: 10499.42 | AB46: 11606.13 | AC46: 11391.57 | AD46: 12302.65 | AE46: 11325.33 | AF46: 110622.74 | AG46: 12790.64 | AH46: 12772.94 | AI46: 13358.09 | AJ46: 12924.15 | AK46: 14452.43 | AL46: 15127.82 | AM46: 14895.92 | AN46: 16872.31 | AO46: 19320.98 | AP46: 20954.47 | AQ46: 26370.13 | AR46: 26337.35 | AS46: 206177.23 | AU46: 206177.23 | AV46: 28539.97 | AW46: 28636.98 | AX46: 23416.82 | AY46: 22282.83 | AZ46: 24792.59 | BA46: 22289.57 | BB46: 23963.42 | BC46: 23779.28 | BD46: 23255.88 | BE46: 25201.55 | BF46: 25097.3 | BG46: 25954.68 | BH46: 297210.87 | BI46: 29863.6 | BJ46: 30384.88 | BK46: 29154.07 | BL46: 27181.59 | BM46: 28045.25 | BN46: 26100.11 | BO46: 24973.74 | BP46: 25153.79 | BQ46: 25490 | BR46: 24145.75 | BS46: 27287.95 | BT46: 25303.18 | BU46: =SUM(BI46:BT46) -> 323083.91 | BV46: 31942.99 | BW46: 30280.97 | BX46: 34147.74 | BY46: 30460.64 | BZ46: 31859.34 | CA46: 32657.71 | CB46: 31933.28 | CC46: 35526.96 | CD46: 34553.33 | CE46: 36690.24 | CF46: 38769.96 | CG46: 38284.36 | CH46: =SUM(BV46:CG46) -> 407107.52 | CI46: 45197.4 | CJ46: 37845.61 | CK46: 47393.24 | CL46: 46114.98 | CM46: 50670.63 | CN46: 52107.47 | CO46: 53700.78 | CP46: 57486.13 | CQ46: 60998.35 | CR46: 63746.13 | CS46: 69859.86 | CT46: 67696.03 | CU46: =SUM(CI46:CT46) -> 652816.61 | CV46: 72244.44 | CW46: 78358.16 | CX46: 79411.37 | CY46: 76097.08 | CZ46: 90119.35 | DA46: 85777.32 | DB46: 80718.43 | DC46: 84468.39 | DD46: 81543.44 | DE46: 82691.7 | DF46: 63218.13 | DG46: 72100.73 | DH46: =SUM(CV46:DG46) -> 946748.54 | DI46: 84496.12 | DJ46: 72179.04 | DK46: 76323.94 | DL46: 72952.62 | DM46: 72008.11 | DN46: 68996.94 | DO46: 71683.15 | DP46: 73518.15 | DQ46: 66822.99 | DR46: 71410.7 | DU46: =SUM(DI46:DT46) -> 730391.76
A47: Credit Assessments | B47: 33247.76 | C47: 8858.85 | D47: 8797.97 | E47: 11336.77 | F47: 88834.65 | G47: 13652.37 | H47: 14198.74 | I47: 14191.95 | J47: 13049.43 | K47: 16822.13 | L47: 15774.48 | M47: 15920.96 | N47: 15562.09 | O47: 11293.78 | P47: 17805.76 | Q47: 9253.02 | R47: 17607.92 | S47: 175132.63 | T47: 16420.39 | U47: 16034 | V47: 15379.57 | W47: 21118.58 | X47: 17409.52 | Y47: 17335.86 | Z47: 23479.45 | AA47: 28814.51 | AB47: 25646.65 | AC47: 28054.09 | AD47: 24224.83 | AE47: 33968.18 | AF47: 267885.63 | AG47: 36535.12 | AH47: 40625.14 | AI47: 33401.3 | AJ47: 49482.39 | AK47: 54962.47 | AL47: 58084.68 | AM47: 70186.26 | AN47: 67884.04 | AO47: 88337.76 | AP47: 95085.19 | AQ47: 57712.94 | AR47: 127575.35 | AS47: 779872.64 | AU47: 779872.64 | AV47: 82296.79 | AW47: 59486.39 | AX47: 78059.78 | AY47: 59638.99 | AZ47: 49160.37 | BA47: 72481.12 | BB47: 77029.13 | BC47: 74453.13 | BD47: 83643.98 | BE47: 66900.33 | BF47: 60243.65 | BG47: 105679.47 | BH47: 869073.13 | BI47: 104315.96 | BJ47: 91766.69 | BK47: 89473.75 | BL47: 91898.13 | BM47: 77716.64 | BN47: 79325 | BO47: 80477.07 | BP47: 103477.97 | BQ47: 108437 | BR47: 133209.6 | BS47: 78955.53 | BT47: 105952.34 | BU47: =SUM(BI47:BT47) -> 1145005.7 | BV47: 102472.6 | BW47: 86095.31 | BX47: 105390.54 | BY47: 123689.7 | BZ47: 127955.3 | CA47: 119073.68 | CB47: 113575.9 | CC47: 105106.25 | CD47: 130476.58 | CE47: 121391.75 | CF47: 93672.61 | CG47: 105454.78 | CH47: =SUM(BV47:CG47) -> 1334355 | CI47: 110987.76 | CJ47: 105671.88 | CK47: 124632.75 | CL47: 143502.27 | CM47: 149627.66 | CN47: 170372.67 | CO47: 160822.05 | CP47: 168322.17 | CQ47: 166620.82 | CR47: 175877.51 | CS47: 140780.49 | CT47: 188378.22 | CU47: =SUM(CI47:CT47) -> 1805596.2 | CV47: 191028.52 | CW47: 164721.23 | CX47: 161033.93 | CY47: 196534.11 | CZ47: 215087.78 | DA47: 190730.21 | DB47: 214247.43 | DC47: 256941.01 | DD47: 241643.68 | DE47: 186666.51 | DF47: 255147.99 | DG47: 227639.59 | DH47: =SUM(CV47:DG47) -> 2501422 | DI47: 171754.87 | DJ47: 189388.8 | DK47: 154980.47 | DL47: 216849.44 | DM47: 178478.72 | DN47: 178012.24 | DO47: 177831.27 | DP47: 175679.69 | DQ47: 230587.81 | DR47: 183259.17 | DU47: =SUM(DI47:DT47) -> 1856822.5
A48: Total Other Charges | B48: =SUM(B46:B47) -> 47769.69 | C48: =SUM(C46:C47) -> 12208.17 | D48: =SUM(D46:D47) -> 12712.55 | E48: =SUM(E46:E47) -> 15075.36 | F48: =SUM(F46:F47) -> 128502.09 | G48: =SUM(G41:G47) -> 18211.77 | H48: =SUM(H41:H47) -> 18366.22 | I48: =SUM(I41:I47) -> 18492.46 | J48: =SUM(J41:J47) -> 17574.94 | K48: =SUM(K41:K47) -> 21394.97 | L48: =SUM(L41:L47) -> 21251.15 | M48: =SUM(M41:M47) -> 21323.98 | N48: =SUM(N41:N47) -> 20500.65 | ... R48: =SUM(R41:R47) -> 33868.1 | S48: =SUM(S43:S47) -> 246378.17 | T48: =SUM(T46:T47) -> 23416.04 | U48: 22035 | V48: =SUM(V46:V47) -> 21935.21 | W48: =SUM(W46:W47) -> 28569.97 | X48: =SUM(X46:X47) -> 25604.39 | Y48: =SUM(Y46:Y47) -> 26752.82 | Z48: =SUM(Z46:Z47) -> 32360.58 | AA48: =SUM(AA46:AA47) -> 39313.93 | AB48: =SUM(AB46:AB47) -> 37252.78 | AC48: =SUM(AC46:AC47) -> 39445.66 | ... AE48: =SUM(AE46:AE47) -> 45293.51 | AF48: 378507.37 | AG48: 49325.76 | AH48: 53398.08 | AI48: 46759.39 | AJ48: 62406.54 | AK48: 69414.9 | AL48: 73212.5 | AM48: 85082.18 | AN48: 84756.35 | AO48: 107658.74 | AP48: 116039.66 | AQ48: 84083.07 | AR48: 153912.7 | AS48: 986049.87 | AT48: 0 | AU48: 986049.87 | AV48: 110836.76 | AW48: 88123.37 | AX48: 101476.6 | AY48: 81921.82 | AZ48: 73952.96 | BA48: 94770.69 | BB48: 100992.55 | BC48: 98232.41 | BD48: 106899.86 | BE48: 92101.88 | BF48: 85340.95 | BG48: 131634.15 | BH48: 1166284 | BI48: =SUM('P&L -Dec25'!BI46:BI47) -> 134179.56 | BJ48: =SUM('P&L -Dec25'!BJ46:BJ47) -> 122151.57 | BK48: =SUM('P&L -Dec25'!BK46:BK47) -> 118627.82 | BL48: =SUM('P&L -Dec25'!BL46:BL47) -> 119079.72 | BM48: =SUM('P&L -Dec25'!BM46:BM47) -> 105761.89 | BN48: =SUM('P&L -Dec25'!BN46:BN47) -> 105425.11 | BO48: =SUM('P&L -Dec25'!BO46:BO47) -> 105450.81 | BP48: =SUM('P&L -Dec25'!BP46:BP47) -> 128631.76 | ... BR48: =SUM('P&L -Dec25'!BR46:BR47) -> 157355.35 | BS48: =SUM(BS46:BS47) -> 106243.48 | BT48: =SUM(BT46:BT47) -> 131255.52 | BU48: =SUM(BI48:BT48) -> 1468089.6 | BV48: =SUM(BV46:BV47) -> 134415.59 | BW48: =SUM('P&L -Dec25'!BW46:BW47) -> 116376.28 | BX48: =SUM('P&L -Dec25'!BX46:BX47) -> 139538.28 | BY48: =SUM('P&L -Dec25'!BY46:BY47) -> 154150.34 | BZ48: =SUM('P&L -Dec25'!BZ46:BZ47) -> 159814.64 | CA48: =SUM('P&L -Dec25'!CA46:CA47) -> 151731.39 | CB48: =SUM('P&L -Dec25'!CB46:CB47) -> 145509.18 | CC48: =SUM('P&L -Dec25'!CC46:CC47) -> 140633.21 | CD48: =SUM('P&L -Dec25'!CD46:CD47) -> 165029.91 | ... CG48: =SUM('P&L -Dec25'!CG46:CG47) -> 143739.14 | CH48: =SUM(BV48:CG48) -> 1741462.5 | CI48: =SUM('P&L -Dec25'!CI46:CI47) -> 156185.16 | CJ48: =SUM('P&L -Dec25'!CJ46:CJ47) -> 143517.49 | CK48: =SUM('P&L -Dec25'!CK46:CK47) -> 172025.99 | CL48: =SUM('P&L -Dec25'!CL46:CL47) -> 189617.25 | CM48: =SUM('P&L -Dec25'!CM46:CM47) -> 200298.29 | CN48: =SUM('P&L -Dec25'!CN46:CN47) -> 222480.14 | CO48: =SUM('P&L -Dec25'!CO46:CO47) -> 214522.83 | CP48: =SUM('P&L -Dec25'!CP46:CP47) -> 225808.3 | ... CT48: =SUM('P&L -Dec25'!CT46:CT47) -> 256074.25 | CU48: =SUM(CI48:CT48) -> 2458412.9 | CV48: =SUM('P&L -Dec25'!CV46:CV47) -> 263272.96 | CW48: =SUM('P&L -Dec25'!CW46:CW47) -> 243079.39 | CX48: =SUM('P&L -Dec25'!CX46:CX47) -> 240445.3 | CY48: =SUM('P&L -Dec25'!CY46:CY47) -> 272631.19 | CZ48: =SUM('P&L -Dec25'!CZ46:CZ47) -> 305207.13 | DA48: =SUM('P&L -Dec25'!DA46:DA47) -> 276507.53 | DB48: =SUM('P&L -Dec25'!DB46:DB47) -> 294965.86 | DC48: =SUM('P&L -Dec25'!DC46:DC47) -> 341409.4 | ... DG48: =SUM('P&L -Dec25'!DG46:DG47) -> 299740.32 | DH48: =SUM(CV48:DG48) -> 3448170.5 | DI48: =SUM('P&L -Dec25'!DI46:DI47) -> 256250.99 | DJ48: =SUM('P&L -Dec25'!DJ46:DJ47) -> 261567.84 | DK48: =SUM('P&L -Dec25'!DK46:DK47) -> 231304.41 | DL48: =SUM('P&L -Dec25'!DL46:DL47) -> 289802.06 | DM48: =SUM('P&L -Dec25'!DM46:DM47) -> 250486.83 | DN48: =SUM('P&L -Dec25'!DN46:DN47) -> 247009.18 | DO48: =SUM('P&L -Dec25'!DO46:DO47) -> 249514.42 | DP48: =SUM('P&L -Dec25'!DP46:DP47) -> 249197.84 | ... DT48: =SUM('P&L -Dec25'!DT46:DT47) -> 0 | DU48: =SUM(DI48:DT48) -> 2587214.2
A50: Lula Banking - cost of service
A52: Banking (Connect)
A53: Courier and fees | CA53: 5000 | CB53: 1071.21 | CC53: 243.6 | CD53: 243.6 | CE53: 243.6 | CF53: 243.6 | CG53: 487.21 | CH53: =SUM(BV53:CG53) -> 7532.82 | CI53: 81.2 | CJ53: 243.6 | CK53: 1218.02 | CL53: 3106.84 | CM53: 20395.01 | CN53: 9112.57 | CO53: 6471.35 | CP53: 10569.32 | CQ53: 23300.05 | CR53: 15475.36 | CS53: 9053.75 | CT53: 23889.54 | CU53: =SUM(CI53:CT53) -> 122916.61 | CV53: 30024.92 | CW53: 24645.33 | CX53: 47188.52 | CY53: 42244.81 | CZ53: 38000.19 | DA53: 32611.73 | DB53: 37657.77 | DC53: 44648.62 | DD53: 43415.74 | DE53: 13292.97 | DF53: 29549.32 | DG53: 28116.21 | DH53: =SUM(CV53:DG53) -> 411396.13 | DI53: 22775.18 | DJ53: 76723.57 | DK53: 25762.51 | DL53: 23449.2 | DM53: 24724.32 | DN53: 22529.89 | DO53: 8284.14 | DP53: 53923.21 | DQ53: 13563.22 | DR53: 0 | DU53: =SUM(DI53:DT53) -> 271735.24
A54: Interest expense (Connect) | CV54: 9886.31 | CW54: 10415.43 | CX54: 6299.47 | CY54: 9168.64 | CZ54: 9168.64 | DA54: 8434.48 | DB54: 7170.78 | DC54: 9581.11 | DD54: 8381.53 | DE54: 12070.17 | DF54: 11820.44 | DG54: 12114.15 | DH54: =SUM(CV54:DG54) -> 114511.15 | DI54: 21296.19 | DJ54: 17437.4 | DK54: 19517.32 | DL54: 21567.18 | DM54: 26096.79 | DN54: 25776.57 | DO54: 25484.47 | DP54: 27472.27 | DQ54: 0 | DR54: 0 | DU54: =SUM(DI54:DT54) -> 184648.19
...

Sheet Balance Sheet - Dec25
A1: Balance Sheet
A2: Lula Lend (Pty) Ltd
A3: As at 31 December 2025
B5: Note | C5: 46022 | E5: 45991 | G5: 45961 | I5: 45930 | K5: 45900 | M5: 45869 | O5: 45838 | Q5: 45808 | S5: 45777 | U5: 45747 | W5: 45716 | Y5: 45688 | AA5: 45657 | AC5: 45626 | AE5: 45596 | AG5: 45565 | AI5: 45535 | AK5: 45504 | AM5: 45473 | AO5: 45443 | AQ5: 45412 | AS5: 45382 | AU5: 45351 | AW5: 45322 | AY5: 45291 | BA5: 45260 | BC5: 45230 | BE5: 45199 | BG5: 45169 | BI5: 45138 | BK5: 45107 | BM5: 45077 | BO5: 45046 | BQ5: 45016 | BS5: 44985 | BU5: 44957 | BW5: 44926 | BY5: 44895 | CA5: 44865 | CC5: 44834 | CE5: 44804 | CG5: 44773 | CI5: 44742 | CK5: 44712 | CM5: 44681 | CO5: 44651 | CQ5: 44620 | CS5: 31 Jan 2022 | CU5: 31 Dec 2021 | CW5: 30 Nov 2021 | CY5: 31 Oct 2021 | DA5: 30 Sep 2021 | DC5: 31 Aug 2021 | DE5: 31 Jul 2021 | DG5: 30 Jun 2021 | DI5: 31 May 2021 | DK5: 30 April 2021 | DM5: 31 March 2021 | DO5: 28 February 2021 | DQ5: 31 January 2021 | DS5: 31 December 2020 | DU5: 30 November 2020 | DW5: 31 October 2020 | DY5: 30 September 2020 | EA5: 31 August 2020 | EC5: 31 July 2020 | EE5: 30 June 2020 | EG5: 31 May 2020 | EI5: 30 April 2020 | EK5: 31 March 2020 | EM5: 29 February 2020 | EO5: 31 January 2020 | EQ5: 31 December 2019 | ES5: 30 November 2019 | EU5: 31 October 2019 | EW5: 30 September 2019 | EY5: 31 August 2019 | FA5: 31 July 2019 | FC5: 30 June 2019 | FE5: 31 May 2019 | FG5: 30 April 2019 | FI5: 31 March 2019 | FK5: 28 February 2019 | FM5: 31 January 2019 | FO5: 31 December 2018 | FQ5: 30 November 2018 | FS5: 31 October 2018 | FU5: 30 September 2018 | FW5: 31 August 2018 | FY5: 31 July 2018 | GA5: 30 June 2018 | GC5: 31 May 2018 | GE5: 30 April 2018 | GG5: 31 March 2018 | GI5: 28 February 2018 | GK5: 31 January 2018 | GM5: 31 December 2017 | GO5: 30 November 2017 | GQ5: 31 October 2017 | GS5: 30 September 2017 | GU5: 31 August 2017 | GW5: 31 July 2017 | GY5: 30 June 2017 | HA5: 31 May 2017 | HC5: 30 Apr 2017 | HE5: 31 Mar 2017 | HG5: 28 Feb 2017
A7: Assets | C7: =SUM(C8:C17) -> 2.0721263e+09 | E7: =SUM(E8:E17) -> 1.9914537e+09 | G7: =SUM(G8:G17) -> 1.9477409e+09 | I7: 1.9813908e+09 | K7: 2.1090189e+09 | M7: =SUM(M8:M17) -> 2.1518578e+09 | O7: =SUM(O8:O17) -> 2.192448e+09 | Q7: =SUM(Q8:Q17) -> 2.2005295e+09 | S7: =SUM(S8:S17) -> 2.2375257e+09 | U7: =SUM(U8:U17) -> 2.0526214e+09 | W7: =SUM(W8:W17) -> 2.1675086e+09 | Y7: 2.2231317e+09 | AA7: 2.25e+09 | AC7: 2.306836e+09 | AE7: 2.32028e+09 | AG7: 2.2023167e+09 | AI7: 2.2505996e+09 | AK7: 2.0962932e+09 | AM7: 2.100169e+09 | AO7: 2.0503994e+09 | AQ7: 1.9190766e+09 | AS7: 1.8444264e+09 | AU7: =SUM(AU8:AU17) -> 1.6895661e+09 | AW7: 1.7178849e+09 | AY7: 1.7339179e+09 | BA7: 1.5616749e+09 | BC7: 1.5358321e+09 | BE7: 1.429968e+09 | BG7: 1.2772405e+09 | BI7: 1.2549291e+09 | BK7: 1.2300931e+09 | BM7: 1.2357726e+09 | BO7: 1.2053235e+09 | BQ7: =SUM(BQ8:BQ17) -> 5.5468793e+08 | BS7: =SUM(BS8:BS17) -> 1.0772012e+09 | BU7: 1.1831534e+09 | BW7: 8.2663888e+08 | BY7: 8.2024724e+08 | CA7: 7.3039614e+08 | CC7: 7.2894163e+08 | CE7: 7.4957229e+08 | CG7: 7.5474413e+08 | CI7: 6.5282699e+08 | CK7: 6.4966137e+08 | CM7: 6.4393881e+08 | CO7: =SUM(CO8:CO17) -> 6.4783466e+08 | CQ7: =SUM(CQ8:CQ17) -> 6.0766085e+08 | CS7: =SUM(CS8:CS17) -> 5.7276029e+08 | CU7: =SUM(CU8:CU17) -> 4.9987402e+08 | CW7: =SUM(CW8:CW17) -> 5.1305868e+08 | CY7: =SUM(CY8:CY17) -> 5.0840609e+08 | DA7: =SUM(DA8:DA17) -> 4.2506581e+08 | DC7: =SUM(DC8:DC17) -> 4.2511854e+08 | DE7: =SUM(DE8:DE17) -> 3.9147582e+08 | DG7: =SUM(DG8:DG17) -> 3.5750725e+08 | DI7: =SUM(DI8:DI17) -> 3.1940397e+08 | DK7: =SUM(DK8:DK17) -> 3.2303099e+08 | DM7: =SUM(DM8:DM17) -> 3.0301033e+08 | DO7: 3.0165104e+08 | DQ7: 2.7014793e+08 | DS7: 2.6908846e+08 | DU7: 2.8471434e+08 | DW7: 3.0747512e+08 | DY7: 3.1955354e+08 | EA7: 2.703074e+08 | EC7: 2.6770201e+08 | EE7: 2.692046e+08 | EG7: 2.6856269e+08 | EI7: 2.674109e+08 | EK7: 2.7211391e+08 | EM7: 2.7739587e+08 | EO7: 2.7980385e+08 | EQ7: 2.7763278e+08 | ES7: 2.4412734e+08 | EU7: 1.996623e+08 | EW7: 1.7702124e+08 | EY7: 1.7434507e+08 | FA7: 1.7638416e+08 | FC7: 1.7994533e+08 | FE7: 90524983 | FG7: 89224776 | FI7: 87836057 | FK7: 76859702 | FM7: 76851290 | FO7: 80968553 | FQ7: 65961033 | FS7: 67506267 | FU7: 46447928 | FW7: 41982557 | FY7: 38595572 | GA7: 33396339 | GC7: 33009429 | GE7: 31529369 | GG7: 31428514 | GI7: 31020182 | GK7: 27087750 | GM7: 27071748 | GO7: 28067168 | GQ7: 27425147 | GS7: 24771482 | GU7: 25119066 | GW7: 24440237 | GY7: 24597276 | HA7: 22438710 | HC7: 22129893 | HE7: 22332816 | HG7: 22737686
A8: Bank | C8: 46703517 | E8: 38038011 | G8: 38057566 | I8: 40296682 | K8: 41380623 | M8: 43032626 | O8: 66618857 | Q8: 49675407 | S8: 26615001 | U8: 56762148 | W8: 41210243 | Y8: 32658375 | AA8: 32579934 | AC8: 41195859 | AE8: 63666235 | AG8: 34322888 | AI8: 38074906 | AK8: 23161933 | AM8: 72008771 | AO8: 43705687 | AQ8: 27058869 | AS8: 38076302 | AU8: 8466107 | AW8: 19892582 | AY8: 26206943 | BA8: 22515441 | BC8: 1.6100768e+08 | BE8: 59079175 | BG8: 22780795 | BI8: 42452571 | BK8: 25095351 | BM8: 23997635 | BO8: 22517338 | BQ8: 11510023 | BS8: 3.1149569e+08 | BU8: 4.1630095e+08 | BW8: 91652756 | BY8: 70735831 | CA8: 47435565 | CC8: 62296602 | CE8: 122025858 | CG8: 150142123 | CI8: 12395298 | CK8: 11578254 | CM8: 14314168 | CO8: 46108806 | CQ8: 19282406 | CS8: 16343471 | CU8: 13283191 | CW8: 4109352 | CY8: 11430255 | DA8: 6354640.8 | DC8: 6912516.5 | DE8: 6908378.6 | DG8: 24967153 | DI8: 6726657.9 | DK8: 5702844.1 | DM8: 4764699.1 | DO8: 5925577.5 | DQ8: 6977360.1 | DS8: 8175547.1 | DU8: 6134514.7 | DW8: 5407838.8 | DY8: 3296504.7 | EA8: 23306833 | EC8: 24640200 | EE8: 28070477 | EG8: 24530681 | EI8: 22040176 | EK8: 27937729 | EM8: 35049425 | EO8: 50771438 | EQ8: 51911162 | ES8: 21227343 | EU8: 5484862.9 | EW8: 6552421.6 | EY8: 7425167.5 | FA8: 47740848 | FC8: 21050056 | FE8: 8496771.5 | FG8: 7801128.6 | FI8: 18355518 | FK8: 4232869.6 | FM8: 5660186.8 | FO8: 13730334 | FQ8: 7236672.8 | FS8: 19226142 | FU8: 4978040.5 | FW8: 3321017.8 | FY8: 4084405.6 | GA8: 3118219.2 | GC8: 1498945.3 | GE8: 2908466 | GG8: 3644314.4 | GI8: 3766000.9 | GK8: 1372328 | GM8: 2441615.5 | GO8: 3155860.5 | GQ8: 2037962.8 | GS8: 1847396.5 | GU8: 1715156.2 | GW8: 1006738.1 | GY8: 1605637.7 | HA8: 493989.11 | HC8: 1067168.5 | HE8: 831169.98 | HG8: 1817724
A9: Investment Accounts | B9: 5. | C9: ='Notes - Dec25'!C42 -> 1.7070692e+08 | E9: ='Notes - Dec25'!E42 -> 50807984 | G9: ='Notes - Dec25'!G42 -> 81780346 | I9: 74237361 | K9: 1.935832e+08 | M9: 2.0957524e+08 | O9: 2.3852626e+08 | Q9: 2.3021314e+08 | S9: 2.8414521e+08 | U9: 43436803 | W9: 1.0372029e+08 | Y9: 1.2971521e+08 | AA9: 1.384414e+08 | AC9: 1.0728823e+08 | AE9: 1.2740355e+08 | AG9: 97741476 | AI9: ='Notes - Dec25'!AE42 -> 1.2740355e+08 | AK9: 67042340 | AM9: 85725012 | AO9: 1.1974487e+08 | AQ9: 52837446 | AS9: 11875443 | AU9: 1063217.3 | AW9: 1.0979233e+08 | AY9: 2.1667587e+08 | BA9: 88815846 | BC9: 60153463 | BE9: 1.2689133e+08 | BG9: 70416172 | BI9: 1.1620261e+08 | BK9: 1.565131e+08 | BM9: 221534203 | BO9: 2.5022921e+08 | BQ9: 334580676 | BS9: 248861.47 | BU9: 247470.72 | BW9: 246129.7 | BY9: 396673.75 | CA9: 5775722.5 | CC9: 5741456 | CE9: 5710596 | CG9: 5680126 | CI9: 64402412 | CK9: 100160401 | CM9: 1.2366704e+08 | CO9: ='Notes - Dec25'!CO42 -> 1.1014141e+08 | CQ9: ='Notes - Dec25'!CQ42 -> 1.1579483e+08 | CS9: ='Notes - Dec25'!CS42 -> 1.2406481e+08 | CU9: ='Notes - Dec25'!CU42 -> 61352517 | CW9: =+'Notes - Dec25'!CW42 -> 79548039 | CY9: =+'Notes - Dec25'!CY42 -> 1.0847554e+08 | DA9: =+'Notes - Dec25'!DA42 -> 57354789 | DC9: =+'Notes - Dec25'!DC42 -> 87143010 | DE9: =+'Notes - Dec25'!DE42 -> 83247084 | DG9: =+'Notes - Dec25'!DG42 -> 40462362 | DI9: =+'Notes - Dec25'!DI42 -> 32669443 | DK9: =+'Notes - Dec25'!DK42 -> 62893341 | DM9: =+'Notes - Dec25'!DM42 -> 50747876 | DO9: 71550519 | DQ9: 59723956 | DS9: 66038456 | DU9: 81659201 | DW9: 1.2675395e+08 | DY9: 1.5331764e+08 | EA9: 88453000 | EC9: 88715908 | EE9: 79984237 | EG9: 82254324 | EI9: 79996764 | EK9: 62736057 | EM9: 52465200 | EO9: 61664511 | EQ9: 65290791 | ES9: 69919871 | EU9: 64962950 | EW9: 52971149 | EY9: 60987411 | FA9: 41021161 | FC9: 73311111 | FE9: 211641.39 | FG9: 8665305.4 | FI9: 141016.13 | FK9: 3129983.4 | FM9: 9082520.2 | FO9: 11025359 | FQ9: 4009292.9 | FS9: 9285.65 | FU9: 9278.66 | FW9: 9271.45 | FY9: 9264.25 | GA9: 9257.31 | GC9: 1895866.1 | GE9: 2382465 | GG9: 2866713.9 | GI9: 2855804.2 | GK9: 3838203.9 | GM9: 3816668.5 | GO9: 4866941.2 | GQ9: 7125990.2 | GS9: 6191176 | GU9: 6768252.6 | GW9: 8221553 | GY9: 8670910.8 | HA9: 8916823.5 | HC9: 9224313.9 | HE9: 10664451 | HG9: 11006670
A10: Advances (Net) | B10: 1.3 | C10: =+'Notes - Dec25'!C15 -> 1.5068569e+09 | E10: =+'Notes - Dec25'!E15 -> 1.5543096e+09 | G10: =+'Notes - Dec25'!G15 -> 1.487163e+09 | I10: 1.5291501e+09 | K10: 1.540093e+09 | M10: ='Notes - Dec25'!M15 -> 1.5698073e+09 | O10: ='Notes - Dec25'!O15 -> 1.5624488e+09 | Q10: ='Notes - Dec25'!Q15 -> 1.6009868e+09 | S10: ='Notes - Dec25'!S15 -> 1.6171536e+09 | U10: ='Notes - Dec25'!U15 -> 1.6533135e+09 | W10: ='Notes - Dec25'!W15 -> 1.728136e+09 | Y10: 1.7914689e+09 | AA10: 1.8106753e+09 | AC10: 1.889595e+09 | AE10: 1.8758871e+09 | AG10: 1.8294239e+09 | AI10: 1.7953648e+09 | AK10: 1.7692985e+09 | AM10: 1.7123067e+09 | AO10: 1.6679456e+09 | AQ10: 1.6315326e+09 | AS10: 1.5929185e+09 | AU10: ='Notes - Dec25'!AU15 -> 1.4805857e+09 | AW10: 1.4077248e+09 | AY10: 1.3139125e+09 | BA10: 1.273905e+09 | BC10: 1.1569814e+09 | BE10: 1.0908727e+09 | BG10: 1.0369445e+09 | BI10: 9.5321446e+08 | BK10: 9.0806196e+08 | BM10: 8.5524237e+08 | BO10: 8.0665928e+08 | BQ10: =+'Notes - Dec25'!DQ15 -> 1.7844209e+08 | BS10: ='Notes - Dec25'!BS15 -> 669631787 | BU10: 6.7079383e+08 | BW10: 6.4173882e+08 | BY10: 6.5876549e+08 | CA10: 5.9377353e+08 | CC10: 5.8357025e+08 | CE10: 5.4940578e+08 | CG10: 5.2804942e+08 | CI10: 5.0826785e+08 | CK10: 4.7572364e+08 | CM10: 4.4880497e+08 | CO10: =+'Notes - Dec25'!CO15 -> 4.3629512e+08 | CQ10: =+'Notes - Dec25'!CQ15 -> 4.2198443e+08 | CS10: =+'Notes - Dec25'!CS15 -> 3.883681e+08 | CU10: =+'Notes - Dec25'!CU15 -> 3.8057297e+08 | CW10: =+'Notes - Dec25'!CW15 -> 3.8686791e+08 | CY10: =+'Notes - Dec25'!CY15 -> 3.5194409e+08 | DA10: =+'Notes - Dec25'!DA15 -> 3.2717067e+08 | DC10: =+'Notes - Dec25'!DC15 -> 3.009107e+08 | DE10: =+'Notes - Dec25'!DE15 -> 2.7069217e+08 | DG10: =+'Notes - Dec25'!DG15 -> 2.6154039e+08 | DI10: =+'Notes - Dec25'!DI15 -> 2.5086966e+08 | DK10: =+'Notes - Dec25'!DK15 -> 2.2606548e+08 | DM10: =+'Notes - Dec25'!DM15 -> 2.2039062e+08 | DO10: 1.9601839e+08 | DQ10: 1.7844209e+08 | DS10: 1.7208553e+08 | DU10: 1.7399482e+08 | DW10: 1.525848e+08 | DY10: 1.4128786e+08 | EA10: 1.3653779e+08 | EC10: 1.3286184e+08 | EE10: 1.3995046e+08 | EG10: 1.4218065e+08 | EI10: 1.4655205e+08 | EK10: 1.6397432e+08 | EM10: 1.7398916e+08 | EO10: 1.5297567e+08 | EQ10: 1.4624843e+08 | ES10: 1.3950736e+08 | EU10: 1.1560401e+08 | EW10: 1.0408517e+08 | EY10: 92566613 | FA10: 84484576 | FC10: 76456674 | FE10: 72994655 | FG10: 64845496 | FI10: 61979794 | FK10: 62186784 | FM10: 54897873 | FO10: 49311217 | FQ10: 48128211 | FS10: 42010777 | FU10: 35445285 | FW10: 32752530 | FY10: 28775974 | GA10: 24876301 | GC10: 24377633 | GE10: 21238134 | GG10: 20040814 | GI10: 19661322 | GK10: 17226776 | GM10: 16327150 | GO10: 15793239 | GQ10: 14130790 | GS10: 12811910 | GU10: 12944904 | GW10: 11676471 | GY10: 10930713 | HA10: 10069932 | HC10: 8972739.5 | HE10: 8151563.8 | HG10: 7589157.4
A11: Gross loan book (after WO) | GI11: 21438647 | GK11: 18963498 | GM11: 17879970 | GO11: 17218993 | GQ11: 15531633 | GS11: 14093812 | GU11: 14093498 | GW11: 12675065 | HA11: 11473457 | HC11: 10224150 | HE11: 9254593.6
A12: Provision for default | GI12: -1777324.5 | GK12: -1736722.1 | GM12: -1552820 | GO12: -1425753.1 | GQ12: -1400843.3 | GS12: -1281901.9 | GU12: -1148593.9 | GW12: -998594.18 | HA12: -1403524.8 | HC12: -1251410.2 | HE12: -1103029.7
